Workbook
Name _____8: #REF!
Name _____8: #REF!
Name _____8: #REF!
Name _____8: #REF!
Name _____B20996: #REF!
Name _____B20996: #REF!
Name _____B20996: #REF!
Name _____B20996: #REF!
Name _____C: #REF!
Name _____C: #REF!
Name _____C: #REF!
Name _____C: #REF!
Name _____cib27: #REF!
Name _____cib27: #REF!
Name _____cib27: #REF!
Name _____cib27: #REF!
Name _____dbk27: #REF!
Name _____dbk27: #REF!
Name _____dbk27: #REF!
Name _____dbk27: #REF!
Name _____meb27: #REF!
Name _____meb27: #REF!
Name _____meb27: #REF!
Name _____meb27: #REF!
Name _____mtu27: #REF!
Name _____mtu27: #REF!
Name _____mtu27: #REF!
Name _____mtu27: #REF!
Name _____P1: #REF!
Name _____P1: #REF!
Name _____P1: #REF!
Name _____P1: #REF!
Name _____P2: #REF!
Name _____P2: #REF!
Name _____P2: #REF!
Name _____P2: #REF!
Name _____P3: #REF!
Name _____P3: #REF!
Name _____P3: #REF!
Name _____P3: #REF!
Name _____P4: #REF!
Name _____P4: #REF!
Name _____P4: #REF!
Name _____P4: #REF!
Name _____pc27: #REF!
Name _____pc27: #REF!
Name _____pc27: #REF!
Name _____pc27: #REF!
Name _____pib27: #REF!
Name _____pib27: #REF!
Name _____pib27: #REF!
Name _____pib27: #REF!
Name _____pos27: #REF!
Name _____pos27: #REF!
Name _____pos27: #REF!
Name _____pos27: #REF!
Name _____ram128: #REF!
Name _____ram128: #REF!
Name _____ram128: #REF!
Name _____ram128: #REF!

Sheet Note
B5: Method recording COGS/Revenue in Construction sites
B7: Revenue (PC) = (DC+IC+5%(DC+IC))*115%
B9: Estimate Revenue (Fast) = (DC+IC+Actual SOE)*115% = COGS *115%
B12: => By the month: COGS/Estimate Revenue (Fast)= 86.96%
B16: After Project finishs, the Revenue of Project has to be Revenue in PC
B17: => Adjust the Estimate Revenue in Fast system to Revenue in PC: Grand Total Revenue (PC) = Estimate Revenue (Fast) +- Amount (A)
H18: Final COGS = COGS + Provision for Reparing Cost
B20: => Final

Sheet 원가이체, 판관비 배부현황(VND)
A1: ○ DECV - Site 실적
A3: 구 분 | C3: 2026년
C4: 1월 | D4: 2월 | E4: 3월 | F4: 4월 | G4: 5월 | H4: 6월 | I4: 7월 | J4: 8월 | K4: 9월 | L4: 10월 | M4: 11월 | N4: 12월 | O4: 소계
A5: Site 5 (Infra O&M) | B5: 매출 (Sales) | C5: =+'Summary 2026'!E9 -> 1593627000 | D5: =+'Summary 2026'!F9 -> 1593627000 | E5: =+'Summary 2026'!G9 -> 2143475816 | F5: =+'Summary 2026'!H9 -> 0 | G5: =+'Summary 2026'!I9 -> 0 | H5: =+'Summary 2026'!J9 -> 0 | I5: =+'Summary 2026'!K9 -> 0 | J5: =+'Summary 2026'!L9 -> 0 | ... N5: =+'Summary 2026'!P9 -> 0 | O5: =SUM(C5:N5) -> 5330729816
B6: 매출원가 (CGS) | C6: =+'Summary 2026'!E30 -> 765010240 | D6: =+'Summary 2026'!F30 -> 1068076592 | E6: =+'Summary 2026'!G30 -> 1700502515 | F6: =+'Summary 2026'!H30 -> 330291789 | G6: =+'Summary 2026'!I30 -> 0 | H6: =+'Summary 2026'!J30 -> 0 | I6: =+'Summary 2026'!K30 -> 0 | J6: =+'Summary 2026'!L30 -> 0 | ... N6: =+'Summary 2026'!P30 -> 0 | O6: =SUM(C6:N6) -> 3863881136
B7: 현장원가 (Site Cost) | C7: =C6-C8 -> 837739214 | D7: =+D6-D8 -> 1068076592 | E7: =+E6-E8 -> 1700502515 | F7: =+F6-F8 -> 330291789 | G7: =+G6-G8 -> 0 | H7: =+H6-H8 -> 0 | I7: =+I6-I8 -> 0 | J7: =+J6-J8 -> 0 | K7: =+K6-K8 -> 0 | ... N7: =+N6-N8 -> 0 | O7: =SUM(C7:N7) -> 3936610110
B8: 본사이체원가 (HQ Transfer) | C8: -72728974 | D8: 0 | E8: 0 | F8: 0 | G8: 0 | H8: 0 | I8: 0 | J8: 0 | K8: 0 | L8: 0 | M8: 0 | N8: 0 | O8: =SUM(C8:N8) -> -72728974
B9: 판관비 (S&A Exp) | C9: 0 | O9: =SUM(C9:N9) -> 0
B10: 아국인 인원수 (No. of Employee) | C10: 0 | O10: =SUM(C10:N10) -> 0
A11: Site 6 (Phase2 Infra) | B11: 매출 (Sales) | C11: =+'Summary 2026'!E10 -> 1542200224 | D11: =+'Summary 2026'!F10 -> 9761784424 | E11: =+'Summary 2026'!G10 -> 8010675534 | F11: =+'Summary 2026'!H10 -> 9796332935 | G11: =+'Summary 2026'!I10 -> 9416448788 | H11: =+'Summary 2026'!J10 -> 9123243464 | I11: =+'Summary 2026'!K10 -> 0 | J11: =+'Summary 2026'!L10 -> 0 | ... N11: =+'Summary 2026'!P10 -> 0 | O11: =SUM(C11:N11) -> 47650685369
B12: 매출원가 (CGS) | C12: =+'Summary 2026'!E31 -> 1342485295 | D12: =+'Summary 2026'!F31 -> 8497633341 | E12: =+'Summary 2026'!G31 -> 6973293052 | F12: =+'Summary 2026'!H31 -> 8527707820 | G12: =+'Summary 2026'!I31 -> 8197018670 | H12: =+'Summary 2026'!J31 -> 7941783435 | I12: =+'Summary 2026'!K31 -> 0 | J12: =+'Summary 2026'!L31 -> 0 | ... N12: =+'Summary 2026'!P31 -> 0 | O12: =SUM(C12:N12) -> 41479921613
B13: 현장원가 (Site Cost) | C13: =C12-C14 -> 1351844825 | D13: =D12-D14 -> 8399658021 | E13: =E12-E14 -> 6832745789 | F13: =F12-F14 -> 8438491109 | G13: =G12-G14 -> 7753053105 | H13: =H12-H14 -> 7871897411 | I13: =I12-I14 -> 0 | J13: =J12-J14 -> 0 | ... N13: =N12-N14 -> 0 | O13: =SUM(C13:N13) -> 40647690260
B14: 본사이체원가 (HQ Transfer) | C14: -9359530 | D14: 97975320 | E14: 140547263 | F14: 89216711 | G14: 443965565 | H14: 69886024 | O14: =SUM(C14:N14) -> 832231353
B15: 판관비 (S&A Exp) | C15: =ROUND(C$131*((C16/C$133)*50%+(C12/C$132)*50%),) -> 789177115 | D15: =ROUND(D$131*((D16/D$133)*50%+(D12/D$132)*50%),) -> 568929877 | E15: =ROUND(E$131*((E16/E$133)*50%+(E12/E$132)*50%),) -> 633523305 | F15: =ROUND(F$131*((F16/F$133)*50%+(F12/F$132)*50%),) -> 576517309 | G15: =ROUND(G$131*((G16/G$133)*50%+(G12/G$132)*50%),) -> 746446044 | H15: =ROUND(H$131*((H16/H$133)*50%+(H12/H$132)*50%),) -> 579071165 | I15: =ROUND(I$131*((I16/I$133)*50%+(I12/I$132)*50%),) -> #DIV/0! | J15: =ROUND(J$131*((J16/J$133)*50%+(J12/J$132)*50%),) -> #DIV/0! | ... N15: =ROUND(N$131*((N16/N$133)*50%+(N12/N$132)*50%),) -> #DIV/0! | O15: =SUM(C15:N15) -> #DIV/0!
B16: 아국인 인원수 (No. of Employee) | C16: 2 | D16: 2 | E16: 2 | F16: 2 | G16: 2 | H16: 2 | I16: 2 | J16: 2 | K16: 2 | L16: 2 | M16: 2 | N16: 2 | O16: =SUM(C16:N16)/12 -> 2
A17: Site 8 (Consulting service) | B17: 매출 (Sales) | C17: =+'Summary 2026'!E11 -> 0 | D17: =+'Summary 2026'!F11 -> 0 | E17: =+'Summary 2026'!G11 -> 0 | F17: =+'Summary 2026'!H11 -> 0 | G17: =+'Summary 2026'!I11 -> 0 | H17: =+'Summary 2026'!J11 -> 0 | I17: =+'Summary 2026'!K11 -> 0 | J17: =+'Summary 2026'!L11 -> 0 | ... N17: =+'Summary 2026'!P11 -> 0 | O17: =SUM(C17:N17) -> 0
B18: 매출원가 (CGS) | C18: =+'Summary 2026'!E32 -> 0 | D18: =+'Summary 2026'!F32 -> 0 | E18: =+'Summary 2026'!G32 -> 0 | F18: =+'Summary 2026'!H32 -> 0 | G18: =+'Summary 2026'!I32 -> 0 | H18: =+'Summary 2026'!J32 -> 0 | I18: =+'Summary 2026'!K32 -> 0 | J18: =+'Summary 2026'!L32 -> 0 | ... N18: =+'Summary 2026'!P32 -> 0 | O18: =SUM(C18:N18) -> 0
B19: 현장원가 (Site Cost) | C19: =+C18-C20 -> 0 | D19: =+D18-D20 -> 0 | E19: =+E18-E20 -> 0 | F19: =+F18-F20 -> 0 | G19: =+G18-G20 -> 0 | H19: =+H18-H20 -> 0 | I19: =+I18-I20 -> 0 | J19: =+J18-J20 -> 0 | ... N19: =+N18-N20 -> 0 | O19: =SUM(C19:N19) -> 0
B20: 본사이체원가 (HQ Transfer) | O20: =SUM(C20:N20) -> 0
B21: 판관비 (S&A Exp) | O21: =SUM(C21:N21) -> 0
B22: 아국인 인원수 (No. of Employee) | O22: =SUM(C22:N22) -> 0
A23: Site 14 (B1CC4) | B23: 매출 (Sales) | C23: =+'Summary 2026'!E12 -> 4774000000 | D23: =+'Summary 2026'!F12 -> 0 | E23: =+'Summary 2026'!G12 -> 0 | F23: =+'Summary 2026'!H12 -> 0 | G23: =+'Summary 2026'!I12 -> 0 | H23: =+'Summary 2026'!J12 -> 0 | I23: =+'Summary 2026'!K12 -> 0 | J23: =+'Summary 2026'!L12 -> 0 | ... N23: =+'Summary 2026'!P12 -> 0 | O23: =SUM(C23:N23) -> 4774000000
B24: 매출원가 (CGS) | C24: =+'Summary 2026'!E33 -> 1762265417 | D24: =+'Summary 2026'!F33 -> 0 | E24: =+'Summary 2026'!G33 -> 0 | F24: =+'Summary 2026'!H33 -> 0 | G24: =+'Summary 2026'!I33 -> 0 | H24: =+'Summary 2026'!J33 -> 0 | I24: =+'Summary 2026'!K33 -> 0 | J24: =+'Summary 2026'!L33 -> 0 | ... N24: =+'Summary 2026'!P33 -> 0 | O24: =SUM(C24:N24) -> 1762265417
B25: 현장원가 (Site Cost) | C25: =+C24-C26 -> 1745875441 | D25: =+D24-D26 -> 0 | E25: =+E24-E26 -> 0 | F25: =+F24-F26 -> 0 | G25: =+G24-G26 -> 0 | H25: =+H24-H26 -> 0 | I25: =+I24-I26 -> 0 | J25: =+J24-J26 -> 0 | ... N25: =+N24-N26 -> 0 | O25: =SUM(C25:N25) -> 1745875441
B26: 본사이체원가 (HQ Transfer) | C26: 16389976 | O26: =SUM(C26:N26) -> 16389976
B27: 판관비 (S&A Exp) | O27: =SUM(C27:N27) -> 0
B28: 아국인 인원수 (No. of Employee) | O28: =SUM(C28:N28) -> 0
A29: Site 16 (K8CT1 Precon) | B29: 매출 (Sales) | C29: =+'Summary 2026'!E13 -> 0 | D29: =+'Summary 2026'!F13 -> 0 | E29: =+'Summary 2026'!G13 -> 0 | F29: =+'Summary 2026'!H13 -> 0 | G29: =+'Summary 2026'!I13 -> 0 | H29: =+'Summary 2026'!J13 -> 0 | I29: =+'Summary 2026'!K13 -> 0 | J29: =+'Summary 2026'!L13 -> 0 | ... N29: =+'Summary 2026'!P13 -> 0 | O29: =SUM(C29:N29) -> 0
B30: 매출원가 (CGS) | C30: =+'Summary 2026'!E34 -> 0 | D30: =+'Summary 2026'!F34 -> 0 | E30: =+'Summary 2026'!G34 -> 0 | F30: =+'Summary 2026'!H34 -> 0 | G30: =+'Summary 2026'!I34 -> 0 | H30: =+'Summary 2026'!J34 -> 0 | I30: =+'Summary 2026'!K34 -> 0 | J30: =+'Summary 2026'!L34 -> 0 | ... N30: =+'Summary 2026'!P34 -> 0 | O30: =SUM(C30:N30) -> 0
B31: 현장원가 (Site Cost) | C31: =+C30-C32 -> 0 | D31: =+D30-D32 -> 0 | E31: =+E30-E32 -> 0 | F31: =+F30-F32 -> 0 | G31: =+G30-G32 -> 0 | H31: =+H30-H32 -> 0 | I31: =+I30-I32 -> 0 | J31: =+J30-J32 -> 0 | ... N31: =+N30-N32 -> 0 | O31: =SUM(C31:N31) -> 0
B32: 본사이체원가 (HQ Transfer) | O32: =SUM(C32:N32) -> 0
B33: 판관비 (S&A Exp) | O33: =SUM(C33:N33) -> 0
B34: 아국인 인원수 (No. of Employee) | O34: =SUM(C34:N34) -> 0
A35: Site 17 (H1HH1) | B35: 매출 (Sales) | C35: =+'Summary 2026'!E14 -> 18604651000 | D35: =+'Summary 2026'!F14 -> 0 | E35: =+'Summary 2026'!G14 -> 9302325000 | F35: =+'Summary 2026'!H14 -> 0 | G35: =+'Summary 2026'!I14 -> 0 | H35: =+'Summary 2026'!J14 -> 0 | I35: =+'Summary 2026'!K14 -> 0 | J35: =+'Summary 2026'!L14 -> 0 | ... N35: =+'Summary 2026'!P14 -> 0 | O35: =SUM(C35:N35) -> 27906976000
B36: 매출원가 (CGS) | C36: =+'Summary 2026'!E35 -> 14612106035 | D36: =+'Summary 2026'!F35 -> 0 | E36: =+'Summary 2026'!G35 -> 338665881 | F36: =+'Summary 2026'!H35 -> 0 | G36: =+'Summary 2026'!I35 -> 0 | H36: =+'Summary 2026'!J35 -> 0 | I36: =+'Summary 2026'!K35 -> 0 | J36: =+'Summary 2026'!L35 -> 0 | ... N36: =+'Summary 2026'!P35 -> 0 | O36: =SUM(C36:N36) -> 14950771916
B37: 현장원가 (Site Cost) | C37: =+C36-C38 -> 14215671258 | D37: =+D36-D38 -> 0 | E37: =+E36-E38 -> 338665881 | F37: =+F36-F38 -> 0 | G37: =+G36-G38 -> 0 | H37: =+H36-H38 -> 0 | I37: =+I36-I38 -> 0 | J37: =+J36-J38 -> 0 | ... N37: =+N36-N38 -> 0 | O37: =SUM(C37:N37) -> 14554337139
B38: 본사이체원가 (HQ Transfer) | C38: =417653186-21218409 -> 396434777 | O38: =SUM(C38:N38) -> 396434777
B39: 판관비 (S&A Exp) | O39: =SUM(C39:N39) -> 0
B40: 아국인 인원수 (No. of Employee) | O40: =SUM(C40:N40) -> 0
A41: Site 18 (Construction K8CT1) | B41: 매출 (Sales) | C41: =+'Summary 2026'!E15 -> 2072675730 | D41: =+'Summary 2026'!F15 -> 33496121350 | E41: =+'Summary 2026'!G15 -> 15563253849 | F41: =+'Summary 2026'!H15 -> 38519575773 | G41: =+'Summary 2026'!I15 -> 76324301108 | H41: =+'Summary 2026'!J15 -> 107210623606 | I41: =+'Summary 2026'!K15 -> 0 | J41: =+'Summary 2026'!L15 -> 0 | ... N41: =+'Summary 2026'!P15 -> 0 | O41: =SUM(C41:N41) -> 273186551416
...

Sheet 원가이체, 판관비 배부현황(1000USD)
A1: ○ DECV - Site 실적
A3: 구 분 | C3: 2026년
C4: 1월 | D4: 2월 | E4: 3월 | F4: 4월 | G4: 5월 | H4: 6월 | I4: 7월 | J4: 8월 | K4: 9월 | L4: 10월 | M4: 11월 | N4: 12월 | O4: 소계
A5: Site 5 (Infra O&M) | B5: 매출 (Sales) | C5: =+'원가이체, 판관비 배부현황(VND)'!C5/C$128 -> 61.309853 | D5: =+'원가이체, 판관비 배부현황(VND)'!D5/D$128 -> 61.081909 | E5: =+'원가이체, 판관비 배부현황(VND)'!E5/E$128 -> 81.296966 | F5: =+'원가이체, 판관비 배부현황(VND)'!F5/F$128 -> 0 | G5: =+'원가이체, 판관비 배부현황(VND)'!G5/G$128 -> 0 | H5: =+'원가이체, 판관비 배부현황(VND)'!H5/H$128 -> 0 | I5: =+'원가이체, 판관비 배부현황(VND)'!I5/I$128 -> 0 | J5: =+'원가이체, 판관비 배부현황(VND)'!J5/J$128 -> 0 | ... N5: =+'원가이체, 판관비 배부현황(VND)'!N5/N$128 -> 0 | O5: =SUM(C5:N5) -> 203.68873
B6: 매출원가 (CGS) | C6: =+'원가이체, 판관비 배부현황(VND)'!C6/C$128 -> 29.431395 | D6: =+'원가이체, 판관비 배부현황(VND)'!D6/D$128 -> 40.93816 | E6: =+'원가이체, 판관비 배부현황(VND)'!E6/E$128 -> 64.496037 | F6: =+'원가이체, 판관비 배부현황(VND)'!F6/F$128 -> 12.530513 | G6: =+'원가이체, 판관비 배부현황(VND)'!G6/G$128 -> 0 | H6: =+'원가이체, 판관비 배부현황(VND)'!H6/H$128 -> 0 | I6: =+'원가이체, 판관비 배부현황(VND)'!I6/I$128 -> 0 | J6: =+'원가이체, 판관비 배부현황(VND)'!J6/J$128 -> 0 | ... N6: =+'원가이체, 판관비 배부현황(VND)'!N6/N$128 -> 0 | O6: =SUM(C6:N6) -> 147.3961
B7: 현장원가 (Site Cost) | C7: =+'원가이체, 판관비 배부현황(VND)'!C7/C$128 -> 32.229416 | D7: =+'원가이체, 판관비 배부현황(VND)'!D7/D$128 -> 40.93816 | E7: =+'원가이체, 판관비 배부현황(VND)'!E7/E$128 -> 64.496037 | F7: =+'원가이체, 판관비 배부현황(VND)'!F7/F$128 -> 12.530513 | G7: =+'원가이체, 판관비 배부현황(VND)'!G7/G$128 -> 0 | H7: =+'원가이체, 판관비 배부현황(VND)'!H7/H$128 -> 0 | I7: =+'원가이체, 판관비 배부현황(VND)'!I7/I$128 -> 0 | J7: =+'원가이체, 판관비 배부현황(VND)'!J7/J$128 -> 0 | ... N7: =+'원가이체, 판관비 배부현황(VND)'!N7/N$128 -> 0 | O7: =SUM(C7:N7) -> 150.19413
B8: 본사이체원가 (HQ Transfer) | C8: =+'원가이체, 판관비 배부현황(VND)'!C8/C$128 -> -2.7980215 | D8: =+'원가이체, 판관비 배부현황(VND)'!D8/D$128 -> 0 | E8: =+'원가이체, 판관비 배부현황(VND)'!E8/E$128 -> 0 | F8: =+'원가이체, 판관비 배부현황(VND)'!F8/F$128 -> 0 | G8: =+'원가이체, 판관비 배부현황(VND)'!G8/G$128 -> 0 | H8: =+'원가이체, 판관비 배부현황(VND)'!H8/H$128 -> 0 | I8: =+'원가이체, 판관비 배부현황(VND)'!I8/I$128 -> 0 | J8: =+'원가이체, 판관비 배부현황(VND)'!J8/J$128 -> 0 | ... N8: =+'원가이체, 판관비 배부현황(VND)'!N8/N$128 -> 0 | O8: =SUM(C8:N8) -> -2.7980215
B9: 판관비 (S&A Exp) | C9: =+'원가이체, 판관비 배부현황(VND)'!C9/C$128 -> 0 | D9: =+'원가이체, 판관비 배부현황(VND)'!D9/D$128 -> 0 | E9: =+'원가이체, 판관비 배부현황(VND)'!E9/E$128 -> 0 | F9: =+'원가이체, 판관비 배부현황(VND)'!F9/F$128 -> 0 | G9: =+'원가이체, 판관비 배부현황(VND)'!G9/G$128 -> 0 | H9: =+'원가이체, 판관비 배부현황(VND)'!H9/H$128 -> 0 | I9: =+'원가이체, 판관비 배부현황(VND)'!I9/I$128 -> 0 | J9: =+'원가이체, 판관비 배부현황(VND)'!J9/J$128 -> 0 | ... N9: =+'원가이체, 판관비 배부현황(VND)'!N9/N$128 -> 0 | O9: =SUM(C9:N9) -> 0
B10: 인원수 (No. of Emplyee) | C10: =+'원가이체, 판관비 배부현황(VND)'!C10 -> 0 | D10: =+'원가이체, 판관비 배부현황(VND)'!D10 -> 0 | E10: =+'원가이체, 판관비 배부현황(VND)'!E10 -> 0 | F10: =+'원가이체, 판관비 배부현황(VND)'!F10 -> 0 | G10: =+'원가이체, 판관비 배부현황(VND)'!G10 -> 0 | H10: =+'원가이체, 판관비 배부현황(VND)'!H10 -> 0 | I10: =+'원가이체, 판관비 배부현황(VND)'!I10 -> 0 | J10: =+'원가이체, 판관비 배부현황(VND)'!J10 -> 0 | ... N10: =+'원가이체, 판관비 배부현황(VND)'!N10 -> 0 | O10: =SUM(C10:N10) -> 0
A11: Site 6 (Phase2 Infra) | B11: 매출 (Sales) | C11: =+'원가이체, 판관비 배부현황(VND)'!C11/C$128 -> 59.331367 | D11: =+'원가이체, 판관비 배부현황(VND)'!D11/D$128 -> 374.15808 | E11: =+'원가이체, 판관비 배부현황(VND)'!E11/E$128 -> 303.82597 | F11: =+'원가이체, 판관비 배부현황(VND)'!F11/F$128 -> 371.6504 | G11: =+'원가이체, 판관비 배부현황(VND)'!G11/G$128 -> 357.69986 | H11: =+'원가이체, 판관비 배부현황(VND)'!H11/H$128 -> 346.82545 | I11: =+'원가이체, 판관비 배부현황(VND)'!I11/I$128 -> 0 | J11: =+'원가이체, 판관비 배부현황(VND)'!J11/J$128 -> 0 | ... N11: =+'원가이체, 판관비 배부현황(VND)'!N11/N$128 -> 0 | O11: =SUM(C11:N11) -> 1813.4911
B12: 매출원가 (CGS) | C12: =+'원가이체, 판관비 배부현황(VND)'!C12/C$128 -> 51.647955 | D12: =+'원가이체, 판관비 배부현황(VND)'!D12/D$128 -> 325.70461 | E12: =+'원가이체, 판관비 배부현황(VND)'!E12/E$128 -> 264.48051 | F12: =+'원가이체, 판관비 배부현황(VND)'!F12/F$128 -> 323.52167 | G12: =+'원가이체, 판관비 배부현황(VND)'!G12/G$128 -> 311.37773 | H12: =+'원가이체, 판관비 배부현황(VND)'!H12/H$128 -> 301.91155 | I12: =+'원가이체, 판관비 배부현황(VND)'!I12/I$128 -> 0 | J12: =+'원가이체, 판관비 배부현황(VND)'!J12/J$128 -> 0 | ... N12: =+'원가이체, 판관비 배부현황(VND)'!N12/N$128 -> 0 | O12: =SUM(C12:N12) -> 1578.644
B13: 현장원가 (Site Cost) | C13: =+'원가이체, 판관비 배부현황(VND)'!C13/C$128 -> 52.008034 | D13: =+'원가이체, 판관비 배부현황(VND)'!D13/D$128 -> 321.94933 | E13: =+'원가이체, 판관비 배부현황(VND)'!E13/E$128 -> 259.14988 | F13: =+'원가이체, 판관비 배부현황(VND)'!F13/F$128 -> 320.137 | G13: =+'원가이체, 판관비 배부현황(VND)'!G13/G$128 -> 294.51294 | H13: =+'원가이체, 판관비 배부현황(VND)'!H13/H$128 -> 299.2548 | I13: =+'원가이체, 판관비 배부현황(VND)'!I13/I$128 -> 0 | J13: =+'원가이체, 판관비 배부현황(VND)'!J13/J$128 -> 0 | ... N13: =+'원가이체, 판관비 배부현황(VND)'!N13/N$128 -> 0 | O13: =SUM(C13:N13) -> 1547.012
B14: 본사이체원가 (HQ Transfer) | C14: =+'원가이체, 판관비 배부현황(VND)'!C14/C$128 -> -0.36007887 | D14: =+'원가이체, 판관비 배부현황(VND)'!D14/D$128 -> 3.7552825 | E14: =+'원가이체, 판관비 배부현황(VND)'!E14/E$128 -> 5.3306252 | F14: =+'원가이체, 판관비 배부현황(VND)'!F14/F$128 -> 3.3846774 | G14: =+'원가이체, 판관비 배부현황(VND)'!G14/G$128 -> 16.864789 | H14: =+'원가이체, 판관비 배부현황(VND)'!H14/H$128 -> 2.6567582 | I14: =+'원가이체, 판관비 배부현황(VND)'!I14/I$128 -> 0 | J14: =+'원가이체, 판관비 배부현황(VND)'!J14/J$128 -> 0 | ... N14: =+'원가이체, 판관비 배부현황(VND)'!N14/N$128 -> 0 | O14: =SUM(C14:N14) -> 31.632053
B15: 판관비 (S&A Exp) | C15: =+'원가이체, 판관비 배부현황(VND)'!C15/C$128 -> 30.36114 | D15: =+'원가이체, 판관비 배부현황(VND)'!D15/D$128 -> 21.806435 | E15: =+'원가이체, 판관비 배부현황(VND)'!E15/E$128 -> 24.02804 | F15: =+'원가이체, 판관비 배부현황(VND)'!F15/F$128 -> 21.871744 | G15: =+'원가이체, 판관비 배부현황(VND)'!G15/G$128 -> 28.355025 | H15: =+'원가이체, 판관비 배부현황(VND)'!H15/H$128 -> 22.01373 | I15: =+'원가이체, 판관비 배부현황(VND)'!I15/I$128 -> #DIV/0! | J15: =+'원가이체, 판관비 배부현황(VND)'!J15/J$128 -> #DIV/0! | ... N15: =+'원가이체, 판관비 배부현황(VND)'!N15/N$128 -> #DIV/0! | O15: =SUM(C15:N15) -> #DIV/0!
B16: 아국인 인원수 (No. of Emplyee) | C16: ='원가이체, 판관비 배부현황(VND)'!C16 -> 2 | D16: ='원가이체, 판관비 배부현황(VND)'!D16 -> 2 | E16: ='원가이체, 판관비 배부현황(VND)'!E16 -> 2 | F16: ='원가이체, 판관비 배부현황(VND)'!F16 -> 2 | G16: ='원가이체, 판관비 배부현황(VND)'!G16 -> 2 | H16: ='원가이체, 판관비 배부현황(VND)'!H16 -> 2 | I16: ='원가이체, 판관비 배부현황(VND)'!I16 -> 2 | J16: ='원가이체, 판관비 배부현황(VND)'!J16 -> 2 | ... N16: ='원가이체, 판관비 배부현황(VND)'!N16 -> 2 | O16: =SUM(C16:N16)/12 -> 2
A17: Site 8 (Consulting service) | B17: 매출 (Sales) | C17: =+'원가이체, 판관비 배부현황(VND)'!C17/C$128 -> 0 | D17: =+'원가이체, 판관비 배부현황(VND)'!D17/D$128 -> 0 | E17: =+'원가이체, 판관비 배부현황(VND)'!E17/E$128 -> 0 | F17: =+'원가이체, 판관비 배부현황(VND)'!F17/F$128 -> 0 | G17: =+'원가이체, 판관비 배부현황(VND)'!G17/G$128 -> 0 | H17: =+'원가이체, 판관비 배부현황(VND)'!H17/H$128 -> 0 | I17: =+'원가이체, 판관비 배부현황(VND)'!I17/I$128 -> 0 | J17: =+'원가이체, 판관비 배부현황(VND)'!J17/J$128 -> 0 | ... N17: =+'원가이체, 판관비 배부현황(VND)'!N17/N$128 -> 0 | O17: =SUM(C17:N17) -> 0
B18: 매출원가 (CGS) | C18: =+'원가이체, 판관비 배부현황(VND)'!C18/C$128 -> 0 | D18: =+'원가이체, 판관비 배부현황(VND)'!D18/D$128 -> 0 | E18: =+'원가이체, 판관비 배부현황(VND)'!E18/E$128 -> 0 | F18: =+'원가이체, 판관비 배부현황(VND)'!F18/F$128 -> 0 | G18: =+'원가이체, 판관비 배부현황(VND)'!G18/G$128 -> 0 | H18: =+'원가이체, 판관비 배부현황(VND)'!H18/H$128 -> 0 | I18: =+'원가이체, 판관비 배부현황(VND)'!I18/I$128 -> 0 | J18: =+'원가이체, 판관비 배부현황(VND)'!J18/J$128 -> 0 | ... N18: =+'원가이체, 판관비 배부현황(VND)'!N18/N$128 -> 0 | O18: =SUM(C18:N18) -> 0
B19: 현장원가 (Site Cost) | C19: =+'원가이체, 판관비 배부현황(VND)'!C19/C$128 -> 0 | D19: =+'원가이체, 판관비 배부현황(VND)'!D19/D$128 -> 0 | E19: =+'원가이체, 판관비 배부현황(VND)'!E19/E$128 -> 0 | F19: =+'원가이체, 판관비 배부현황(VND)'!F19/F$128 -> 0 | G19: =+'원가이체, 판관비 배부현황(VND)'!G19/G$128 -> 0 | H19: =+'원가이체, 판관비 배부현황(VND)'!H19/H$128 -> 0 | I19: =+'원가이체, 판관비 배부현황(VND)'!I19/I$128 -> 0 | J19: =+'원가이체, 판관비 배부현황(VND)'!J19/J$128 -> 0 | ... N19: =+'원가이체, 판관비 배부현황(VND)'!N19/N$128 -> 0 | O19: =SUM(C19:N19) -> 0
B20: 본사이체원가 (HQ Transfer) | C20: =+'원가이체, 판관비 배부현황(VND)'!C20/C$128 -> 0 | D20: =+'원가이체, 판관비 배부현황(VND)'!D20/D$128 -> 0 | E20: =+'원가이체, 판관비 배부현황(VND)'!E20/E$128 -> 0 | F20: =+'원가이체, 판관비 배부현황(VND)'!F20/F$128 -> 0 | G20: =+'원가이체, 판관비 배부현황(VND)'!G20/G$128 -> 0 | H20: =+'원가이체, 판관비 배부현황(VND)'!H20/H$128 -> 0 | I20: =+'원가이체, 판관비 배부현황(VND)'!I20/I$128 -> 0 | J20: =+'원가이체, 판관비 배부현황(VND)'!J20/J$128 -> 0 | ... N20: =+'원가이체, 판관비 배부현황(VND)'!N20/N$128 -> 0 | O20: =SUM(C20:N20) -> 0
B21: 판관비 (S&A Exp) | C21: =+'원가이체, 판관비 배부현황(VND)'!C21/C$128 -> 0 | D21: =+'원가이체, 판관비 배부현황(VND)'!D21/D$128 -> 0 | E21: =+'원가이체, 판관비 배부현황(VND)'!E21/E$128 -> 0 | F21: =+'원가이체, 판관비 배부현황(VND)'!F21/F$128 -> 0 | G21: =+'원가이체, 판관비 배부현황(VND)'!G21/G$128 -> 0 | H21: =+'원가이체, 판관비 배부현황(VND)'!H21/H$128 -> 0 | I21: =+'원가이체, 판관비 배부현황(VND)'!I21/I$128 -> 0 | J21: =+'원가이체, 판관비 배부현황(VND)'!J21/J$128 -> 0 | ... N21: =+'원가이체, 판관비 배부현황(VND)'!N21/N$128 -> 0 | O21: =SUM(C21:N21) -> 0
B22: 아국인 인원수 (No. of Emplyee) | C22: ='원가이체, 판관비 배부현황(VND)'!C22 -> 0 | D22: ='원가이체, 판관비 배부현황(VND)'!D22 -> 0 | E22: ='원가이체, 판관비 배부현황(VND)'!E22 -> 0 | F22: ='원가이체, 판관비 배부현황(VND)'!F22 -> 0 | G22: ='원가이체, 판관비 배부현황(VND)'!G22 -> 0 | H22: ='원가이체, 판관비 배부현황(VND)'!H22 -> 0 | I22: ='원가이체, 판관비 배부현황(VND)'!I22 -> 0 | J22: ='원가이체, 판관비 배부현황(VND)'!J22 -> 0 | ... N22: ='원가이체, 판관비 배부현황(VND)'!N22 -> 0 | O22: =SUM(C22:N22) -> 0
A23: Site 14 (B1CC4 Consulting) | B23: 매출 (Sales) | C23: =+'원가이체, 판관비 배부현황(VND)'!C23/C$128 -> 183.66483 | D23: =+'원가이체, 판관비 배부현황(VND)'!D23/D$128 -> 0 | E23: =+'원가이체, 판관비 배부현황(VND)'!E23/E$128 -> 0 | F23: =+'원가이체, 판관비 배부현황(VND)'!F23/F$128 -> 0 | G23: =+'원가이체, 판관비 배부현황(VND)'!G23/G$128 -> 0 | H23: =+'원가이체, 판관비 배부현황(VND)'!H23/H$128 -> 0 | I23: =+'원가이체, 판관비 배부현황(VND)'!I23/I$128 -> 0 | J23: =+'원가이체, 판관비 배부현황(VND)'!J23/J$128 -> 0 | ... N23: =+'원가이체, 판관비 배부현황(VND)'!N23/N$128 -> 0 | O23: =SUM(C23:N23) -> 183.66483
B24: 매출원가 (CGS) | C24: =+'원가이체, 판관비 배부현황(VND)'!C24/C$128 -> 67.797692 | D24: =+'원가이체, 판관비 배부현황(VND)'!D24/D$128 -> 0 | E24: =+'원가이체, 판관비 배부현황(VND)'!E24/E$128 -> 0 | F24: =+'원가이체, 판관비 배부현황(VND)'!F24/F$128 -> 0 | G24: =+'원가이체, 판관비 배부현황(VND)'!G24/G$128 -> 0 | H24: =+'원가이체, 판관비 배부현황(VND)'!H24/H$128 -> 0 | I24: =+'원가이체, 판관비 배부현황(VND)'!I24/I$128 -> 0 | J24: =+'원가이체, 판관비 배부현황(VND)'!J24/J$128 -> 0 | ... N24: =+'원가이체, 판관비 배부현황(VND)'!N24/N$128 -> 0 | O24: =SUM(C24:N24) -> 67.797692
B25: 현장원가 (Site Cost) | C25: =+'원가이체, 판관비 배부현황(VND)'!C25/C$128 -> 67.167139 | D25: =+'원가이체, 판관비 배부현황(VND)'!D25/D$128 -> 0 | E25: =+'원가이체, 판관비 배부현황(VND)'!E25/E$128 -> 0 | F25: =+'원가이체, 판관비 배부현황(VND)'!F25/F$128 -> 0 | G25: =+'원가이체, 판관비 배부현황(VND)'!G25/G$128 -> 0 | H25: =+'원가이체, 판관비 배부현황(VND)'!H25/H$128 -> 0 | I25: =+'원가이체, 판관비 배부현황(VND)'!I25/I$128 -> 0 | J25: =+'원가이체, 판관비 배부현황(VND)'!J25/J$128 -> 0 | ... N25: =+'원가이체, 판관비 배부현황(VND)'!N25/N$128 -> 0 | O25: =SUM(C25:N25) -> 67.167139
B26: 본사이체원가 (HQ Transfer) | C26: =+'원가이체, 판관비 배부현황(VND)'!C26/C$128 -> 0.63055346 | D26: =+'원가이체, 판관비 배부현황(VND)'!D26/D$128 -> 0 | E26: =+'원가이체, 판관비 배부현황(VND)'!E26/E$128 -> 0 | F26: =+'원가이체, 판관비 배부현황(VND)'!F26/F$128 -> 0 | G26: =+'원가이체, 판관비 배부현황(VND)'!G26/G$128 -> 0 | H26: =+'원가이체, 판관비 배부현황(VND)'!H26/H$128 -> 0 | I26: =+'원가이체, 판관비 배부현황(VND)'!I26/I$128 -> 0 | J26: =+'원가이체, 판관비 배부현황(VND)'!J26/J$128 -> 0 | ... N26: =+'원가이체, 판관비 배부현황(VND)'!N26/N$128 -> 0 | O26: =SUM(C26:N26) -> 0.63055346
B27: 판관비 (S&A Exp) | C27: =+'원가이체, 판관비 배부현황(VND)'!C27/C$128 -> 0 | D27: =+'원가이체, 판관비 배부현황(VND)'!D27/D$128 -> 0 | E27: =+'원가이체, 판관비 배부현황(VND)'!E27/E$128 -> 0 | F27: =+'원가이체, 판관비 배부현황(VND)'!F27/F$128 -> 0 | G27: =+'원가이체, 판관비 배부현황(VND)'!G27/G$128 -> 0 | H27: =+'원가이체, 판관비 배부현황(VND)'!H27/H$128 -> 0 | I27: =+'원가이체, 판관비 배부현황(VND)'!I27/I$128 -> 0 | J27: =+'원가이체, 판관비 배부현황(VND)'!J27/J$128 -> 0 | ... N27: =+'원가이체, 판관비 배부현황(VND)'!N27/N$128 -> 0 | O27: =SUM(C27:N27) -> 0
B28: 아국인 인원수 (No. of Emplyee) | C28: ='원가이체, 판관비 배부현황(VND)'!C28 -> 0 | D28: ='원가이체, 판관비 배부현황(VND)'!D28 -> 0 | E28: ='원가이체, 판관비 배부현황(VND)'!E28 -> 0 | F28: ='원가이체, 판관비 배부현황(VND)'!F28 -> 0 | G28: ='원가이체, 판관비 배부현황(VND)'!G28 -> 0 | H28: ='원가이체, 판관비 배부현황(VND)'!H28 -> 0 | I28: ='원가이체, 판관비 배부현황(VND)'!I28 -> 0 | J28: ='원가이체, 판관비 배부현황(VND)'!J28 -> 0 | ... N28: ='원가이체, 판관비 배부현황(VND)'!N28 -> 0 | O28: =SUM(C28:N28) -> 0
A29: Site 16 (K8HH1 Precon) | B29: 매출 (Sales) | C29: =+'원가이체, 판관비 배부현황(VND)'!C29/C$128 -> 0 | D29: =+'원가이체, 판관비 배부현황(VND)'!D29/D$128 -> 0 | E29: =+'원가이체, 판관비 배부현황(VND)'!E29/E$128 -> 0 | F29: =+'원가이체, 판관비 배부현황(VND)'!F29/F$128 -> 0 | G29: =+'원가이체, 판관비 배부현황(VND)'!G29/G$128 -> 0 | H29: =+'원가이체, 판관비 배부현황(VND)'!H29/H$128 -> 0 | I29: =+'원가이체, 판관비 배부현황(VND)'!I29/I$128 -> 0 | J29: =+'원가이체, 판관비 배부현황(VND)'!J29/J$128 -> 0 | ... N29: =+'원가이체, 판관비 배부현황(VND)'!N29/N$128 -> 0 | O29: =SUM(C29:N29) -> 0
B30: 매출원가 (CGS) | C30: =+'원가이체, 판관비 배부현황(VND)'!C30/C$128 -> 0 | D30: =+'원가이체, 판관비 배부현황(VND)'!D30/D$128 -> 0 | E30: =+'원가이체, 판관비 배부현황(VND)'!E30/E$128 -> 0 | F30: =+'원가이체, 판관비 배부현황(VND)'!F30/F$128 -> 0 | G30: =+'원가이체, 판관비 배부현황(VND)'!G30/G$128 -> 0 | H30: =+'원가이체, 판관비 배부현황(VND)'!H30/H$128 -> 0 | I30: =+'원가이체, 판관비 배부현황(VND)'!I30/I$128 -> 0 | J30: =+'원가이체, 판관비 배부현황(VND)'!J30/J$128 -> 0 | ... N30: =+'원가이체, 판관비 배부현황(VND)'!N30/N$128 -> 0 | O30: =SUM(C30:N30) -> 0
B31: 현장원가 (Site Cost) | C31: =+'원가이체, 판관비 배부현황(VND)'!C31/C$128 -> 0 | D31: =+'원가이체, 판관비 배부현황(VND)'!D31/D$128 -> 0 | E31: =+'원가이체, 판관비 배부현황(VND)'!E31/E$128 -> 0 | F31: =+'원가이체, 판관비 배부현황(VND)'!F31/F$128 -> 0 | G31: =+'원가이체, 판관비 배부현황(VND)'!G31/G$128 -> 0 | H31: =+'원가이체, 판관비 배부현황(VND)'!H31/H$128 -> 0 | I31: =+'원가이체, 판관비 배부현황(VND)'!I31/I$128 -> 0 | J31: =+'원가이체, 판관비 배부현황(VND)'!J31/J$128 -> 0 | ... N31: =+'원가이체, 판관비 배부현황(VND)'!N31/N$128 -> 0 | O31: =SUM(C31:N31) -> 0
B32: 본사이체원가 (HQ Transfer) | C32: =+'원가이체, 판관비 배부현황(VND)'!C32/C$128 -> 0 | D32: =+'원가이체, 판관비 배부현황(VND)'!D32/D$128 -> 0 | E32: =+'원가이체, 판관비 배부현황(VND)'!E32/E$128 -> 0 | F32: =+'원가이체, 판관비 배부현황(VND)'!F32/F$128 -> 0 | G32: =+'원가이체, 판관비 배부현황(VND)'!G32/G$128 -> 0 | H32: =+'원가이체, 판관비 배부현황(VND)'!H32/H$128 -> 0 | I32: =+'원가이체, 판관비 배부현황(VND)'!I32/I$128 -> 0 | J32: =+'원가이체, 판관비 배부현황(VND)'!J32/J$128 -> 0 | ... N32: =+'원가이체, 판관비 배부현황(VND)'!N32/N$128 -> 0 | O32: =SUM(C32:N32) -> 0
B33: 판관비 (S&A Exp) | C33: =+'원가이체, 판관비 배부현황(VND)'!C33/C$128 -> 0 | D33: =+'원가이체, 판관비 배부현황(VND)'!D33/D$128 -> 0 | E33: =+'원가이체, 판관비 배부현황(VND)'!E33/E$128 -> 0 | F33: =+'원가이체, 판관비 배부현황(VND)'!F33/F$128 -> 0 | G33: =+'원가이체, 판관비 배부현황(VND)'!G33/G$128 -> 0 | H33: =+'원가이체, 판관비 배부현황(VND)'!H33/H$128 -> 0 | I33: =+'원가이체, 판관비 배부현황(VND)'!I33/I$128 -> 0 | J33: =+'원가이체, 판관비 배부현황(VND)'!J33/J$128 -> 0 | ... N33: =+'원가이체, 판관비 배부현황(VND)'!N33/N$128 -> 0 | O33: =SUM(C33:N33) -> 0
B34: 아국인 인원수 (No. of Emplyee) | C34: ='원가이체, 판관비 배부현황(VND)'!C34 -> 0 | D34: ='원가이체, 판관비 배부현황(VND)'!D34 -> 0 | E34: ='원가이체, 판관비 배부현황(VND)'!E34 -> 0 | F34: ='원가이체, 판관비 배부현황(VND)'!F34 -> 0 | G34: ='원가이체, 판관비 배부현황(VND)'!G34 -> 0 | H34: ='원가이체, 판관비 배부현황(VND)'!H34 -> 0 | I34: ='원가이체, 판관비 배부현황(VND)'!I34 -> 0 | J34: ='원가이체, 판관비 배부현황(VND)'!J34 -> 0 | ... N34: ='원가이체, 판관비 배부현황(VND)'!N34 -> 0 | O34: =SUM(C34:N34) -> 0
A35: Site 17 (H1HH1 Consulting) | B35: 매출 (Sales) | C35: =+'원가이체, 판관비 배부현황(VND)'!C35/C$128 -> 715.7562 | D35: =+'원가이체, 판관비 배부현황(VND)'!D35/D$128 -> 0 | E35: =+'원가이체, 판관비 배부현황(VND)'!E35/E$128 -> 352.81518 | F35: =+'원가이체, 판관비 배부현황(VND)'!F35/F$128 -> 0 | G35: =+'원가이체, 판관비 배부현황(VND)'!G35/G$128 -> 0 | H35: =+'원가이체, 판관비 배부현황(VND)'!H35/H$128 -> 0 | I35: =+'원가이체, 판관비 배부현황(VND)'!I35/I$128 -> 0 | J35: =+'원가이체, 판관비 배부현황(VND)'!J35/J$128 -> 0 | ... N35: =+'원가이체, 판관비 배부현황(VND)'!N35/N$128 -> 0 | O35: =SUM(C35:N35) -> 1068.5714
B36: 매출원가 (CGS) | C36: =+'원가이체, 판관비 배부현황(VND)'!C36/C$128 -> 562.15543 | D36: =+'원가이체, 판관비 배부현황(VND)'!D36/D$128 -> 0 | E36: =+'원가이체, 판관비 배부현황(VND)'!E36/E$128 -> 12.844796 | F36: =+'원가이체, 판관비 배부현황(VND)'!F36/F$128 -> 0 | G36: =+'원가이체, 판관비 배부현황(VND)'!G36/G$128 -> 0 | H36: =+'원가이체, 판관비 배부현황(VND)'!H36/H$128 -> 0 | I36: =+'원가이체, 판관비 배부현황(VND)'!I36/I$128 -> 0 | J36: =+'원가이체, 판관비 배부현황(VND)'!J36/J$128 -> 0 | ... N36: =+'원가이체, 판관비 배부현황(VND)'!N36/N$128 -> 0 | O36: =SUM(C36:N36) -> 575.00022
B37: 현장원가 (Site Cost) | C37: =+'원가이체, 판관비 배부현황(VND)'!C37/C$128 -> 546.90383 | D37: =+'원가이체, 판관비 배부현황(VND)'!D37/D$128 -> 0 | E37: =+'원가이체, 판관비 배부현황(VND)'!E37/E$128 -> 12.844796 | F37: =+'원가이체, 판관비 배부현황(VND)'!F37/F$128 -> 0 | G37: =+'원가이체, 판관비 배부현황(VND)'!G37/G$128 -> 0 | H37: =+'원가이체, 판관비 배부현황(VND)'!H37/H$128 -> 0 | I37: =+'원가이체, 판관비 배부현황(VND)'!I37/I$128 -> 0 | J37: =+'원가이체, 판관비 배부현황(VND)'!J37/J$128 -> 0 | ... N37: =+'원가이체, 판관비 배부현황(VND)'!N37/N$128 -> 0 | O37: =SUM(C37:N37) -> 559.74863
B38: 본사이체원가 (HQ Transfer) | C38: =+'원가이체, 판관비 배부현황(VND)'!C38/C$128 -> 15.251598 | D38: =+'원가이체, 판관비 배부현황(VND)'!D38/D$128 -> 0 | E38: =+'원가이체, 판관비 배부현황(VND)'!E38/E$128 -> 0 | F38: =+'원가이체, 판관비 배부현황(VND)'!F38/F$128 -> 0 | G38: =+'원가이체, 판관비 배부현황(VND)'!G38/G$128 -> 0 | H38: =+'원가이체, 판관비 배부현황(VND)'!H38/H$128 -> 0 | I38: =+'원가이체, 판관비 배부현황(VND)'!I38/I$128 -> 0 | J38: =+'원가이체, 판관비 배부현황(VND)'!J38/J$128 -> 0 | ... N38: =+'원가이체, 판관비 배부현황(VND)'!N38/N$128 -> 0 | O38: =SUM(C38:N38) -> 15.251598
B39: 판관비 (S&A Exp) | C39: =+'원가이체, 판관비 배부현황(VND)'!C39/C$128 -> 0 | D39: =+'원가이체, 판관비 배부현황(VND)'!D39/D$128 -> 0 | E39: =+'원가이체, 판관비 배부현황(VND)'!E39/E$128 -> 0 | F39: =+'원가이체, 판관비 배부현황(VND)'!F39/F$128 -> 0 | G39: =+'원가이체, 판관비 배부현황(VND)'!G39/G$128 -> 0 | H39: =+'원가이체, 판관비 배부현황(VND)'!H39/H$128 -> 0 | I39: =+'원가이체, 판관비 배부현황(VND)'!I39/I$128 -> 0 | J39: =+'원가이체, 판관비 배부현황(VND)'!J39/J$128 -> 0 | ... N39: =+'원가이체, 판관비 배부현황(VND)'!N39/N$128 -> 0 | O39: =SUM(C39:N39) -> 0
B40: 아국인 인원수 (No. of Emplyee) | C40: ='원가이체, 판관비 배부현황(VND)'!C40 -> 0 | D40: ='원가이체, 판관비 배부현황(VND)'!D40 -> 0 | E40: ='원가이체, 판관비 배부현황(VND)'!E40 -> 0 | F40: ='원가이체, 판관비 배부현황(VND)'!F40 -> 0 | G40: ='원가이체, 판관비 배부현황(VND)'!G40 -> 0 | H40: ='원가이체, 판관비 배부현황(VND)'!H40 -> 0 | I40: ='원가이체, 판관비 배부현황(VND)'!I40 -> 0 | J40: ='원가이체, 판관비 배부현황(VND)'!J40 -> 0 | ... N40: ='원가이체, 판관비 배부현황(VND)'!N40 -> 0 | O40: =SUM(C40:N40) -> 0
A41: Site 18 (Construction K8CT1) | B41: 매출 (Sales) | C41: =+'원가이체, 판관비 배부현황(VND)'!C41/C$128 -> 79.739766 | D41: =+'원가이체, 판관비 배부현황(VND)'!D41/D$128 -> 1283.8682 | E41: =+'원가이체, 판관비 배부현황(VND)'!E41/E$128 -> 590.2774 | F41: =+'원가이체, 판관비 배부현황(VND)'!F41/F$128 -> 1461.3444 | G41: =+'원가이체, 판관비 배부현황(VND)'!G41/G$128 -> 2899.3087 | H41: =+'원가이체, 판관비 배부현황(VND)'!H41/H$128 -> 4075.6747 | I41: =+'원가이체, 판관비 배부현황(VND)'!I41/I$128 -> 0 | J41: =+'원가이체, 판관비 배부현황(VND)'!J41/J$128 -> 0 | ... N41: =+'원가이체, 판관비 배부현황(VND)'!N41/N$128 -> 0 | O41: =SUM(C41:N41) -> 10390.213
...

Sheet Reparing Cost
A3: SUMMARY OF REPAIRING COST ALLOWANCE
A5: SITE | B5: DESCRIPTION | C5: DATE OF COMPLETION | D5: WARRANTY PERIOD | E5: FINAL CONTRACT AMOUNT | F5: RATE | G5: REPAIRING COST ALLOWANCE | H5: 2025 | I5: 2026 | X5: REMARK
H6: REMAINING AMOUNT | I6: Jan | J6: Feb | K6: Mar | L6: Apr | M6: May | N6: Jun | O6: Jul | P6: Aug | Q6: Sep | R6: Oct | S6: Nov | T6: Dec | U6: TOTAL | V6: REFUND | W6: REMAINING AMOUNT
A7: A | B7: B | C7: C | E7: 1 | F7: 2 | G7: 3=1*2 | H7: 5=3-4
A8: 1 | B8: Villa - Infra Phase 1 | C8: Mar.2020 ~ Mar.2022 | E8: =E9+E10 -> 1311159373245 | G8: =G9+G10 -> 10724957525 | H8: 0 | I8: =I9+I10 -> 0 | U8: =SUM(H8:I8) -> 0 | V8: 0 | W8: 0
B9: Villa part | E9: 949521088397 | F9: 0.0108 | G9: =ROUND(F9*E9,0) -> 10254827755 | H9: 0 | U9: =SUM(H9:I9) -> 0 | V9: 0 | W9: 0
B10: Infra part | E10: 361638284848 | F10: 0.0013 | G10: =ROUND(F10*E10,0) -> 470129770 | H10: 0 | U10: =SUM(H10:I10) -> 0 | V10: 0 | W10: 0
A11: 03 | B11: H9CT1 | C11: Dec.2020 ~ Dec.2022 | E11: 2166776114349 | F11: 0.0096 | G11: =ROUND(F11*E11,0) -> 20801050698 | H11: 0 | U11: =SUM(I11:I11) -> 0 | V11: 0 | W11: 0
A12: 07 | B12: Villa K3 | C12: Dec.2021 ~ Dec.2023 | E12: 516092416153 | F12: 0.008 | G12: =ROUND(F12*E12,0) -> 4128739329 | H12: 0 | U12: =SUM(I12:I12) -> 0 | V12: 0 | W12: =H12-U12-V12 -> 0
A13: 10 | B13: Villa K5K7 | C13: Nov.2022~Nov.2024 | E13: 531271745117 | F13: 0.0115 | G13: =ROUND(F13*E13,0) -> 6109625069 | H13: 0 | U13: =+SUM(I13:I13) -> 0 | W13: =H13+U13+V13 -> 0
A14: 24 | B14: Operation office & mock-up house of THT | C14: Apr.2024~Apr.2025 | E14: 8804407658 | F14: 0.0032 | G14: =ROUND(F14*E14,0) -> 28174105 | H14: 0 | U14: =+SUM(I14:I14) -> 0 | V14: 0 | W14: =H14+U14+V14 -> 0
A15: 18 | B15: Construction K8CT1 | F15: 0.0116 | H15: 1609227132 | I15: 24043038 | J15: 388555008 | K15: =+'Summary 2026'!G51 -> 180533745 | L15: 446827079 | M15: 885361893 | N15: 1243643234 | U15: =+SUM(I15:T15) -> 3168963997 | W15: =H15+U15+V15 -> 4778191129 | X15: Long-term
A16: 23 | B16: Construction K8HH1 | F16: 0.0063 | G16: 0 | H16: 6226370228 | I16: 28534009 | J16: 558604649 | K16: =+'Summary 2026'!G52 -> 290765752 | L16: 588246657 | M16: 874949579 | N16: 562698907 | U16: =+SUM(I16:T16) -> 2903799553 | W16: =H16+U16+V16 -> 9130169781 | X16: Long-term
A17: 27 | B17: Mockup house of THT-Phase 2 | C17: 46126 | D17: 12 months | E17: 45888984025 | F17: 0.0032 | G17: =+F17*E17 -> 1.4684475e+08 | H17: 136755746 | K17: =+'Summary 2026'!G53 -> 0 | L17: 10089003 | U17: =+SUM(I17:T17) -> 10089003 | W17: =H17+U17+V17 -> 146844749 | X17: Short-term
A18: 28 | B18: Nhon Trach Infra | D18: 12 months | F18: 0.0014 | G18: 0 | H18: 301880813 | K18: =+'Summary 2026'!G54 -> 0 | M18: -2540606 | U18: =+SUM(I18:T18) -> -2540606 | W18: =H18+U18+V18 -> 299340207 | X18: Short-term
A19: TOTAL | G19: =+SUM(G16:G18) -> 1.4684475e+08 | H19: =+SUM(H15:H18) -> 8274233919 | I19: =+SUM(I15:I18) -> 52577047 | J19: =+SUM(J15:J18) -> 947159657 | K19: =+SUM(K15:K18) -> 471299497 | L19: =+SUM(L15:L18) -> 1045162739 | M19: =+SUM(M15:M18) -> 1757770866 | N19: =+SUM(N15:N18) -> 1806342141 | O19: =+SUM(O15:O18) -> 0 | ... W19: =+SUM(W15:W18) -> 14354545866

Sheet Summary 2026
D1: DAEWOO VINA
D2: SUMMARY SALES + COGS 2026
E3: =+SUBTOTAL(9,E9:E23) -> 61352023012 | F3: =+SUBTOTAL(9,F9:F27) -> 146586099975 | G3: =+SUBTOTAL(9,G9:G26) -> 90817850714 | H3: =+SUBTOTAL(9,H9:H26) -> 138006342444 | I3: =+SUBTOTAL(9,I9:I23) -> 209788460017 | J3: =+SUBTOTAL(9,J9:J28) -> 196741611577 | K3: =+SUBTOTAL(9,K9:K23) -> 0 | L3: =+SUBTOTAL(9,L9:L23) -> 0 | M3: =+SUBTOTAL(9,M9:M24) -> 0 | N3: =+SUBTOTAL(9,N9:N24) -> 0 | O3: =+SUBTOTAL(9,O9:O24) -> 0 | P3: =+SUBTOTAL(9,P9:P24) -> 0 | Q3: =+SUBTOTAL(9,Q9:Q24) -> 831607991796
E4: =+SUBTOTAL(9,E30:E55) -> 31422009296 | F4: =+SUBTOTAL(9,F30:F56) -> 113338911619 | G4: =+SUBTOTAL(9,G30:G56) -> 65100801201 | H4: =+SUBTOTAL(9,H30:H56) -> 120738364051 | I4: =+SUBTOTAL(9,I30:I56) -> 182028135308 | J4: =+SUBTOTAL(9,J30:J56) -> 169887161193 | K4: =+SUBTOTAL(9,K30:K56) -> 0 | L4: =+SUBTOTAL(9,L30:L56) -> 0 | M4: =+SUBTOTAL(9,M30:M56) -> 0 | ... Q4: =+SUBTOTAL(9,Q30:Q56) -> 682515382668
D5: Month | E5: 2026
E6: VND | R6: TOTAL up to 2026 | S6: 1000 USD
E7: 46023 | F7: 46054 | G7: 46082 | H7: 46113 | I7: 46143 | J7: 46174 | K7: 46204 | L7: 46235 | M7: 46266 | N7: 46296 | O7: 46327 | P7: 46357 | Q7: Total VND | S7: 46023 | T7: 46054 | U7: 46082 | V7: 46113 | W7: 46143 | X7: 46174 | Y7: 46204 | Z7: 46235 | AA7: 46266 | AB7: 46296 | AC7: 46327 | AD7: 46357 | AE7: Total 1000 USD
D8: Revenue | E8: =SUM(E9:E27) -> 61352023012 | F8: =SUM(F9:F27) -> 146586099975 | G8: =SUM(G9:G27) -> 90817850714 | H8: =SUM(H9:H27) -> 138006342444 | I8: =SUM(I9:I28) -> 211247592323 | J8: =SUM(J9:J28) -> 196741611577 | K8: =SUM(K9:K28) -> 0 | L8: =SUM(L9:L28) -> 0 | M8: =SUM(M9:M28) -> 0 | N8: =SUM(N9:N28) -> 0 | O8: =SUM(O9:O28) -> 0 | P8: =SUM(P9:P28) -> 0 | ... AE8: =SUM(AE9:AE28) -> 32162.807 | AF8: =+X8-'[1]IS (01)'!$F$6 -> 0 | AG8: =+AE8-'[1]IS (01)'!$G$6 -> 0.0072019848
A9: SITE05 | C9: O&M | D9: SITE05 - Infra Management | E9: 1593627000 | F9: 1593627000 | G9: 2143475816 | Q9: =SUM(E9:P9) -> 5330729816 | R9: =+Q9+'Summary 2025'!Q9 -> 123969759233 | S9: =E9/$S$55 -> 61.309853 | T9: =F9/$T$55 -> 61.081909 | U9: =G9/$U$55 -> 81.296966 | V9: =H9/$V$55 -> 0 | W9: =I9/$W$55 -> 0 | X9: =ROUND(J9/$X$55,2) -> 0 | Y9: =K9/$Y$55 -> 0 | Z9: =ROUND(L9/$Z$55,2) -> 0 | AA9: =ROUND(M9/$AA$55,2) -> 0 | AB9: =ROUND(N9/$AB$55,2) -> 0 | AC9: =ROUND(O9/$AC$55,2) -> 0 | AD9: =ROUND(P9/$AD$55,2) -> 0 | AE9: =SUM(S9:AD9) -> 203.68873
A10: SITE06 | B10: Infra | C10: Construction | D10: SITE06 - Infra Phase II | E10: 1542200224 | F10: 9761784424 | G10: 8010675534 | H10: 9796332935 | I10: 9416448788 | J10: 9123243464 | Q10: =SUM(E10:P10) -> 47650685369 | R10: =+Q10+'Summary 2025'!Q10 -> 1.1368545e+12 | S10: =E10/$S$55 -> 59.331367 | T10: =F10/$T$55 -> 374.15808 | U10: =G10/$U$55 -> 303.82597 | V10: =H10/$V$55 -> 371.6504 | W10: =I10/$W$55 -> 357.69986 | X10: =ROUND(J10/$X$55,2) -> 346.83 | Y10: =K10/$Y$55 -> 0 | Z10: =ROUND(L10/$Z$55,2) -> 0 | AA10: =ROUND(M10/$AA$55,2) -> 0 | AB10: =ROUND(N10/$AB$55,2) -> 0 | AC10: =ROUND(O10/$AC$55,2) -> 0 | AD10: =ROUND(P10/$AD$55,2) -> 0 | AE10: =SUM(S10:AD10) -> 1813.4957
A11: SITE08 | C11: Consulting | D11: SITE08 - B3CC1 | G11: 0 | I11: 0 | Q11: =SUM(E11:P11) -> 0 | R11: =+Q11+'Summary 2025'!Q11 -> 104618100000 | S11: =E11/$S$55 -> 0 | T11: =F11/$T$55 -> 0 | U11: =G11/$U$55 -> 0 | V11: =H11/$V$55 -> 0 | W11: =I11/$W$55 -> 0 | X11: =ROUND(J11/$X$55,2) -> 0 | Y11: =K11/$Y$55 -> 0 | Z11: =ROUND(L11/$Z$55,2) -> 0 | AA11: =ROUND(M11/$AA$55,2) -> 0 | AB11: =ROUND(N11/$AB$55,2) -> 0 | AC11: =ROUND(O11/$AC$55,2) -> 0 | AD11: =ROUND(P11/$AD$55,2) -> 0 | AE11: =SUM(S11:AD11) -> 0
A12: =+LEFT(D12,6) -> SITE14 | C12: Consulting | D12: SITE14 - B1CC4 | E12: 4774000000 | G12: 0 | I12: 0 | Q12: =SUM(E12:P12) -> 4774000000 | R12: =+Q12+'Summary 2025'!Q12 -> 38192000000 | S12: =E12/$S$55 -> 183.66483 | T12: =F12/$T$55 -> 0 | U12: =G12/$U$55 -> 0 | V12: =H12/$V$55 -> 0 | W12: =I12/$W$55 -> 0 | X12: =ROUND(J12/$X$55,2) -> 0 | Y12: =K12/$Y$55 -> 0 | Z12: =ROUND(L12/$Z$55,2) -> 0 | AA12: =ROUND(M12/$AA$55,2) -> 0 | AB12: =ROUND(N12/$AB$55,2) -> 0 | AC12: =ROUND(O12/$AC$55,2) -> 0 | AD12: =ROUND(P12/$AD$55,2) -> 0 | AE12: =SUM(S12:AD12) -> 183.66483
A13: =+LEFT(D13,6) -> SITE16 | C13: Consulting | D13: SITE16 - Precons K8CT1 | G13: 0 | I13: 0 | Q13: =SUM(E13:P13) -> 0 | R13: =+Q13+'Summary 2025'!Q13 -> 39781808000 | S13: =E13/$S$55 -> 0 | T13: =F13/$T$55 -> 0 | U13: =G13/$U$55 -> 0 | V13: =H13/$V$55 -> 0 | W13: =I13/$W$55 -> 0 | X13: =ROUND(J13/$X$55,2) -> 0 | Y13: =K13/$Y$55 -> 0 | Z13: =ROUND(L13/$Z$55,2) -> 0 | AA13: =ROUND(M13/$AA$55,2) -> 0 | AB13: =ROUND(N13/$AB$55,2) -> 0 | AC13: =ROUND(O13/$AC$55,2) -> 0 | AD13: =ROUND(P13/$AD$55,2) -> 0 | AE13: =SUM(S13:AD13) -> 0
A14: =+LEFT(D14,6) -> SITE17 | C14: Consulting | D14: SITE17 - H1HH1 | E14: 18604651000 | G14: 9302325000 | I14: 0 | Q14: =SUM(E14:P14) -> 27906976000 | R14: =+Q14+'Summary 2025'!Q14 -> 27906976000 | S14: =E14/$S$55 -> 715.7562 | T14: =F14/$T$55 -> 0 | U14: =G14/$U$55 -> 352.81518 | V14: =H14/$V$55 -> 0 | W14: =I14/$W$55 -> 0 | X14: =ROUND(J14/$X$55,2) -> 0 | Y14: =K14/$Y$55 -> 0 | Z14: =ROUND(L14/$Z$55,2) -> 0 | AA14: =ROUND(M14/$AA$55,2) -> 0 | AB14: =ROUND(N14/$AB$55,2) -> 0 | AC14: =ROUND(O14/$AC$55,2) -> 0 | AD14: =ROUND(P14/$AD$55,2) -> 0 | AE14: =SUM(S14:AD14) -> 1068.5714
A15: =+LEFT(D15,6) -> SITE18 | B15: Housing | C15: Construction | D15: SITE18 - Construction K8CT1 | E15: 2072675730 | F15: 33496121350 | G15: 15563253849 | H15: 38519575773 | I15: 76324301108 | J15: 107210623606 | Q15: =SUM(E15:P15) -> 273186551416 | R15: =+Q15+'Summary 2025'!Q15 -> 411913028309 | S15: =E15/$S$55 -> 79.739766 | T15: =F15/$T$55 -> 1283.8682 | U15: =G15/$U$55 -> 590.2774 | V15: =H15/$V$55 -> 1461.3444 | W15: =I15/$W$55 -> 2899.3087 | X15: =ROUND(J15/$X$55,2) -> 4075.67 | Y15: =K15/$Y$55 -> 0 | Z15: =ROUND(L15/$Z$55,2) -> 0 | AA15: =ROUND(M15/$AA$55,2) -> 0 | AB15: =ROUND(N15/$AB$55,2) -> 0 | AC15: =ROUND(O15/$AC$55,2) -> 0 | AD15: =ROUND(P15/$AD$55,2) -> 0 | AE15: =SUM(S15:AD15) -> 10390.208
A16: =+LEFT(D16,6) -> SITE20 | C16: Consulting | D16: SITE20 - Precons K2CT1 | G16: 0 | I16: 0 | Q16: =SUM(E16:P16) -> 0 | R16: =+Q16+'Summary 2025'!Q16 -> 23822780000 | S16: =E16/$S$55 -> 0 | T16: =F16/$T$55 -> 0 | U16: =G16/$U$55 -> 0 | V16: =H16/$V$55 -> 0 | W16: =I16/$W$55 -> 0 | X16: =ROUND(J16/$X$55,2) -> 0 | Y16: =K16/$Y$55 -> 0 | Z16: =ROUND(L16/$Z$55,2) -> 0 | AA16: =ROUND(M16/$AA$55,2) -> 0 | AB16: =ROUND(N16/$AB$55,2) -> 0 | AC16: =ROUND(O16/$AC$55,2) -> 0 | AD16: =ROUND(P16/$AD$55,2) -> 0 | AE16: =SUM(S16:AD16) -> 0
A17: =+LEFT(D17,6) -> SITE22 | C17: O&M | D17: SITE22 - Villa H&K Management | E17: 2408912500 | F17: 2408912500 | G17: 2408912500 | I17: 0 | Q17: =SUM(E17:P17) -> 7226737500 | R17: =+Q17+'Summary 2025'!Q17 -> 78652162500 | S17: =E17/$S$55 -> 92.675432 | T17: =F17/$T$55 -> 92.330874 | U17: =G17/$U$55 -> 91.364352 | V17: =H17/$V$55 -> 0 | W17: =I17/$W$55 -> 0 | X17: =ROUND(J17/$X$55,2) -> 0 | Y17: =K17/$Y$55 -> 0 | Z17: =ROUND(L17/$Z$55,2) -> 0 | AA17: =ROUND(M17/$AA$55,2) -> 0 | AB17: =ROUND(N17/$AB$55,2) -> 0 | AC17: =ROUND(O17/$AC$55,2) -> 0 | AD17: =ROUND(P17/$AD$55,2) -> 0 | AE17: =SUM(S17:AD17) -> 276.37066
A18: =+LEFT(D18,6) -> SITE23 | B18: Housing | C18: Construction | D18: SITE23 - Construction K8HH1 | E18: 4018874509 | F18: 78676711142 | G18: 40952922858 | H18: 82851641855 | I18: 123232335065 | J18: 79253367236 | Q18: =SUM(E18:P18) -> 408985852665 | R18: =+Q18+'Summary 2025'!Q18 -> 1285939405969 | S18: =E18/$S$55 -> 154.61372 | T18: =F18/$T$55 -> 3015.5888 | U18: =G18/$U$55 -> 1553.2475 | V18: =H18/$V$55 -> 3143.2013 | W18: =I18/$W$55 -> 4681.1903 | X18: =ROUND(J18/$X$55,2) -> 3012.86 | Y18: =K18/$Y$55 -> 0 | Z18: =ROUND(L18/$Z$55,2) -> 0 | AA18: =ROUND(M18/$AA$55,2) -> 0 | AB18: =ROUND(N18/$AB$55,2) -> 0 | AC18: =ROUND(O18/$AC$55,2) -> 0 | AD18: =ROUND(P18/$AD$55,2) -> 0 | AE18: =SUM(S18:AD18) -> 15560.702
A19: =+LEFT(D19,6) -> SITE27 | B19: Housing | C19: Construction | D19: SITE27 - Mockup house of THT-Phase 2 | G19: 0 | H19: 3152813293 | I19: 0 | Q19: =SUM(E19:P19) -> 3152813293 | R19: =+Q19+'Summary 2025'!Q19 -> 45888984025 | S19: =E19/$S$55 -> 0 | T19: =F19/$T$55 -> 0 | U19: =G19/$U$55 -> 0 | V19: =H19/$V$55 -> 119.6105 | W19: =I19/$W$55 -> 0 | X19: =ROUND(J19/$X$55,2) -> 0 | Y19: =K19/$Y$55 -> 0 | Z19: =ROUND(L19/$Z$55,2) -> 0 | AA19: =ROUND(M19/$AA$55,2) -> 0 | AB19: =ROUND(N19/$AB$55,2) -> 0 | AC19: =ROUND(O19/$AC$55,2) -> 0 | AD19: =ROUND(P19/$AD$55,2) -> 0 | AE19: =SUM(S19:AD19) -> 119.6105
A20: =+LEFT(D20,6) -> SITE28 | B20: Infra | C20: Construction | D20: SITE28 - Nhon Trach Infra | G20: 0 | I20: -1814718058 | Q20: =SUM(E20:P20) -> -1814718058 | R20: =+Q20+'Summary 2025'!Q20 -> 213814433247 | S20: =E20/$S$55 -> 0 | T20: =F20/$T$55 -> 0 | U20: =G20/$U$55 -> 0 | V20: =H20/$V$55 -> 0 | W20: =I20/$W$55 -> -68.935159 | X20: =ROUND(J20/$X$55,2) -> 0 | Y20: =K20/$Y$55 -> 0 | Z20: =ROUND(L20/$Z$55,2) -> 0 | AA20: =ROUND(M20/$AA$55,2) -> 0 | AB20: =ROUND(N20/$AB$55,2) -> 0 | AC20: =ROUND(O20/$AC$55,2) -> 0 | AD20: =ROUND(P20/$AD$55,2) -> 0 | AE20: =SUM(S20:AD20) -> -68.935159
A21: =+LEFT(D21,6) -> SITE30 | C21: Consulting | D21: SITE30 - Brokerage for K8HH1 Building distribution | E21: 26161676872 | F21: 18559516555 | G21: 4611506400 | I21: 2553696661 | Q21: =SUM(E21:P21) -> 51886396488 | R21: =+Q21+'Summary 2025'!Q22 -> 237856652925 | S21: =E21/$S$55 -> 1006.4893 | T21: =F21/$T$55 -> 711.36514 | U21: =G21/$U$55 -> 174.90353 | V21: =H21/$V$55 -> 0 | W21: =I21/$W$55 -> 97.006521 | X21: =ROUND(J21/$X$55,2) -> 0 | Y21: =K21/$Y$55 -> 0 | Z21: =ROUND(L21/$Z$55,2) -> 0 | AA21: =ROUND(M21/$AA$55,2) -> 0 | AB21: =ROUND(N21/$AB$55,2) -> 0 | AC21: =ROUND(O21/$AC$55,2) -> 0 | AD21: =ROUND(P21/$AD$55,2) -> 0 | AE21: =SUM(S21:AD21) -> 1989.7645
A22: =+LEFT(D22,6) -> SITE31 | C22: Consulting | D22: SITE31 - Brokerage for H9CT1 & K8HH1 Shophouse distribution | G22: 0 | I22: 0 | Q22: =SUM(E22:P22) -> 0 | R22: =+Q22+'Summary 2025'!Q23 -> 0 | S22: =E22/$S$55 -> 0 | T22: =F22/$T$55 -> 0 | U22: =G22/$U$55 -> 0 | V22: =H22/$V$55 -> 0 | W22: =I22/$W$55 -> 0 | X22: =ROUND(J22/$X$55,2) -> 0 | Y22: =K22/$Y$55 -> 0 | Z22: =ROUND(L22/$Z$55,2) -> 0 | AA22: =ROUND(M22/$AA$55,2) -> 0 | AB22: =ROUND(N22/$AB$55,2) -> 0 | AC22: =ROUND(O22/$AC$55,2) -> 0 | AD22: =ROUND(P22/$AD$55,2) -> 0 | AE22: =SUM(S22:AD22) -> 0
A23: =+LEFT(D23,6) -> SITE34 | B23: Housing | C23: Construction | D23: SITE34 - Defect repairing for H9CT1 | E23: 175405177 | F23: 211832004 | G23: 1390742757 | H23: 2077469588 | I23: 76396453 | J23: -609878672 | Q23: =SUM(E23:P23) -> 3321967307 | R23: =+Q23+'Summary 2025'!Q26 -> 20334632038 | S23: =E23/$S$55 -> 6.7481698 | T23: =F23/$T$55 -> 8.1192796 | U23: =G23/$U$55 -> 52.747582 | V23: =H23/$V$55 -> 78.814431 | W23: =I23/$W$55 -> 2.9020495 | X23: =ROUND(J23/$X$55,2) -> -23.18 | Y23: =K23/$Y$55 -> 0 | Z23: =ROUND(L23/$Z$55,2) -> 0 | AA23: =ROUND(M23/$AA$55,2) -> 0 | AB23: =ROUND(N23/$AB$55,2) -> 0 | AC23: =ROUND(O23/$AC$55,2) -> 0 | AD23: =ROUND(P23/$AD$55,2) -> 0 | AE23: =SUM(S23:AD23) -> 126.15151
A24: =+LEFT(D24,6) -> SITE35 | C24: Consulting | D24: SITE35 - Precons K2HH1 | G24: 0 | I24: 0 | Q24: =SUM(E24:P24) -> 0 | R24: =+Q24+'Summary 2025'!Q27 -> 10120000000 | S24: =E24/$S$55 -> 0 | T24: =F24/$T$55 -> 0 | U24: =G24/$U$55 -> 0 | V24: =H24/$V$55 -> 0 | W24: =I24/$W$55 -> 0 | X24: =ROUND(J24/$X$55,2) -> 0 | Y24: =K24/$Y$55 -> 0 | Z24: =ROUND(L24/$Z$55,2) -> 0 | AA24: =ROUND(M24/$AA$55,2) -> 0 | AB24: =ROUND(N24/$AB$55,2) -> 0 | AC24: =ROUND(O24/$AC$55,2) -> 0 | AD24: =ROUND(P24/$AD$55,2) -> 0 | AE24: =SUM(S24:AD24) -> 0
A25: =+LEFT(D25,6) -> SITE36 | C25: Consulting | D25: SITE36 - Pile testing B1CC4 | F25: 1877595000 | G25: 0 | I25: 0 | Q25: =SUM(E25:P25) -> 1877595000 | R25: =+Q25+'Summary 2025'!Q28 -> 9387975000 | S25: =E25/$S$55 -> 0 | T25: =F25/$T$55 -> 71.966079 | U25: =G25/$U$55 -> 0 | V25: =H25/$V$55 -> 0 | W25: =I25/$W$55 -> 0 | X25: =ROUND(J25/$X$55,2) -> 0 | Y25: =K25/$Y$55 -> 0 | Z25: =ROUND(L25/$Z$55,2) -> 0 | AA25: =ROUND(M25/$AA$55,2) -> 0 | AB25: =ROUND(N25/$AB$55,2) -> 0 | AC25: =ROUND(O25/$AC$55,2) -> 0 | AD25: =ROUND(P25/$AD$55,2) -> 0 | AE25: =SUM(S25:AD25) -> 71.966079
A26: =+LEFT(D26,6) -> SITE37 | C26: Consulting | D26: SITE37 - Pile testing H1HH1 | G26: 6434036000 | H26: 1608509000 | I26: 0 | Q26: =SUM(E26:P26) -> 8042545000 | R26: =+Q26 -> 8042545000 | S26: =E26/$S$55 -> 0 | T26: =F26/$T$55 -> 0 | U26: =G26/$U$55 -> 244.02776 | V26: =H26/$V$55 -> 61.023142 | W26: =I26/$W$55 -> 0 | X26: =ROUND(J26/$X$55,2) -> 0 | Y26: =K26/$Y$55 -> 0 | Z26: =ROUND(L26/$Z$55,2) -> 0 | AA26: =ROUND(M26/$AA$55,2) -> 0 | AB26: =ROUND(N26/$AB$55,2) -> 0 | AC26: =ROUND(O26/$AC$55,2) -> 0 | AD26: =ROUND(P26/$AD$55,2) -> 0 | AE26: =SUM(S26:AD26) -> 305.05091
A27: =+LEFT(D27,6) -> SITE38 | C27: Construction | D27: SITE38 - Temporary gate & Fence for H1HH1 | G27: 0 | I27: 0 | Q27: =SUM(E27:P27) -> 0 | R27: =+Q27 -> 0 | S27: =E27/$S$55 -> 0 | T27: =F27/$T$55 -> 0 | U27: =G27/$U$55 -> 0 | V27: =H27/$V$55 -> 0 | W27: =I27/$W$55 -> 0 | X27: =ROUND(J27/$X$55,2) -> 0 | Y27: =K27/$Y$55 -> 0 | Z27: =ROUND(L27/$Z$55,2) -> 0 | AA27: =ROUND(M27/$AA$55,2) -> 0 | AB27: =ROUND(N27/$AB$55,2) -> 0 | AC27: =ROUND(O27/$AC$55,2) -> 0 | AD27: =ROUND(P27/$AD$55,2) -> 0 | AE27: =SUM(S27:AD27) -> 0
A28: =+LEFT(D28,6) -> SITE39 | B28: Housing | C28: Construction | D28: SITE39 - Mockup house of THT-Phase 3 | I28: 1459132306 | J28: 1764255943 | Q28: =SUM(E28:P28) -> 3223388249 | R28: =+I28 -> 1459132306 | W28: =I28/$W$55 -> 55.427628 | X28: =ROUND(J28/$X$55,2) -> 67.07 | AE28: =SUM(S28:AD28) -> 122.49763
D29: COGS | E29: =SUM(E30:E48) -> 31316855202 | F29: =SUM(F30:F48) -> 111444592305 | G29: =SUM(G30:G48) -> 64158202207 | H29: =SUM(H30:H48) -> 118648038573 | I29: =SUM(I30:I49) -> 178507512364 | J29: =SUM(J30:J49) -> 166274476911 | K29: =SUM(K30:K49) -> 0 | L29: =SUM(L30:L49) -> 0 | M29: =SUM(M30:M49) -> 0 | N29: =SUM(N30:N49) -> 0 | O29: =SUM(O30:O49) -> 0 | P29: =SUM(P30:P49) -> 0 | ... AE29: =SUM(AE30:AE49) -> 25512.899 | AF29: =+X29-'[1]IS (01)'!$F$14 -> 0 | AG29: =+AE29-'[1]IS (01)'!$G$14 -> 0.0085688926
A30: =+LEFT(D30,6) -> SITE05 | C30: O&M | D30: SITE05 - Infra Management | E30: 765010240 | F30: 1068076592 | G30: 1700502515 | H30: 330291789 | I30: 0 | Q30: =SUM(E30:P30) -> 3863881136 | R30: =+Q30+'Summary 2025'!Q30 -> 109203185029 | S30: =E30/$S$55 -> 29.431395 | T30: =F30/$T$55 -> 40.93816 | U30: =G30/$U$55 -> 64.496037 | V30: =H30/$V$55 -> 12.530513 | W30: =I30/$W$55 -> 0 | X30: =ROUND(J30/$X$55,2) -> 0 | Y30: =K30/$Y$55 -> 0 | Z30: =ROUND(L30/$Z$55,2) -> 0 | AA30: =ROUND(M30/$AA$55,2) -> 0 | AB30: =ROUND(N30/$AB$55,2) -> 0 | AC30: =ROUND(O30/$AC$55,2) -> 0 | AD30: =ROUND(P30/$AD$55,2) -> 0 | AE30: =SUM(S30:AD30) -> 147.3961
A31: =+LEFT(D31,6) -> SITE06 | B31: Infra | C31: Construction | D31: SITE06 - Infra Phase II | E31: 1342485295 | F31: 8497633341 | G31: 6973293052 | H31: 8527707820 | I31: 8197018670 | J31: 7941783435 | Q31: =SUM(E31:P31) -> 41479921613 | R31: =+Q31+'Summary 2025'!Q31 -> 989631883657 | S31: =E31/$S$55 -> 51.647955 | T31: =F31/$T$55 -> 325.70461 | U31: =G31/$U$55 -> 264.48051 | V31: =H31/$V$55 -> 323.52167 | W31: =I31/$W$55 -> 311.37773 | X31: =ROUND(J31/$X$55,2) -> 301.91 | Y31: =K31/$Y$55 -> 0 | Z31: =ROUND(L31/$Z$55,2) -> 0 | AA31: =ROUND(M31/$AA$55,2) -> 0 | AB31: =ROUND(N31/$AB$55,2) -> 0 | AC31: =ROUND(O31/$AC$55,2) -> 0 | AD31: =ROUND(P31/$AD$55,2) -> 0 | AE31: =SUM(S31:AD31) -> 1578.6425
A32: =+LEFT(D32,6) -> SITE08 | C32: Consulting | D32: SITE08 - B3CC1 | G32: 0 | I32: 0 | Q32: =SUM(E32:P32) -> 0 | R32: =+Q32+'Summary 2025'!Q32 -> 20208965609 | S32: =E32/$S$55 -> 0 | T32: =F32/$T$55 -> 0 | U32: =G32/$U$55 -> 0 | V32: =H32/$V$55 -> 0 | W32: =I32/$W$55 -> 0 | X32: =ROUND(J32/$X$55,2) -> 0 | Y32: =K32/$Y$55 -> 0 | Z32: =ROUND(L32/$Z$55,2) -> 0 | AA32: =ROUND(M32/$AA$55,2) -> 0 | AB32: =ROUND(N32/$AB$55,2) -> 0 | AC32: =ROUND(O32/$AC$55,2) -> 0 | AD32: =ROUND(P32/$AD$55,2) -> 0 | AE32: =SUM(S32:AD32) -> 0
A33: =+LEFT(D33,6) -> SITE14 | C33: Consulting | D33: SITE14 - B1CC4 | E33: 1762265417 | G33: 0 | I33: 0 | Q33: =SUM(E33:P33) -> 1762265417 | R33: =+Q33+'Summary 2025'!Q33 -> 15048974984 | S33: =E33/$S$55 -> 67.797692 | T33: =F33/$T$55 -> 0 | U33: =G33/$U$55 -> 0 | V33: =H33/$V$55 -> 0 | W33: =I33/$W$55 -> 0 | X33: =ROUND(J33/$X$55,2) -> 0 | Y33: =K33/$Y$55 -> 0 | Z33: =ROUND(L33/$Z$55,2) -> 0 | AA33: =ROUND(M33/$AA$55,2) -> 0 | AB33: =ROUND(N33/$AB$55,2) -> 0 | AC33: =ROUND(O33/$AC$55,2) -> 0 | AD33: =ROUND(P33/$AD$55,2) -> 0 | AE33: =SUM(S33:AD33) -> 67.797692
A34: =+LEFT(D34,6) -> SITE16 | C34: Consulting | D34: SITE16 - Precons K8CT1 | G34: 0 | I34: 0 | Q34: =SUM(E34:P34) -> 0 | R34: =+Q34+'Summary 2025'!Q34 -> 21060715417 | S34: =E34/$S$55 -> 0 | T34: =F34/$T$55 -> 0 | U34: =G34/$U$55 -> 0 | V34: =H34/$V$55 -> 0 | W34: =I34/$W$55 -> 0 | X34: =ROUND(J34/$X$55,2) -> 0 | Y34: =K34/$Y$55 -> 0 | Z34: =ROUND(L34/$Z$55,2) -> 0 | AA34: =ROUND(M34/$AA$55,2) -> 0 | AB34: =ROUND(N34/$AB$55,2) -> 0 | AC34: =ROUND(O34/$AC$55,2) -> 0 | AD34: =ROUND(P34/$AD$55,2) -> 0 | AE34: =SUM(S34:AD34) -> 0
A35: =+LEFT(D35,6) -> SITE17 | C35: Consulting | D35: SITE17 - H1HH1 | E35: 14612106035 | G35: 338665881 | I35: 0 | Q35: =SUM(E35:P35) -> 14950771916 | R35: =+Q35+'Summary 2025'!Q35 -> 14950771916 | S35: =E35/$S$55 -> 562.15543 | T35: =F35/$T$55 -> 0 | U35: =G35/$U$55 -> 12.844796 | V35: =H35/$V$55 -> 0 | W35: =I35/$W$55 -> 0 | X35: =ROUND(J35/$X$55,2) -> 0 | Y35: =K35/$Y$55 -> 0 | Z35: =ROUND(L35/$Z$55,2) -> 0 | AA35: =ROUND(M35/$AA$55,2) -> 0 | AB35: =ROUND(N35/$AB$55,2) -> 0 | AC35: =ROUND(O35/$AC$55,2) -> 0 | AD35: =ROUND(P35/$AD$55,2) -> 0 | AE35: =SUM(S35:AD35) -> 575.00022
A36: =+LEFT(D36,6) -> SITE18 | B36: Housing | C36: Construction | D36: SITE18 - Construction K8CT1 | E36: 1737731332 | F36: 28083148140 | G36: 13048232027 | H36: 32294812328 | I36: 63990294049 | J36: 89885386831 | Q36: =SUM(E36:P36) -> 229039604707 | R36: =+Q36+'Summary 2025'!Q36 -> 346957110066 | S36: =E36/$S$55 -> 66.85382 | T36: =F36/$T$55 -> 1076.3951 | U36: =G36/$U$55 -> 494.88857 | V36: =H36/$V$55 -> 1225.1911 | W36: =I36/$W$55 -> 2430.7804 | X36: =ROUND(J36/$X$55,2) -> 3417.05 | Y36: =K36/$Y$55 -> 0 | Z36: =ROUND(L36/$Z$55,2) -> 0 | AA36: =ROUND(M36/$AA$55,2) -> 0 | AB36: =ROUND(N36/$AB$55,2) -> 0 | AC36: =ROUND(O36/$AC$55,2) -> 0 | AD36: =ROUND(P36/$AD$55,2) -> 0 | AE36: =SUM(S36:AD36) -> 8711.159
A37: =+LEFT(D37,6) -> SITE20 | C37: Consulting | D37: SITE20 - Precons K2CT1 | G37: 0 | I37: 0 | Q37: =SUM(E37:P37) -> 0 | R37: =+Q37+'Summary 2025'!Q37 -> 10046168062 | S37: =E37/$S$55 -> 0 | T37: =F37/$T$55 -> 0 | U37: =G37/$U$55 -> 0 | V37: =H37/$V$55 -> 0 | W37: =I37/$W$55 -> 0 | X37: =ROUND(J37/$X$55,2) -> 0 | Y37: =K37/$Y$55 -> 0 | Z37: =ROUND(L37/$Z$55,2) -> 0 | AA37: =ROUND(M37/$AA$55,2) -> 0 | AB37: =ROUND(N37/$AB$55,2) -> 0 | AC37: =ROUND(O37/$AC$55,2) -> 0 | AD37: =ROUND(P37/$AD$55,2) -> 0 | AE37: =SUM(S37:AD37) -> 0
A38: =+LEFT(D38,6) -> SITE22 | C38: O&M | D38: SITE22 - Villa H&K Management | E38: 1590816166 | F38: 2035919803 | G38: 2541362899 | H38: 119246040 | I38: 0 | Q38: =SUM(E38:P38) -> 6287344908 | R38: =+Q38+'Summary 2025'!Q38 -> 70215035698 | S38: =E38/$S$55 -> 61.201715 | T38: =F38/$T$55 -> 78.034488 | U38: =G38/$U$55 -> 96.387882 | V38: =H38/$V$55 -> 4.5239212 | W38: =I38/$W$55 -> 0 | X38: =ROUND(J38/$X$55,2) -> 0 | Y38: =K38/$Y$55 -> 0 | Z38: =ROUND(L38/$Z$55,2) -> 0 | AA38: =ROUND(M38/$AA$55,2) -> 0 | AB38: =ROUND(N38/$AB$55,2) -> 0 | AC38: =ROUND(O38/$AC$55,2) -> 0 | AD38: =ROUND(P38/$AD$55,2) -> 0 | AE38: =SUM(S38:AD38) -> 240.14801
A39: =+LEFT(D39,6) -> SITE23 | B39: Housing | C39: Construction | D39: SITE23 - Construction K8HH1 | E39: 3375050813 | F39: 66072702017 | G39: 34392264616 | H39: 69578808830 | I39: 103490514988 | J39: 66556977805 | Q39: =SUM(E39:P39) -> 343466319069 | R39: =+Q39+'Summary 2025'!Q39 -> 1086158283362 | S39: =E39/$S$55 -> 129.8446 | T39: =F39/$T$55 -> 2532.4915 | U39: =G39/$U$55 -> 1304.4172 | V39: =H39/$V$55 -> 2639.6604 | W39: =I39/$W$55 -> 3931.2636 | X39: =ROUND(J39/$X$55,2) -> 2530.2 | Y39: =K39/$Y$55 -> 0 | Z39: =ROUND(L39/$Z$55,2) -> 0 | AA39: =ROUND(M39/$AA$55,2) -> 0 | AB39: =ROUND(N39/$AB$55,2) -> 0 | AC39: =ROUND(O39/$AC$55,2) -> 0 | AD39: =ROUND(P39/$AD$55,2) -> 0 | AE39: =SUM(S39:AD39) -> 13067.877
A40: =+LEFT(D40,6) -> SITE27 | B40: Housing | C40: Construction | D40: SITE27 - Mockup house of THT-Phase 2 | G40: 0 | H40: 2697122223 | I40: 0 | Q40: =SUM(E40:P40) -> 2697122223 | R40: =+Q40+'Summary 2025'!Q40 -> 39710919693 | S40: =E40/$S$55 -> 0 | T40: =F40/$T$55 -> 0 | U40: =G40/$U$55 -> 0 | V40: =H40/$V$55 -> 102.32263 | W40: =I40/$W$55 -> 0 | X40: =ROUND(J40/$X$55,2) -> 0 | Y40: =K40/$Y$55 -> 0 | Z40: =ROUND(L40/$Z$55,2) -> 0 | AA40: =ROUND(M40/$AA$55,2) -> 0 | AB40: =ROUND(N40/$AB$55,2) -> 0 | AC40: =ROUND(O40/$AC$55,2) -> 0 | AD40: =ROUND(P40/$AD$55,2) -> 0 | AE40: =SUM(S40:AD40) -> 102.32263
...

Sheet Summary 2025
C1: DAEWOO VINA
C2: SUMMARY SALES + COGS 2025
D3: =+SUBTOTAL(9,D9:D26) -> 13237143700 | E3: =+SUBTOTAL(9,E9:E26) -> 40366653995 | F3: =+SUBTOTAL(9,F9:F26) -> 29904196188 | G3: =+SUBTOTAL(9,G9:G26) -> 78247883913 | H3: =+SUBTOTAL(9,H9:H26) -> 99841667840 | I3: =+SUBTOTAL(9,I9:I26) -> 115393148483 | J3: =+SUBTOTAL(9,J9:J26) -> 65082588410 | K3: =+SUBTOTAL(9,K9:K26) -> 65619552198 | L3: =+SUBTOTAL(9,L9:L27) -> 66816260917 | M3: =+SUBTOTAL(9,M9:M27) -> 49804552226 | N3: =+SUBTOTAL(9,N9:N27) -> 102517004504 | O3: =+SUBTOTAL(9,O9:O27) -> 645735136331 | P3: =+SUBTOTAL(9,P9:P27) -> 1372565788705
D4: =+SUBTOTAL(9,D30:D51) -> 10191759312 | E4: =+SUBTOTAL(9,E30:E51) -> 36414796814 | F4: =+SUBTOTAL(9,F30:F51) -> 25894418238 | G4: =+SUBTOTAL(9,G30:G51) -> 67446139929 | H4: =+SUBTOTAL(9,H30:H51) -> 85638316411 | I4: =+SUBTOTAL(9,I30:I51) -> 96138186949 | J4: =+SUBTOTAL(9,J30:J51) -> 56280575729 | K4: =+SUBTOTAL(9,K30:K51) -> 56293851323 | ... P4: =+SUBTOTAL(9,P30:P51) -> 1.1223832e+12
C5: Month | D5: 2025
D6: VND | Q6: TOTAL up to 2025 | R6: 1000 USD
D7: 45658 | E7: 45689 | F7: 45717 | G7: 45748 | H7: 45778 | I7: 45809 | J7: 45839 | K7: 45870 | L7: 45901 | M7: 45931 | N7: 45962 | O7: 45992 | P7: Total VND | R7: 45658 | S7: 45689 | T7: 45717 | U7: 45748 | V7: 45778 | W7: 45809 | X7: 45839 | Y7: 45870 | Z7: 45901 | AA7: 45931 | AB7: 45962 | AC7: 45992 | AD7: Total 1000 USD
C8: Revenue | D8: =SUM(D9:D28) -> 13237143700 | E8: =SUM(E9:E28) -> 40366653995 | F8: =SUM(F9:F28) -> 29904196188 | G8: =SUM(G9:G28) -> 78247883913 | H8: =SUM(H9:H28) -> 99841667840 | I8: =SUM(I9:I28) -> 115393148483 | J8: =SUM(J9:J28) -> 65082588410 | K8: =SUM(K9:K28) -> 65619552198 | ... AG8: =SUM(AG9:AG28) -> 0 | AH8: =+P8-'[2]IS (01)'!$L$6 -> 0 | AI8: =+AD8-'[2]IS (01)'!$G$6 -> -0.006176885
B9: O&M | C9: SITE05 - Infra Management | D9: 1547890964 | E9: 1517740000 | F9: 1649245000 | G9: 1599512000 | H9: 1593627000 | I9: 1593627000 | J9: 1593627000 | K9: 1610017000 | L9: 1699447000 | M9: 1890079545 | N9: 1593627000 | O9: 1593627000 | P9: =SUM(D9:O9) -> 19482066509 | Q9: =+P9+'Summary 2024'!Q9 -> 118639029417 | R9: =D9/$R$50 -> 61.664049 | S9: =E9/$S$50 -> 59.460921 | T9: =F9/$T$50 -> 64.441253 | U9: =G9/$U$50 -> 61.488948 | V9: =H9/$V$50 -> 61.258005 | W9: =ROUND(I9/$W$50,2) -> 61.09 | X9: =J9/$X$50 -> 60.846359 | Y9: =ROUND(K9/$Y$50,2) -> 60.99 | Z9: =ROUND(L9/$Z$50,2) -> 64.36 | AA9: =ROUND(M9/$AA$50,2) -> 71.85 | AB9: =ROUND(N9/$AB$50,2) -> 60.38 | AC9: =ROUND(O9/$AC$50,2) -> 60.64 | AD9: =SUM(R9:AC9) -> 748.46954 | AE9: =+E9+E17 -> 3926652500
A10: Infra | B10: Construction | C10: SITE06 - Infra Phase II | D10: 3093843795 | E10: 2238531317 | F10: 1893615964 | G10: 1820519462 | H10: 2499781977 | I10: 1723909886 | J10: 12671382160 | K10: 2470378345 | L10: 1863283803 | M10: 6734849528 | N10: 4011403299 | O10: 67784105752 | P10: =SUM(D10:O10) -> 108805605288 | Q10: =+P10+'Summary 2024'!Q10 -> 1.0892039e+12 | R10: =D10/$R$50 -> 123.25089 | S10: =E10/$S$50 -> 87.699562 | T10: =F10/$T$50 -> 73.989605 | U10: =G10/$U$50 -> 69.984987 | V10: =H10/$V$50 -> 96.090024 | W10: =ROUND(I10/$W$50,2) -> 66.09 | X10: =J10/$X$50 -> 483.80673 | Y10: =ROUND(K10/$Y$50,2) -> 93.58 | Z10: =ROUND(L10/$Z$50,2) -> 70.56 | AA10: =ROUND(M10/$AA$50,2) -> 256.01 | AB10: =ROUND(N10/$AB$50,2) -> 151.99 | AC10: =ROUND(O10/$AC$50,2) -> 2579.3 | AD10: =SUM(R10:AC10) -> 4152.3518 | AE10: =+E10+E18+E19+E20 -> 36440001495
B11: Consulting | C11: SITE08 - B3CC1 | P11: =SUM(D11:O11) -> 0 | Q11: =+P11+'Summary 2024'!Q11 -> 104618100000 | R11: =D11/$R$50 -> 0 | S11: =E11/$S$50 -> 0 | T11: =F11/$T$50 -> 0 | U11: =G11/$U$50 -> 0 | V11: =H11/$V$50 -> 0 | W11: =ROUND(I11/$W$50,2) -> 0 | X11: =J11/$X$50 -> 0 | Y11: =ROUND(K11/$Y$50,2) -> 0 | Z11: =ROUND(L11/$Z$50,2) -> 0 | AA11: =ROUND(M11/$AA$50,2) -> 0 | AB11: =ROUND(N11/$AB$50,2) -> 0 | AC11: =ROUND(O11/$AC$50,2) -> 0 | AD11: =SUM(R11:AC11) -> 0
B12: Consulting | C12: SITE14 - B1CC4 | I12: 9548000000 | L12: 4774000000 | P12: =SUM(D12:O12) -> 14322000000 | Q12: =+P12+'Summary 2024'!Q12 -> 33418000000 | R12: =D12/$R$50 -> 0 | S12: =E12/$S$50 -> 0 | T12: =F12/$T$50 -> 0 | U12: =G12/$U$50 -> 0 | V12: =H12/$V$50 -> 0 | W12: =ROUND(I12/$W$50,2) -> 366.03 | X12: =J12/$X$50 -> 0 | Y12: =ROUND(K12/$Y$50,2) -> 0 | Z12: =ROUND(L12/$Z$50,2) -> 180.79 | AA12: =ROUND(M12/$AA$50,2) -> 0 | AB12: =ROUND(N12/$AB$50,2) -> 0 | AC12: =ROUND(O12/$AC$50,2) -> 0 | AD12: =SUM(R12:AC12) -> 546.82
B13: Consulting | C13: SITE16 - Precons K8CT1 | P13: =SUM(D13:O13) -> 0 | Q13: =+P13+'Summary 2024'!Q14 -> 39781808000 | R13: =D13/$R$50 -> 0 | S13: =E13/$S$50 -> 0 | T13: =F13/$T$50 -> 0 | U13: =G13/$U$50 -> 0 | V13: =H13/$V$50 -> 0 | W13: =ROUND(I13/$W$50,2) -> 0 | X13: =J13/$X$50 -> 0 | Y13: =ROUND(K13/$Y$50,2) -> 0 | Z13: =ROUND(L13/$Z$50,2) -> 0 | AA13: =ROUND(M13/$AA$50,2) -> 0 | AB13: =ROUND(N13/$AB$50,2) -> 0 | AC13: =ROUND(O13/$AC$50,2) -> 0 | AD13: =SUM(R13:AC13) -> 0
B14: Consulting | C14: SITE17 - H1HH1 | P14: =SUM(D14:O14) -> 0 | Q14: =+P14+'Summary 2024'!Q15 -> 0 | R14: =D14/$R$50 -> 0 | S14: =E14/$S$50 -> 0 | T14: =F14/$T$50 -> 0 | U14: =G14/$U$50 -> 0 | V14: =H14/$V$50 -> 0 | W14: =ROUND(I14/$W$50,2) -> 0 | X14: =J14/$X$50 -> 0 | Y14: =ROUND(K14/$Y$50,2) -> 0 | Z14: =ROUND(L14/$Z$50,2) -> 0 | AA14: =ROUND(M14/$AA$50,2) -> 0 | AB14: =ROUND(N14/$AB$50,2) -> 0 | AC14: =ROUND(O14/$AC$50,2) -> 0 | AD14: =SUM(R14:AC14) -> 0
A15: Housing | B15: Construction | C15: SITE 18 - Construction K8CT1 | M15: 737199552 | N15: 13015353428 | O15: 124973923913 | P15: =SUM(D15:O15) -> 138726476893 | Q15: =+P15+'Summary 2024'!Q16 -> 138726476893 | R15: =D15/$R$50 -> 0 | S15: =E15/$S$50 -> 0 | T15: =F15/$T$50 -> 0 | U15: =G15/$U$50 -> 0 | V15: =H15/$V$50 -> 0 | W15: =ROUND(I15/$W$50,2) -> 0 | X15: =J15/$X$50 -> 0 | Y15: =ROUND(K15/$Y$50,2) -> 0 | Z15: =ROUND(L15/$Z$50,2) -> 0 | AA15: =ROUND(M15/$AA$50,2) -> 28.02 | AB15: =ROUND(N15/$AB$50,2) -> 493.14 | AC15: =ROUND(O15/$AC$50,2) -> 4755.48 | AD15: =SUM(R15:AC15) -> 5276.64
B16: Consulting | C16: SITE 20 - Precons K2CT1 | P16: =SUM(D16:O16) -> 0 | Q16: =+P16+'Summary 2024'!Q17 -> 23822780000 | R16: =D16/$R$50 -> 0 | S16: =E16/$S$50 -> 0 | T16: =F16/$T$50 -> 0 | U16: =G16/$U$50 -> 0 | V16: =H16/$V$50 -> 0 | W16: =ROUND(I16/$W$50,2) -> 0 | X16: =J16/$X$50 -> 0 | Y16: =ROUND(K16/$Y$50,2) -> 0 | Z16: =ROUND(L16/$Z$50,2) -> 0 | AA16: =ROUND(M16/$AA$50,2) -> 0 | AB16: =ROUND(N16/$AB$50,2) -> 0 | AC16: =ROUND(O16/$AC$50,2) -> 0 | AD16: =SUM(R16:AC16) -> 0
B17: O&M | C17: SITE 22 - Villa H&K Management | D17: 2408912500 | E17: 2408912500 | F17: 2408912500 | G17: 2408912500 | H17: 2408912500 | I17: 2408912500 | J17: 2408912500 | K17: 2408912500 | L17: 2408912500 | M17: 2408912500 | N17: 2408912500 | O17: 2408912500 | P17: =SUM(D17:O17) -> 28906950000 | Q17: =+P17+'Summary 2024'!Q18 -> 71425425000 | R17: =D17/$R$50 -> 95.964963 | S17: =E17/$S$50 -> 94.374633 | T17: =F17/$T$50 -> 94.123882 | U17: =G17/$U$50 -> 92.604179 | V17: =H17/$V$50 -> 92.597059 | W17: =ROUND(I17/$W$50,2) -> 92.35 | X17: =J17/$X$50 -> 91.97482 | Y17: =ROUND(K17/$Y$50,2) -> 91.25 | Z17: =ROUND(L17/$Z$50,2) -> 91.22 | AA17: =ROUND(M17/$AA$50,2) -> 91.57 | AB17: =ROUND(N17/$AB$50,2) -> 91.27 | AC17: =ROUND(O17/$AC$50,2) -> 91.66 | AD17: =SUM(R17:AC17) -> 1110.9595
