Workbook
Name _1: #REF!
Name _1: #REF!
Name _1: #REF!
Name _1: #REF!
Name _10_0R: #REF!
Name _10_0R: #REF!
Name _10_0R: #REF!
Name _10_0R: #REF!
Name _11_10: #REF!
Name _11_10: #REF!
Name _11_10: #REF!
Name _11_10: #REF!
Name _12_11: #REF!
Name _12_11: #REF!
Name _12_11: #REF!
Name _12_11: #REF!
Name _13_6: #REF!
Name _13_6: #REF!
Name _13_6: #REF!
Name _13_6: #REF!
Name _14_7: #REF!
Name _14_7: #REF!
Name _14_7: #REF!
Name _14_7: #REF!
Name _15_8: #REF!
Name _15_8: #REF!
Name _15_8: #REF!
Name _15_8: #REF!
Name _18_8_0R: #REF!
Name _18_8_0R: #REF!
Name _18_8_0R: #REF!
Name _18_8_0R: #REF!
Name _19_9: #REF!
Name _19_9: #REF!
Name _19_9: #REF!
Name _19_9: #REF!
Name _1C_: #REF!
Name _1C_: #REF!
Name _1C_: #REF!
Name _1C_: #REF!
Name _2: #N/A
Name _22B_0R: #REF!
Name _22B_0R: #REF!
Name _22B_0R: #REF!
Name _22B_0R: #REF!
Name _23C_: #REF!
Name _23C_: #REF!
Name _23C_: #REF!
Name _23C_: #REF!
Name _26D_0R: #REF!
Name _26D_0R: #REF!
Name _26D_0R: #REF!
Name _26D_0R: #REF!
Name _3: #N/A
Name _4: #N/A
Name _4_0R: #REF!
Name _4_0R: #REF!
Name _4_0R: #REF!
Name _4_0R: #REF!
Name _44L_0R: #REF!

Sheet EPA_자동계산
A1: ▶ DECV법인 자금수지 총괄(EPA입력)
A3: [단위:천USD]
A4: 구분 | B4: 약정항목명 | C4: 44927 | D4: 44958 | E4: 44986 | F4: 45017 | G4: 45047 | H4: 45078 | I4: 45108 | J4: 45139 | K4: 45170 | L4: 45200 | M4: 45231 | N4: 45261 | O4: 45292 | P4: 45323 | Q4: 45352 | R4: 45383 | S4: 45413 | T4: 45444 | U4: 45474 | V4: 45505 | W4: 45536 | X4: 45566 | Y4: 45597 | Z4: 45627 | AA4: 45658 | AB4: 45689 | AC4: 45717 | AD4: 45748 | AE4: 45778 | AF4: 45809 | AG4: 45839 | AH4: 45870 | AI4: 45901 | AJ4: 45931 | AK4: 45962 | AL4: 45992 | AM4: 46023 | AN4: 46054 | AO4: 46082 | AP4: 46113 | AQ4: 46143 | AR4: 46174 | AS4: 46204 | AT4: 46235 | AU4: 46266 | AV4: 46296 | AW4: 46327 | AX4: 46357 | AY4: 46388 | AZ4: 46419 | BA4: 46447 | BB4: 46478 | BC4: 46508 | BD4: 46539 | BE4: 46569 | BF4: 46600 | BG4: 46631 | BH4: 46661 | BI4: 46692 | BJ4: 46722 | BK4: 46753 | BL4: 46784 | BM4: 46813 | BN4: 46844 | BO4: 46874 | BP4: 46905 | BQ4: 46935 | BR4: 46966 | BS4: 46997 | BT4: 47027 | BU4: 47058 | BV4: 47088 | BW4: 47119 | BX4: 47150 | BY4: 47178 | BZ4: 47209 | CA4: 47239 | CB4: 47270 | CC4: 47300 | CD4: 47331 | CE4: 47362 | CF4: 47392 | CG4: 47423 | CH4: 47453
A5: 수입 | B5: 영업수익 | C5: =+'자금수지(FS)_작성시트'!G4 -> 2410.7997 | D5: =+'자금수지(FS)_작성시트'!H4 -> 2585.0402 | E5: =+'자금수지(FS)_작성시트'!I4 -> 1643.8651 | F5: =+'자금수지(FS)_작성시트'!J4 -> 1095.5899 | G5: =+'자금수지(FS)_작성시트'!K4 -> 938.78216 | H5: =+'자금수지(FS)_작성시트'!L4 -> 2572.7345 | I5: =+'자금수지(FS)_작성시트'!M4 -> 1109.6346 | J5: =+'자금수지(FS)_작성시트'!N4 -> 640.46318 | ... N5: =+'자금수지(FS)_작성시트'!R4 -> 2951.7028 | O5: =+'자금수지(FS)_작성시트'!T4 -> 2477.254 | P5: =+'자금수지(FS)_작성시트'!U4 -> 1158.4478 | Q5: =+'자금수지(FS)_작성시트'!V4 -> 607.71865 | R5: =+'자금수지(FS)_작성시트'!W4 -> 727.13063 | S5: =+'자금수지(FS)_작성시트'!X4 -> 647.41928 | T5: =+'자금수지(FS)_작성시트'!Y4 -> 849.2885 | U5: =+'자금수지(FS)_작성시트'!Z4 -> 1210.0058 | V5: =+'자금수지(FS)_작성시트'!AA4 -> 1798.5852 | ... Z5: =+'자금수지(FS)_작성시트'!AE4 -> 32193.421 | AA5: =+'자금수지(FS)_작성시트'!AG4 -> 5306.9558 | AB5: =+'자금수지(FS)_작성시트'!AH4 -> 1009.4704 | AC5: =+'자금수지(FS)_작성시트'!AI4 -> 1334.4752 | AD5: =+'자금수지(FS)_작성시트'!AJ4 -> 2825.325 | AE5: =+'자금수지(FS)_작성시트'!AK4 -> 4332.9034 | AF5: =+'자금수지(FS)_작성시트'!AL4 -> 3324.7459 | AG5: =+'자금수지(FS)_작성시트'!AM4 -> 3227.9172 | AH5: =+'자금수지(FS)_작성시트'!AN4 -> 4322.3224 | ... AL5: =+'자금수지(FS)_작성시트'!AR4 -> 13048.983 | AM5: =+'자금수지(FS)_작성시트'!AT4 -> 13475.46 | AN5: =+'자금수지(FS)_작성시트'!AU4 -> 8369.8133 | AO5: =+'자금수지(FS)_작성시트'!AV4 -> 4229.9638 | AP5: =+'자금수지(FS)_작성시트'!AW4 -> 4720.3816 | AQ5: =+'자금수지(FS)_작성시트'!AX4 -> 65.990113 | AR5: =+'자금수지(FS)_작성시트'!AY4 -> 1989.083 | AS5: =+'자금수지(FS)_작성시트'!AZ4 -> 139.4 | AT5: =+'자금수지(FS)_작성시트'!BA4 -> 6836.1225 | ... AX5: =+'자금수지(FS)_작성시트'!BE4 -> 16348.346 | AY5: =+'자금수지(FS)_작성시트'!BG4 -> 18238.9 | AZ5: =+'자금수지(FS)_작성시트'!BH4 -> 14945.131 | BA5: =+'자금수지(FS)_작성시트'!BI4 -> 17865.559 | BB5: =+'자금수지(FS)_작성시트'!BJ4 -> 34173.96 | BC5: =+'자금수지(FS)_작성시트'!BK4 -> 24465.908 | BD5: =+'자금수지(FS)_작성시트'!BL4 -> 26813.17 | BE5: =+'자금수지(FS)_작성시트'!BM4 -> 104855.1 | BF5: =+'자금수지(FS)_작성시트'!BN4 -> 26265.412 | ... BJ5: =+'자금수지(FS)_작성시트'!BR4 -> 31159.826 | BK5: =+'자금수지(FS)_작성시트'!BT4 -> 31631.133 | BL5: =+'자금수지(FS)_작성시트'!BU4 -> 30145.143 | BM5: =+'자금수지(FS)_작성시트'!BV4 -> 26573.409 | BN5: =+'자금수지(FS)_작성시트'!BW4 -> 27055.125 | BO5: =+'자금수지(FS)_작성시트'!BX4 -> 26237.679 | BP5: =+'자금수지(FS)_작성시트'!BY4 -> 26688.215 | BQ5: =+'자금수지(FS)_작성시트'!BZ4 -> 27897.091 | BR5: =+'자금수지(FS)_작성시트'!CA4 -> 27883.311 | ... BV5: =+'자금수지(FS)_작성시트'!CE4 -> 28474.719 | BW5: =+'자금수지(FS)_작성시트'!CG4 -> 26643.526 | BX5: =+'자금수지(FS)_작성시트'!CH4 -> 27507.478 | BY5: =+'자금수지(FS)_작성시트'!CI4 -> 28555.777 | BZ5: =+'자금수지(FS)_작성시트'!CJ4 -> 27406.83 | CA5: =+'자금수지(FS)_작성시트'!CK4 -> 28143.11 | CB5: =+'자금수지(FS)_작성시트'!CL4 -> 28716.185 | CC5: =+'자금수지(FS)_작성시트'!CM4 -> 27043.597 | CD5: =+'자금수지(FS)_작성시트'!CN4 -> 24464.789 | ... CH5: =+'자금수지(FS)_작성시트'!CR4 -> 15832.975
B6: 대여금 | C6: =+'자금수지(FS)_작성시트'!G222 -> 0 | D6: =+'자금수지(FS)_작성시트'!H222 -> 0 | E6: =+'자금수지(FS)_작성시트'!I222 -> 0 | F6: =+'자금수지(FS)_작성시트'!J222 -> 0 | G6: =+'자금수지(FS)_작성시트'!K222 -> 0 | H6: =+'자금수지(FS)_작성시트'!L222 -> 0 | I6: =+'자금수지(FS)_작성시트'!M222 -> 0 | J6: =+'자금수지(FS)_작성시트'!N222 -> 0 | ... N6: =+'자금수지(FS)_작성시트'!R222 -> 0 | O6: =+'자금수지(FS)_작성시트'!T222 -> 0 | P6: =+'자금수지(FS)_작성시트'!U222 -> 0 | Q6: =+'자금수지(FS)_작성시트'!V222 -> 0 | R6: =+'자금수지(FS)_작성시트'!W222 -> 0 | S6: =+'자금수지(FS)_작성시트'!X222 -> 0 | T6: =+'자금수지(FS)_작성시트'!Y222 -> 0 | U6: =+'자금수지(FS)_작성시트'!Z222 -> 0 | V6: =+'자금수지(FS)_작성시트'!AA222 -> 0 | ... Z6: =+'자금수지(FS)_작성시트'!AE222 -> 0 | AA6: =+'자금수지(FS)_작성시트'!AG222 -> 0 | AB6: =+'자금수지(FS)_작성시트'!AH222 -> 0 | AC6: =+'자금수지(FS)_작성시트'!AI222 -> 0 | AD6: =+'자금수지(FS)_작성시트'!AJ222 -> 0 | AE6: =+'자금수지(FS)_작성시트'!AK222 -> 0 | AF6: =+'자금수지(FS)_작성시트'!AL222 -> 0 | AG6: =+'자금수지(FS)_작성시트'!AM222 -> 0 | AH6: =+'자금수지(FS)_작성시트'!AN222 -> 0 | ... AL6: =+'자금수지(FS)_작성시트'!AR222 -> 0 | AM6: =+'자금수지(FS)_작성시트'!AT222 -> 0 | AN6: =+'자금수지(FS)_작성시트'!AU222 -> 0 | AO6: =+'자금수지(FS)_작성시트'!AV222 -> 0 | AP6: =+'자금수지(FS)_작성시트'!AW222 -> 0 | AQ6: =+'자금수지(FS)_작성시트'!AX222 -> 0 | AR6: =+'자금수지(FS)_작성시트'!AY222 -> 0 | AS6: =+'자금수지(FS)_작성시트'!AZ222 -> 0 | AT6: =+'자금수지(FS)_작성시트'!BA222 -> 0 | ... AX6: =+'자금수지(FS)_작성시트'!BE222 -> 0 | AY6: =+'자금수지(FS)_작성시트'!BG222 -> 0 | AZ6: =+'자금수지(FS)_작성시트'!BH222 -> 0 | BA6: =+'자금수지(FS)_작성시트'!BI222 -> 0 | BB6: =+'자금수지(FS)_작성시트'!BJ222 -> 0 | BC6: =+'자금수지(FS)_작성시트'!BK222 -> 0 | BD6: =+'자금수지(FS)_작성시트'!BL222 -> 0 | BE6: =+'자금수지(FS)_작성시트'!BM222 -> 0 | BF6: =+'자금수지(FS)_작성시트'!BN222 -> 0 | ... BJ6: =+'자금수지(FS)_작성시트'!BR222 -> 0 | BK6: =+'자금수지(FS)_작성시트'!BT222 -> 0 | BL6: =+'자금수지(FS)_작성시트'!BU222 -> 0 | BM6: =+'자금수지(FS)_작성시트'!BV222 -> 0 | BN6: =+'자금수지(FS)_작성시트'!BW222 -> 0 | BO6: =+'자금수지(FS)_작성시트'!BX222 -> 0 | BP6: =+'자금수지(FS)_작성시트'!BY222 -> 0 | BQ6: 27958 | BR6: =+'자금수지(FS)_작성시트'!CA222 -> 0 | BS6: =+'자금수지(FS)_작성시트'!CB222 -> 0 | BT6: =+'자금수지(FS)_작성시트'!CC222 -> 0 | BU6: =+'자금수지(FS)_작성시트'!CD222 -> 0 | BV6: =+'자금수지(FS)_작성시트'!CE222 -> 0 | BW6: =+'자금수지(FS)_작성시트'!CG222 -> 0 | BX6: =+'자금수지(FS)_작성시트'!CH222 -> 0 | BY6: =+'자금수지(FS)_작성시트'!CI222 -> 0 | BZ6: =+'자금수지(FS)_작성시트'!CJ222 -> 0 | CA6: =+'자금수지(FS)_작성시트'!CK222 -> 0 | CB6: =+'자금수지(FS)_작성시트'!CL222 -> 0 | CC6: =+'자금수지(FS)_작성시트'!CM222 -> 0 | CD6: =+'자금수지(FS)_작성시트'!CN222 -> 0 | ... CH6: =+'자금수지(FS)_작성시트'!CR222 -> 0
B7: 보증금회수 | C7: =+'자금수지(FS)_작성시트'!G225 -> 0 | D7: =+'자금수지(FS)_작성시트'!H225 -> 0 | E7: =+'자금수지(FS)_작성시트'!I225 -> 0 | F7: =+'자금수지(FS)_작성시트'!J225 -> 0 | G7: =+'자금수지(FS)_작성시트'!K225 -> 0 | H7: =+'자금수지(FS)_작성시트'!L225 -> 0 | I7: =+'자금수지(FS)_작성시트'!M225 -> 0 | J7: =+'자금수지(FS)_작성시트'!N225 -> 0 | ... N7: =+'자금수지(FS)_작성시트'!R225 -> 0 | O7: =+'자금수지(FS)_작성시트'!T225 -> 6.6639158 | P7: =+'자금수지(FS)_작성시트'!U225 -> 2.2228128 | Q7: =+'자금수지(FS)_작성시트'!V225 -> 2.5554342 | R7: =+'자금수지(FS)_작성시트'!W225 -> 4.771941 | S7: =+'자금수지(FS)_작성시트'!X225 -> 2.179599 | T7: =+'자금수지(FS)_작성시트'!Y225 -> 0 | U7: =+'자금수지(FS)_작성시트'!Z225 -> 0 | V7: =+'자금수지(FS)_작성시트'!AA225 -> 2.0075605 | ... Z7: =+'자금수지(FS)_작성시트'!AE225 -> 0.65627821 | AA7: =+'자금수지(FS)_작성시트'!AG225 -> 1.2634133 | AB7: =+'자금수지(FS)_작성시트'!AH225 -> 0 | AC7: =+'자금수지(FS)_작성시트'!AI225 -> 3.0346188 | AD7: =+'자금수지(FS)_작성시트'!AJ225 -> 2.9494099 | AE7: =+'자금수지(FS)_작성시트'!AK225 -> 0 | AF7: =+'자금수지(FS)_작성시트'!AL225 -> 3.5652674 | AG7: =+'자금수지(FS)_작성시트'!AM225 -> 0 | AH7: =+'자금수지(FS)_작성시트'!AN225 -> 0.71101178 | ... AL7: =+'자금수지(FS)_작성시트'!AR225 -> 1.7969178 | AM7: =+'자금수지(FS)_작성시트'!AT225 -> 0 | AN7: =+'자금수지(FS)_작성시트'!AU225 -> 3.2090839 | AO7: =+'자금수지(FS)_작성시트'!AV225 -> 1.7441402 | AP7: =+'자금수지(FS)_작성시트'!AW225 -> 0.22762624 | AQ7: =+'자금수지(FS)_작성시트'!AX225 -> 0 | AR7: =+'자금수지(FS)_작성시트'!AY225 -> 0 | AS7: =+'자금수지(FS)_작성시트'!AZ225 -> 0 | AT7: =+'자금수지(FS)_작성시트'!BA225 -> 0 | ... AX7: =+'자금수지(FS)_작성시트'!BE225 -> 0 | AY7: =+'자금수지(FS)_작성시트'!BG225 -> 0 | AZ7: =+'자금수지(FS)_작성시트'!BH225 -> 0 | BA7: =+'자금수지(FS)_작성시트'!BI225 -> 0 | BB7: =+'자금수지(FS)_작성시트'!BJ225 -> 0 | BC7: =+'자금수지(FS)_작성시트'!BK225 -> 0 | BD7: =+'자금수지(FS)_작성시트'!BL225 -> 0 | BE7: =+'자금수지(FS)_작성시트'!BM225 -> 0 | BF7: =+'자금수지(FS)_작성시트'!BN225 -> 0 | ... BJ7: =+'자금수지(FS)_작성시트'!BR225 -> 0 | BK7: =+'자금수지(FS)_작성시트'!BT225 -> 0 | BL7: =+'자금수지(FS)_작성시트'!BU225 -> 0 | BM7: =+'자금수지(FS)_작성시트'!BV225 -> 0 | BN7: =+'자금수지(FS)_작성시트'!BW225 -> 0 | BO7: =+'자금수지(FS)_작성시트'!BX225 -> 0 | BP7: =+'자금수지(FS)_작성시트'!BY225 -> 0 | BQ7: =+'자금수지(FS)_작성시트'!BZ225 -> 0 | BR7: =+'자금수지(FS)_작성시트'!CA225 -> 0 | ... BV7: =+'자금수지(FS)_작성시트'!CE225 -> 0 | BW7: =+'자금수지(FS)_작성시트'!CG225 -> 0 | BX7: =+'자금수지(FS)_작성시트'!CH225 -> 0 | BY7: =+'자금수지(FS)_작성시트'!CI225 -> 0 | BZ7: =+'자금수지(FS)_작성시트'!CJ225 -> 0 | CA7: =+'자금수지(FS)_작성시트'!CK225 -> 0 | CB7: =+'자금수지(FS)_작성시트'!CL225 -> 0 | CC7: =+'자금수지(FS)_작성시트'!CM225 -> 0 | CD7: =+'자금수지(FS)_작성시트'!CN225 -> 0 | ... CH7: =+'자금수지(FS)_작성시트'!CR225 -> 0
B8: 은행차입조달 | C8: =+'자금수지(FS)_작성시트'!G228 -> 0 | D8: =+'자금수지(FS)_작성시트'!H228 -> 0 | E8: =+'자금수지(FS)_작성시트'!I228 -> 0 | F8: =+'자금수지(FS)_작성시트'!J228 -> 0 | G8: =+'자금수지(FS)_작성시트'!K228 -> 0 | H8: =+'자금수지(FS)_작성시트'!L228 -> 0 | I8: =+'자금수지(FS)_작성시트'!M228 -> 0 | J8: =+'자금수지(FS)_작성시트'!N228 -> 0 | ... N8: =+'자금수지(FS)_작성시트'!R228 -> 0 | O8: =+'자금수지(FS)_작성시트'!T228 -> 0 | P8: =+'자금수지(FS)_작성시트'!U228 -> 0 | Q8: =+'자금수지(FS)_작성시트'!V228 -> 0 | R8: =+'자금수지(FS)_작성시트'!W228 -> 0 | S8: =+'자금수지(FS)_작성시트'!X228 -> 0 | T8: =+'자금수지(FS)_작성시트'!Y228 -> 0 | U8: =+'자금수지(FS)_작성시트'!Z228 -> 0 | V8: =+'자금수지(FS)_작성시트'!AA228 -> 0 | ... Z8: =+'자금수지(FS)_작성시트'!AE228 -> 0 | AA8: =+'자금수지(FS)_작성시트'!AG228 -> 0 | AB8: =+'자금수지(FS)_작성시트'!AH228 -> 0 | AC8: =+'자금수지(FS)_작성시트'!AI228 -> 0 | AD8: =+'자금수지(FS)_작성시트'!AJ228 -> 0 | AE8: =+'자금수지(FS)_작성시트'!AK228 -> 0 | AF8: =+'자금수지(FS)_작성시트'!AL228 -> 0 | AG8: =+'자금수지(FS)_작성시트'!AM228 -> 0 | AH8: =+'자금수지(FS)_작성시트'!AN228 -> 0 | ... AL8: =+'자금수지(FS)_작성시트'!AR228 -> 0 | AM8: =+'자금수지(FS)_작성시트'!AT228 -> 0 | AN8: =+'자금수지(FS)_작성시트'!AU228 -> 0 | AO8: =+'자금수지(FS)_작성시트'!AV228 -> 0 | AP8: =+'자금수지(FS)_작성시트'!AW228 -> 0 | AQ8: =+'자금수지(FS)_작성시트'!AX228 -> 0 | AR8: =+'자금수지(FS)_작성시트'!AY228 -> 0 | AS8: =+'자금수지(FS)_작성시트'!AZ228 -> 0 | AT8: =+'자금수지(FS)_작성시트'!BA228 -> 0 | ... AX8: =+'자금수지(FS)_작성시트'!BE228 -> 0 | AY8: =+'자금수지(FS)_작성시트'!BG228 -> 0 | AZ8: =+'자금수지(FS)_작성시트'!BH228 -> 0 | BA8: =+'자금수지(FS)_작성시트'!BI228 -> 0 | BB8: =+'자금수지(FS)_작성시트'!BJ228 -> 0 | BC8: =+'자금수지(FS)_작성시트'!BK228 -> 0 | BD8: =+'자금수지(FS)_작성시트'!BL228 -> 0 | BE8: =+'자금수지(FS)_작성시트'!BM228 -> 0 | BF8: =+'자금수지(FS)_작성시트'!BN228 -> 0 | ... BJ8: =+'자금수지(FS)_작성시트'!BR228 -> 0 | BK8: =+'자금수지(FS)_작성시트'!BT228 -> 0 | BL8: =+'자금수지(FS)_작성시트'!BU228 -> 0 | BM8: =+'자금수지(FS)_작성시트'!BV228 -> 0 | BN8: =+'자금수지(FS)_작성시트'!BW228 -> 0 | BO8: =+'자금수지(FS)_작성시트'!BX228 -> 0 | BP8: =+'자금수지(FS)_작성시트'!BY228 -> 0 | BQ8: =+'자금수지(FS)_작성시트'!BZ228 -> 0 | BR8: =+'자금수지(FS)_작성시트'!CA228 -> 0 | ... BV8: =+'자금수지(FS)_작성시트'!CE228 -> 0 | BW8: =+'자금수지(FS)_작성시트'!CG228 -> 0 | BX8: =+'자금수지(FS)_작성시트'!CH228 -> 0 | BY8: =+'자금수지(FS)_작성시트'!CI228 -> 0 | BZ8: =+'자금수지(FS)_작성시트'!CJ228 -> 0 | CA8: =+'자금수지(FS)_작성시트'!CK228 -> 0 | CB8: =+'자금수지(FS)_작성시트'!CL228 -> 0 | CC8: =+'자금수지(FS)_작성시트'!CM228 -> 0 | CD8: =+'자금수지(FS)_작성시트'!CN228 -> 0 | ... CH8: =+'자금수지(FS)_작성시트'!CR228 -> 0
B9: 기타수입 | C9: =+'자금수지(FS)_작성시트'!G231+'자금수지(FS)_작성시트'!G234+'자금수지(FS)_작성시트'!G237+'자금수지(FS)_작성시트'!G240 -> 267 | D9: =+'자금수지(FS)_작성시트'!H231+'자금수지(FS)_작성시트'!H234+'자금수지(FS)_작성시트'!H237+'자금수지(FS)_작성시트'!H240 -> 30 | E9: =+'자금수지(FS)_작성시트'!I231+'자금수지(FS)_작성시트'!I234+'자금수지(FS)_작성시트'!I237+'자금수지(FS)_작성시트'!I240 -> 31.690436 | F9: =+'자금수지(FS)_작성시트'!J231+'자금수지(FS)_작성시트'!J234+'자금수지(FS)_작성시트'!J237+'자금수지(FS)_작성시트'!J240 -> 30.818566 | G9: =+'자금수지(FS)_작성시트'!K231+'자금수지(FS)_작성시트'!K234+'자금수지(FS)_작성시트'!K237+'자금수지(FS)_작성시트'!K240 -> 27.487748 | H9: =+'자금수지(FS)_작성시트'!L231+'자금수지(FS)_작성시트'!L234+'자금수지(FS)_작성시트'!L237+'자금수지(FS)_작성시트'!L240 -> 23.602977 | I9: =+'자금수지(FS)_작성시트'!M231+'자금수지(FS)_작성시트'!M234+'자금수지(FS)_작성시트'!M237+'자금수지(FS)_작성시트'!M240 -> 725.21885 | J9: =+'자금수지(FS)_작성시트'!N231+'자금수지(FS)_작성시트'!N234+'자금수지(FS)_작성시트'!N237+'자금수지(FS)_작성시트'!N240 -> 31.233271 | ... N9: =+'자금수지(FS)_작성시트'!R231+'자금수지(FS)_작성시트'!R234+'자금수지(FS)_작성시트'!R237+'자금수지(FS)_작성시트'!R240 -> 75.6487 | O9: =+'자금수지(FS)_작성시트'!T231+'자금수지(FS)_작성시트'!T234+'자금수지(FS)_작성시트'!T237+'자금수지(FS)_작성시트'!T240+'자금수지(FS)_작성시트'!T243 -> 190.97099 | P9: =+'자금수지(FS)_작성시트'!U231+'자금수지(FS)_작성시트'!U234+'자금수지(FS)_작성시트'!U237+'자금수지(FS)_작성시트'!U240+'자금수지(FS)_작성시트'!U243 -> 90.248601 | Q9: =+'자금수지(FS)_작성시트'!V231+'자금수지(FS)_작성시트'!V234+'자금수지(FS)_작성시트'!V237+'자금수지(FS)_작성시트'!V240+'자금수지(FS)_작성시트'!V243 -> 20.484453 | R9: =+'자금수지(FS)_작성시트'!W231+'자금수지(FS)_작성시트'!W234+'자금수지(FS)_작성시트'!W237+'자금수지(FS)_작성시트'!W240+'자금수지(FS)_작성시트'!W243 -> 19.163516 | S9: =+'자금수지(FS)_작성시트'!X231+'자금수지(FS)_작성시트'!X234+'자금수지(FS)_작성시트'!X237+'자금수지(FS)_작성시트'!X240+'자금수지(FS)_작성시트'!X243 -> 329.98395 | T9: =+'자금수지(FS)_작성시트'!Y231+'자금수지(FS)_작성시트'!Y234+'자금수지(FS)_작성시트'!Y237+'자금수지(FS)_작성시트'!Y240+'자금수지(FS)_작성시트'!Y243 -> 21.484912 | U9: =+'자금수지(FS)_작성시트'!Z231+'자금수지(FS)_작성시트'!Z234+'자금수지(FS)_작성시트'!Z237+'자금수지(FS)_작성시트'!Z240+'자금수지(FS)_작성시트'!Z243 -> 80973.547 | V9: =+'자금수지(FS)_작성시트'!AA231+'자금수지(FS)_작성시트'!AA234+'자금수지(FS)_작성시트'!AA237+'자금수지(FS)_작성시트'!AA240+'자금수지(FS)_작성시트'!AA243 -> 1222.2614 | ... Z9: =+'자금수지(FS)_작성시트'!AE231+'자금수지(FS)_작성시트'!AE234+'자금수지(FS)_작성시트'!AE237+'자금수지(FS)_작성시트'!AE240+'자금수지(FS)_작성시트'!AE243 -> 94.161119 | AA9: =+'자금수지(FS)_작성시트'!AG231+'자금수지(FS)_작성시트'!AG234+'자금수지(FS)_작성시트'!AG237+'자금수지(FS)_작성시트'!AG240+'자금수지(FS)_작성시트'!AG243 -> 2329.1354 | AB9: =+'자금수지(FS)_작성시트'!AH231+'자금수지(FS)_작성시트'!AH234+'자금수지(FS)_작성시트'!AH237+'자금수지(FS)_작성시트'!AH240+'자금수지(FS)_작성시트'!AH243 -> 112.49559 | AC9: =+'자금수지(FS)_작성시트'!AI231+'자금수지(FS)_작성시트'!AI234+'자금수지(FS)_작성시트'!AI237+'자금수지(FS)_작성시트'!AI240+'자금수지(FS)_작성시트'!AI243 -> 167.16808 | AD9: =+'자금수지(FS)_작성시트'!AJ231+'자금수지(FS)_작성시트'!AJ234+'자금수지(FS)_작성시트'!AJ237+'자금수지(FS)_작성시트'!AJ240+'자금수지(FS)_작성시트'!AJ243 -> 112.25163 | AE9: =+'자금수지(FS)_작성시트'!AK231+'자금수지(FS)_작성시트'!AK234+'자금수지(FS)_작성시트'!AK237+'자금수지(FS)_작성시트'!AK240+'자금수지(FS)_작성시트'!AK243 -> 2612.5067 | AF9: =+'자금수지(FS)_작성시트'!AL231+'자금수지(FS)_작성시트'!AL234+'자금수지(FS)_작성시트'!AL237+'자금수지(FS)_작성시트'!AL240+'자금수지(FS)_작성시트'!AL243 -> 956.27385 | AG9: =+'자금수지(FS)_작성시트'!AM231+'자금수지(FS)_작성시트'!AM234+'자금수지(FS)_작성시트'!AM237+'자금수지(FS)_작성시트'!AM240+'자금수지(FS)_작성시트'!AM243 -> 704.82279 | AH9: =+'자금수지(FS)_작성시트'!AN231+'자금수지(FS)_작성시트'!AN234+'자금수지(FS)_작성시트'!AN237+'자금수지(FS)_작성시트'!AN240+'자금수지(FS)_작성시트'!AN243 -> 1519.5044 | ... AL9: =+'자금수지(FS)_작성시트'!AR231+'자금수지(FS)_작성시트'!AR234+'자금수지(FS)_작성시트'!AR237+'자금수지(FS)_작성시트'!AR240+'자금수지(FS)_작성시트'!AR243 -> 4420.0204 | AM9: =+'자금수지(FS)_작성시트'!AT231+'자금수지(FS)_작성시트'!AT234+'자금수지(FS)_작성시트'!AT237+'자금수지(FS)_작성시트'!AT240+'자금수지(FS)_작성시트'!AT243 -> 1019.9236 | AN9: =+'자금수지(FS)_작성시트'!AU231+'자금수지(FS)_작성시트'!AU234+'자금수지(FS)_작성시트'!AU237+'자금수지(FS)_작성시트'!AU240+'자금수지(FS)_작성시트'!AU243 -> 270.22288 | AO9: =+'자금수지(FS)_작성시트'!AV231+'자금수지(FS)_작성시트'!AV234+'자금수지(FS)_작성시트'!AV237+'자금수지(FS)_작성시트'!AV240+'자금수지(FS)_작성시트'!AV243 -> 520.04505 | AP9: =+'자금수지(FS)_작성시트'!AW231+'자금수지(FS)_작성시트'!AW234+'자금수지(FS)_작성시트'!AW237+'자금수지(FS)_작성시트'!AW240+'자금수지(FS)_작성시트'!AW243 -> 301.5565 | AQ9: =+'자금수지(FS)_작성시트'!AX231+'자금수지(FS)_작성시트'!AX234+'자금수지(FS)_작성시트'!AX237+'자금수지(FS)_작성시트'!AX240+'자금수지(FS)_작성시트'!AX243 -> 285.33104 | AR9: =+'자금수지(FS)_작성시트'!AY231+'자금수지(FS)_작성시트'!AY234+'자금수지(FS)_작성시트'!AY237+'자금수지(FS)_작성시트'!AY240+'자금수지(FS)_작성시트'!AY243 -> 516.78927 | AS9: =+'자금수지(FS)_작성시트'!AZ231+'자금수지(FS)_작성시트'!AZ234+'자금수지(FS)_작성시트'!AZ237+'자금수지(FS)_작성시트'!AZ240+'자금수지(FS)_작성시트'!AZ243 -> 222.90329 | AT9: =+'자금수지(FS)_작성시트'!BA231+'자금수지(FS)_작성시트'!BA234+'자금수지(FS)_작성시트'!BA237+'자금수지(FS)_작성시트'!BA240+'자금수지(FS)_작성시트'!BA243 -> 125.00049 | ... AX9: =+'자금수지(FS)_작성시트'!BE231+'자금수지(FS)_작성시트'!BE234+'자금수지(FS)_작성시트'!BE237+'자금수지(FS)_작성시트'!BE240+'자금수지(FS)_작성시트'!BE243 -> 80.760157 | AY9: =+'자금수지(FS)_작성시트'!BG231+'자금수지(FS)_작성시트'!BG234+'자금수지(FS)_작성시트'!BG237+'자금수지(FS)_작성시트'!BG240+'자금수지(FS)_작성시트'!BG243 -> 78.602054 | AZ9: =+'자금수지(FS)_작성시트'!BH231+'자금수지(FS)_작성시트'!BH234+'자금수지(FS)_작성시트'!BH237+'자금수지(FS)_작성시트'!BH240+'자금수지(FS)_작성시트'!BH243 -> 85.312998 | BA9: =+'자금수지(FS)_작성시트'!BI231+'자금수지(FS)_작성시트'!BI234+'자금수지(FS)_작성시트'!BI237+'자금수지(FS)_작성시트'!BI240+'자금수지(FS)_작성시트'!BI243 -> 60.300951 | BB9: =+'자금수지(FS)_작성시트'!BJ231+'자금수지(FS)_작성시트'!BJ234+'자금수지(FS)_작성시트'!BJ237+'자금수지(FS)_작성시트'!BJ240+'자금수지(FS)_작성시트'!BJ243 -> 46.440336 | BC9: =+'자금수지(FS)_작성시트'!BK231+'자금수지(FS)_작성시트'!BK234+'자금수지(FS)_작성시트'!BK237+'자금수지(FS)_작성시트'!BK240+'자금수지(FS)_작성시트'!BK243 -> 65.658879 | BD9: =+'자금수지(FS)_작성시트'!BL231+'자금수지(FS)_작성시트'!BL234+'자금수지(FS)_작성시트'!BL237+'자금수지(FS)_작성시트'!BL240+'자금수지(FS)_작성시트'!BL243 -> 56.069618 | BE9: =+'자금수지(FS)_작성시트'!BM231+'자금수지(FS)_작성시트'!BM234+'자금수지(FS)_작성시트'!BM237+'자금수지(FS)_작성시트'!BM240+'자금수지(FS)_작성시트'!BM243 -> 53.086344 | BF9: =+'자금수지(FS)_작성시트'!BN231+'자금수지(FS)_작성시트'!BN234+'자금수지(FS)_작성시트'!BN237+'자금수지(FS)_작성시트'!BN240+'자금수지(FS)_작성시트'!BN243 -> 65.428231 | ... BJ9: =+'자금수지(FS)_작성시트'!BR231+'자금수지(FS)_작성시트'!BR234+'자금수지(FS)_작성시트'!BR237+'자금수지(FS)_작성시트'!BR240+'자금수지(FS)_작성시트'!BR243 -> 48.072189 | BK9: =+'자금수지(FS)_작성시트'!BT231+'자금수지(FS)_작성시트'!BT234+'자금수지(FS)_작성시트'!BT237+'자금수지(FS)_작성시트'!BT240+'자금수지(FS)_작성시트'!BT243 -> 67.544562 | BL9: =+'자금수지(FS)_작성시트'!BU231+'자금수지(FS)_작성시트'!BU234+'자금수지(FS)_작성시트'!BU237+'자금수지(FS)_작성시트'!BU240+'자금수지(FS)_작성시트'!BU243 -> 86.597091 | BM9: =+'자금수지(FS)_작성시트'!BV231+'자금수지(FS)_작성시트'!BV234+'자금수지(FS)_작성시트'!BV237+'자금수지(FS)_작성시트'!BV240+'자금수지(FS)_작성시트'!BV243 -> 96.698086 | BN9: =+'자금수지(FS)_작성시트'!BW231+'자금수지(FS)_작성시트'!BW234+'자금수지(FS)_작성시트'!BW237+'자금수지(FS)_작성시트'!BW240+'자금수지(FS)_작성시트'!BW243 -> 88.690887 | BO9: =+'자금수지(FS)_작성시트'!BX231+'자금수지(FS)_작성시트'!BX234+'자금수지(FS)_작성시트'!BX237+'자금수지(FS)_작성시트'!BX240+'자금수지(FS)_작성시트'!BX243 -> 80.342683 | BP9: =+'자금수지(FS)_작성시트'!BY231+'자금수지(FS)_작성시트'!BY234+'자금수지(FS)_작성시트'!BY237+'자금수지(FS)_작성시트'!BY240+'자금수지(FS)_작성시트'!BY243 -> 83.596186 | BQ9: =+'자금수지(FS)_작성시트'!BZ231+'자금수지(FS)_작성시트'!BZ234+'자금수지(FS)_작성시트'!BZ237+'자금수지(FS)_작성시트'!BZ240+'자금수지(FS)_작성시트'!BZ243-BQ6 -> 4254.1459 | BR9: =+'자금수지(FS)_작성시트'!CA231+'자금수지(FS)_작성시트'!CA234+'자금수지(FS)_작성시트'!CA237+'자금수지(FS)_작성시트'!CA240+'자금수지(FS)_작성시트'!CA243 -> 164.58169 | BS9: =+'자금수지(FS)_작성시트'!CB231+'자금수지(FS)_작성시트'!CB234+'자금수지(FS)_작성시트'!CB237+'자금수지(FS)_작성시트'!CB240+'자금수지(FS)_작성시트'!CB243 -> 129.24149 | BT9: =+'자금수지(FS)_작성시트'!CC231+'자금수지(FS)_작성시트'!CC234+'자금수지(FS)_작성시트'!CC237+'자금수지(FS)_작성시트'!CC240+'자금수지(FS)_작성시트'!CC243 -> 133.89554 | BU9: =+'자금수지(FS)_작성시트'!CD231+'자금수지(FS)_작성시트'!CD234+'자금수지(FS)_작성시트'!CD237+'자금수지(FS)_작성시트'!CD240+'자금수지(FS)_작성시트'!CD243 -> 127.57938 | BV9: =+'자금수지(FS)_작성시트'!CE231+'자금수지(FS)_작성시트'!CE234+'자금수지(FS)_작성시트'!CE237+'자금수지(FS)_작성시트'!CE240+'자금수지(FS)_작성시트'!CE243 -> 132.52428 | BW9: =+'자금수지(FS)_작성시트'!CG231+'자금수지(FS)_작성시트'!CG234+'자금수지(FS)_작성시트'!CG237+'자금수지(FS)_작성시트'!CG240+'자금수지(FS)_작성시트'!CG243 -> 139.71033 | BX9: =+'자금수지(FS)_작성시트'!CH231+'자금수지(FS)_작성시트'!CH234+'자금수지(FS)_작성시트'!CH237+'자금수지(FS)_작성시트'!CH240+'자금수지(FS)_작성시트'!CH243 -> 145.04157 | BY9: =+'자금수지(FS)_작성시트'!CI231+'자금수지(FS)_작성시트'!CI234+'자금수지(FS)_작성시트'!CI237+'자금수지(FS)_작성시트'!CI240+'자금수지(FS)_작성시트'!CI243 -> 127.87079 | BZ9: =+'자금수지(FS)_작성시트'!CJ231+'자금수지(FS)_작성시트'!CJ234+'자금수지(FS)_작성시트'!CJ237+'자금수지(FS)_작성시트'!CJ240+'자금수지(FS)_작성시트'!CJ243 -> 128.34198 | CA9: =+'자금수지(FS)_작성시트'!CK231+'자금수지(FS)_작성시트'!CK234+'자금수지(FS)_작성시트'!CK237+'자금수지(FS)_작성시트'!CK240+'자금수지(FS)_작성시트'!CK243 -> 133.86902 | CB9: =+'자금수지(FS)_작성시트'!CL231+'자금수지(FS)_작성시트'!CL234+'자금수지(FS)_작성시트'!CL237+'자금수지(FS)_작성시트'!CL240+'자금수지(FS)_작성시트'!CL243 -> 140.29517 | CC9: =+'자금수지(FS)_작성시트'!CM231+'자금수지(FS)_작성시트'!CM234+'자금수지(FS)_작성시트'!CM237+'자금수지(FS)_작성시트'!CM240+'자금수지(FS)_작성시트'!CM243 -> 113.5796 | CD9: =+'자금수지(FS)_작성시트'!CN231+'자금수지(FS)_작성시트'!CN234+'자금수지(FS)_작성시트'!CN237+'자금수지(FS)_작성시트'!CN240+'자금수지(FS)_작성시트'!CN243 -> 120.01036 | ... CH9: =+'자금수지(FS)_작성시트'!CR231+'자금수지(FS)_작성시트'!CR234+'자금수지(FS)_작성시트'!CR237+'자금수지(FS)_작성시트'!CR240+'자금수지(FS)_작성시트'!CR243 -> 118.43412
B10: 수입 총계 | C10: =SUM(C5:C9) -> 2677.7997 | D10: =SUM(D5:D9) -> 2615.0402 | E10: =SUM(E5:E9) -> 1675.5555 | F10: =SUM(F5:F9) -> 1126.4085 | G10: =SUM(G5:G9) -> 966.26991 | H10: =SUM(H5:H9) -> 2596.3375 | I10: =SUM(I5:I9) -> 1834.8534 | J10: =SUM(J5:J9) -> 671.69645 | ... CH10: =SUM(CH5:CH9) -> 15951.409
A11: 지출 | B11: 영업지출 | C11: =+'자금수지(FS)_작성시트'!G5 -> 1884.912 | D11: =+'자금수지(FS)_작성시트'!H5 -> 1585.3505 | E11: =+'자금수지(FS)_작성시트'!I5 -> 2036.3751 | F11: =+'자금수지(FS)_작성시트'!J5 -> 1154.8133 | G11: =+'자금수지(FS)_작성시트'!K5 -> 2062.1812 | H11: =+'자금수지(FS)_작성시트'!L5 -> 1125.7989 | I11: =+'자금수지(FS)_작성시트'!M5 -> 1483.1628 | J11: =+'자금수지(FS)_작성시트'!N5 -> 884.48632 | ... N11: =+'자금수지(FS)_작성시트'!R5 -> 1552.2889 | O11: =+'자금수지(FS)_작성시트'!T5 -> 2322.1345 | P11: =+'자금수지(FS)_작성시트'!U5 -> 1117.9377 | Q11: =+'자금수지(FS)_작성시트'!V5 -> 955.4101 | R11: =+'자금수지(FS)_작성시트'!W5 -> 975.01553 | S11: =+'자금수지(FS)_작성시트'!X5 -> 1021.2955 | T11: =+'자금수지(FS)_작성시트'!Y5 -> 1055.7002 | U11: =+'자금수지(FS)_작성시트'!Z5 -> 1216.6466 | V11: =+'자금수지(FS)_작성시트'!AA5 -> 1250.1821 | ... Z11: =+'자금수지(FS)_작성시트'!AE5 -> 6072.4212 | AA11: =+'자금수지(FS)_작성시트'!AG5 -> 5420.8115 | AB11: =+'자금수지(FS)_작성시트'!AH5 -> 1242.4144 | AC11: =+'자금수지(FS)_작성시트'!AI5 -> 1290.7705 | AD11: =+'자금수지(FS)_작성시트'!AJ5 -> 2987.2081 | AE11: =+'자금수지(FS)_작성시트'!AK5 -> 3954.8912 | AF11: =+'자금수지(FS)_작성시트'!AL5 -> 3456.3917 | AG11: =+'자금수지(FS)_작성시트'!AM5 -> 2578.389 | AH11: =+'자금수지(FS)_작성시트'!AN5 -> 2865.3009 | ... AL11: =+'자금수지(FS)_작성시트'!AR5 -> 9966.0627 | AM11: =+'자금수지(FS)_작성시트'!AT5 -> 9911.4363 | AN11: =+'자금수지(FS)_작성시트'!AU5 -> 5681.4823 | AO11: =+'자금수지(FS)_작성시트'!AV5 -> 3514.9385 | AP11: =+'자금수지(FS)_작성시트'!AW5 -> 5429.3869 | AQ11: =+'자금수지(FS)_작성시트'!AX5 -> 7141.0439 | AR11: =+'자금수지(FS)_작성시트'!AY5 -> 6836.5693 | AS11: =+'자금수지(FS)_작성시트'!AZ5 -> 9997.1444 | AT11: =+'자금수지(FS)_작성시트'!BA5 -> 8075.3438 | ... AX11: =+'자금수지(FS)_작성시트'!BE5 -> 17076.537 | AY11: =+'자금수지(FS)_작성시트'!BG5 -> 15669.219 | AZ11: =+'자금수지(FS)_작성시트'!BH5 -> 19670.028 | BA11: =+'자금수지(FS)_작성시트'!BI5 -> 21313.045 | BB11: =+'자금수지(FS)_작성시트'!BJ5 -> 26631.418 | BC11: =+'자금수지(FS)_작성시트'!BK5 -> 27256.315 | BD11: =+'자금수지(FS)_작성시트'!BL5 -> 27764.222 | BE11: =+'자금수지(FS)_작성시트'!BM5 -> 43480.36 | BF11: =+'자금수지(FS)_작성시트'!BN5 -> 25711.824 | ... BJ11: =+'자금수지(FS)_작성시트'!BR5 -> 25366.187 | BK11: =+'자금수지(FS)_작성시트'!BT5 -> 24960.918 | BL11: =+'자금수지(FS)_작성시트'!BU5 -> 27049.412 | BM11: =+'자금수지(FS)_작성시트'!BV5 -> 26932.267 | BN11: =+'자금수지(FS)_작성시트'!BW5 -> 26799.363 | BO11: =+'자금수지(FS)_작성시트'!BX5 -> 25189.941 | BP11: =+'자금수지(FS)_작성시트'!BY5 -> 26126.894 | BQ11: =+'자금수지(FS)_작성시트'!BZ5 -> 26474.482 | BR11: =+'자금수지(FS)_작성시트'!CA5 -> 38497.92 | ... BV11: =+'자금수지(FS)_작성시트'!CE5 -> 26451.429 | BW11: =+'자금수지(FS)_작성시트'!CG5 -> 25100.864 | BX11: =+'자금수지(FS)_작성시트'!CH5 -> 25871.722 | BY11: =+'자금수지(FS)_작성시트'!CI5 -> 26807.292 | BZ11: =+'자금수지(FS)_작성시트'!CJ5 -> 25544.912 | CA11: =+'자금수지(FS)_작성시트'!CK5 -> 26197.106 | CB11: =+'자금수지(FS)_작성시트'!CL5 -> 26701.15 | CC11: =+'자금수지(FS)_작성시트'!CM5 -> 24742.401 | CD11: =+'자금수지(FS)_작성시트'!CN5 -> 22653.883 | ... CH11: =+'자금수지(FS)_작성시트'!CR5 -> 14320.371
B12: 대여금지출 | C12: =+'자금수지(FS)_작성시트'!G223 -> 0 | D12: =+'자금수지(FS)_작성시트'!H223 -> 0 | E12: =+'자금수지(FS)_작성시트'!I223 -> 0 | F12: =+'자금수지(FS)_작성시트'!J223 -> 0 | G12: =+'자금수지(FS)_작성시트'!K223 -> 0 | H12: =+'자금수지(FS)_작성시트'!L223 -> 0 | I12: =+'자금수지(FS)_작성시트'!M223 -> 0 | J12: =+'자금수지(FS)_작성시트'!N223 -> 0 | ... N12: =+'자금수지(FS)_작성시트'!R223 -> 0 | O12: =+'자금수지(FS)_작성시트'!T223 -> 0 | P12: =+'자금수지(FS)_작성시트'!U223 -> 0 | Q12: =+'자금수지(FS)_작성시트'!V223 -> 0 | R12: =+'자금수지(FS)_작성시트'!W223 -> 0 | S12: =+'자금수지(FS)_작성시트'!X223 -> 0 | T12: =+'자금수지(FS)_작성시트'!Y223 -> 0 | U12: =+'자금수지(FS)_작성시트'!Z223 -> 0 | V12: =+'자금수지(FS)_작성시트'!AA223 -> 0 | ... Z12: =+'자금수지(FS)_작성시트'!AE223 -> 0 | AA12: =+'자금수지(FS)_작성시트'!AG223 -> 0 | AB12: =+'자금수지(FS)_작성시트'!AH223 -> 0 | AC12: =+'자금수지(FS)_작성시트'!AI223 -> 0 | AD12: =+'자금수지(FS)_작성시트'!AJ223 -> 0 | AE12: =+'자금수지(FS)_작성시트'!AK223 -> 0 | AF12: =+'자금수지(FS)_작성시트'!AL223 -> 0 | AG12: =+'자금수지(FS)_작성시트'!AM223 -> 0 | AH12: =+'자금수지(FS)_작성시트'!AN223 -> 3962.6919 | ... AL12: =+'자금수지(FS)_작성시트'!AR223 -> 0 | AM12: =+'자금수지(FS)_작성시트'!AT223 -> 0 | AN12: =+'자금수지(FS)_작성시트'!AU223 -> 0 | AO12: =+'자금수지(FS)_작성시트'!AV223 -> 0 | AP12: =+'자금수지(FS)_작성시트'!AW223 -> 0 | AQ12: ='자금수지(FS)_작성시트'!AX188 -> 0 | AR12: ='자금수지(FS)_작성시트'!AY188 -> 0 | AS12: =+'자금수지(FS)_작성시트'!AZ223 -> 0 | AT12: ='자금수지(FS)_작성시트'!BA188 -> 0 | AU12: =+'자금수지(FS)_작성시트'!BB223 -> 0 | AV12: =+'자금수지(FS)_작성시트'!BC223 -> 0 | AW12: =+'자금수지(FS)_작성시트'!BD223 -> 0 | AX12: =+'자금수지(FS)_작성시트'!BE223 -> 0 | AY12: =+'자금수지(FS)_작성시트'!BG223 -> 0 | AZ12: =+'자금수지(FS)_작성시트'!BH223 -> 0 | BA12: =+'자금수지(FS)_작성시트'!BI223 -> 0 | BB12: =+'자금수지(FS)_작성시트'!BJ223 -> 0 | BC12: =+'자금수지(FS)_작성시트'!BK223 -> 0 | BD12: =+'자금수지(FS)_작성시트'!BL223 -> 0 | BE12: =+'자금수지(FS)_작성시트'!BM223 -> 0 | BF12: =+'자금수지(FS)_작성시트'!BN223 -> 0 | ... BJ12: =+'자금수지(FS)_작성시트'!BR223 -> 0 | BK12: =+'자금수지(FS)_작성시트'!BT223 -> 0 | BL12: =+'자금수지(FS)_작성시트'!BU223 -> 0 | BM12: =+'자금수지(FS)_작성시트'!BV223 -> 0 | BN12: =+'자금수지(FS)_작성시트'!BW223 -> 0 | BO12: =+'자금수지(FS)_작성시트'!BX223 -> 0 | BP12: =+'자금수지(FS)_작성시트'!BY223 -> 0 | BQ12: =+'자금수지(FS)_작성시트'!BZ223 -> 0 | BR12: =+'자금수지(FS)_작성시트'!CA223 -> 0 | ... BV12: =+'자금수지(FS)_작성시트'!CE223 -> 0 | BW12: =+'자금수지(FS)_작성시트'!CG223 -> 0 | BX12: =+'자금수지(FS)_작성시트'!CH223 -> 0 | BY12: =+'자금수지(FS)_작성시트'!CI223 -> 0 | BZ12: =+'자금수지(FS)_작성시트'!CJ223 -> 0 | CA12: =+'자금수지(FS)_작성시트'!CK223 -> 0 | CB12: =+'자금수지(FS)_작성시트'!CL223 -> 0 | CC12: =+'자금수지(FS)_작성시트'!CM223 -> 0 | CD12: =+'자금수지(FS)_작성시트'!CN223 -> 0 | ... CH12: =+'자금수지(FS)_작성시트'!CR223 -> 0
B13: 보증금지출 | C13: =+'자금수지(FS)_작성시트'!G226 -> 0 | D13: =+'자금수지(FS)_작성시트'!H226 -> 0 | E13: =+'자금수지(FS)_작성시트'!I226 -> 0 | F13: =+'자금수지(FS)_작성시트'!J226 -> 0 | G13: =+'자금수지(FS)_작성시트'!K226 -> 0 | H13: =+'자금수지(FS)_작성시트'!L226 -> 0 | I13: =+'자금수지(FS)_작성시트'!M226 -> 0 | J13: =+'자금수지(FS)_작성시트'!N226 -> 0 | ... N13: =+'자금수지(FS)_작성시트'!R226 -> 0 | O13: =+'자금수지(FS)_작성시트'!T226 -> 0.20631318 | P13: =+'자금수지(FS)_작성시트'!U226 -> 1.9691333 | Q13: =+'자금수지(FS)_작성시트'!V226 -> 1.6043867 | R13: =+'자금수지(FS)_작성시트'!W226 -> 0 | S13: =+'자금수지(FS)_작성시트'!X226 -> 0 | T13: =+'자금수지(FS)_작성시트'!Y226 -> 8.8756787 | U13: =+'자금수지(FS)_작성시트'!Z226 -> 6.3456107 | V13: =+'자금수지(FS)_작성시트'!AA226 -> -14.506555 | ... Z13: =+'자금수지(FS)_작성시트'!AE226 -> 0.80559336 | AA13: =+'자금수지(FS)_작성시트'!AG226 -> 4.1316628 | AB13: =+'자금수지(FS)_작성시트'!AH226 -> 4.4599412 | AC13: =+'자금수지(FS)_작성시트'!AI226 -> 38.411792 | AD13: =+'자금수지(FS)_작성시트'!AJ226 -> 1.3070388 | AE13: =+'자금수지(FS)_작성시트'!AK226 -> 1.9488756 | AF13: =+'자금수지(FS)_작성시트'!AL226 -> 0 | AG13: =+'자금수지(FS)_작성시트'!AM226 -> 4.8858577 | AH13: =+'자금수지(FS)_작성시트'!AN226 -> 1.8826471 | ... AL13: =+'자금수지(FS)_작성시트'!AR226 -> 1.9597945 | AM13: =+'자금수지(FS)_작성시트'!AT226 -> 4.9429443 | AN13: =+'자금수지(FS)_작성시트'!AU226 -> 0 | AO13: =+'자금수지(FS)_작성시트'!AV226 -> 0 | AP13: =+'자금수지(FS)_작성시트'!AW226 -> 0.66770363 | AQ13: =+'자금수지(FS)_작성시트'!AX226 -> 2.4161994 | AR13: =+'자금수지(FS)_작성시트'!AY226 -> 17.935906 | AS13: =+'자금수지(FS)_작성시트'!AZ226 -> 0 | AT13: =+'자금수지(FS)_작성시트'!BA226 -> 0 | ... AX13: =+'자금수지(FS)_작성시트'!BE226 -> 0 | AY13: =+'자금수지(FS)_작성시트'!BG226 -> 0 | AZ13: =+'자금수지(FS)_작성시트'!BH226 -> 0 | BA13: =+'자금수지(FS)_작성시트'!BI226 -> 0 | BB13: =+'자금수지(FS)_작성시트'!BJ226 -> 0 | BC13: =+'자금수지(FS)_작성시트'!BK226 -> 0 | BD13: =+'자금수지(FS)_작성시트'!BL226 -> 0 | BE13: =+'자금수지(FS)_작성시트'!BM226 -> 0 | BF13: =+'자금수지(FS)_작성시트'!BN226 -> 0 | ... BJ13: =+'자금수지(FS)_작성시트'!BR226 -> 0 | BK13: =+'자금수지(FS)_작성시트'!BT226 -> 0 | BL13: =+'자금수지(FS)_작성시트'!BU226 -> 0 | BM13: =+'자금수지(FS)_작성시트'!BV226 -> 0 | BN13: =+'자금수지(FS)_작성시트'!BW226 -> 0 | BO13: =+'자금수지(FS)_작성시트'!BX226 -> 0 | BP13: =+'자금수지(FS)_작성시트'!BY226 -> 0 | BQ13: =+'자금수지(FS)_작성시트'!BZ226 -> 0 | BR13: =+'자금수지(FS)_작성시트'!CA226 -> 0 | ... BV13: =+'자금수지(FS)_작성시트'!CE226 -> 0 | BW13: =+'자금수지(FS)_작성시트'!CG226 -> 0 | BX13: =+'자금수지(FS)_작성시트'!CH226 -> 0 | BY13: =+'자금수지(FS)_작성시트'!CI226 -> 0 | BZ13: =+'자금수지(FS)_작성시트'!CJ226 -> 0 | CA13: =+'자금수지(FS)_작성시트'!CK226 -> 0 | CB13: =+'자금수지(FS)_작성시트'!CL226 -> 0 | CC13: =+'자금수지(FS)_작성시트'!CM226 -> 0 | CD13: =+'자금수지(FS)_작성시트'!CN226 -> 0 | ... CH13: =+'자금수지(FS)_작성시트'!CR226 -> 0
B14: 은행차입상환 | C14: =+'자금수지(FS)_작성시트'!G229 -> 0 | D14: =+'자금수지(FS)_작성시트'!H229 -> 0 | E14: =+'자금수지(FS)_작성시트'!I229 -> 0 | F14: =+'자금수지(FS)_작성시트'!J229 -> 0 | G14: =+'자금수지(FS)_작성시트'!K229 -> 0 | H14: =+'자금수지(FS)_작성시트'!L229 -> 0 | I14: =+'자금수지(FS)_작성시트'!M229 -> 0 | J14: =+'자금수지(FS)_작성시트'!N229 -> 0 | ... N14: =+'자금수지(FS)_작성시트'!R229 -> 0 | O14: =+'자금수지(FS)_작성시트'!T229 -> 0 | P14: =+'자금수지(FS)_작성시트'!U229 -> 0 | Q14: =+'자금수지(FS)_작성시트'!V229 -> 0 | R14: =+'자금수지(FS)_작성시트'!W229 -> 0 | S14: =+'자금수지(FS)_작성시트'!X229 -> 0 | T14: =+'자금수지(FS)_작성시트'!Y229 -> 0 | U14: =+'자금수지(FS)_작성시트'!Z229 -> 0 | V14: =+'자금수지(FS)_작성시트'!AA229 -> 0 | ... Z14: =+'자금수지(FS)_작성시트'!AE229 -> 0 | AA14: =+'자금수지(FS)_작성시트'!AG229 -> 0 | AB14: =+'자금수지(FS)_작성시트'!AH229 -> 0 | AC14: =+'자금수지(FS)_작성시트'!AI229 -> 0 | AD14: =+'자금수지(FS)_작성시트'!AJ229 -> 0 | AE14: =+'자금수지(FS)_작성시트'!AK229 -> 0 | AF14: =+'자금수지(FS)_작성시트'!AL229 -> 0 | AG14: =+'자금수지(FS)_작성시트'!AM229 -> 0 | AH14: =+'자금수지(FS)_작성시트'!AN229 -> 0 | ... AL14: =+'자금수지(FS)_작성시트'!AR229 -> 0 | AM14: =+'자금수지(FS)_작성시트'!AT229 -> 0 | AN14: =+'자금수지(FS)_작성시트'!AU229 -> 0 | AO14: =+'자금수지(FS)_작성시트'!AV229 -> 0 | AP14: =+'자금수지(FS)_작성시트'!AW229 -> 0 | AQ14: =+'자금수지(FS)_작성시트'!AX229 -> 0 | AR14: =+'자금수지(FS)_작성시트'!AY229 -> 0 | AS14: =+'자금수지(FS)_작성시트'!AZ229 -> 0 | AT14: =+'자금수지(FS)_작성시트'!BA229 -> 0 | ... AX14: =+'자금수지(FS)_작성시트'!BE229 -> 0 | AY14: =+'자금수지(FS)_작성시트'!BG229 -> 0 | AZ14: =+'자금수지(FS)_작성시트'!BH229 -> 0 | BA14: =+'자금수지(FS)_작성시트'!BI229 -> 0 | BB14: =+'자금수지(FS)_작성시트'!BJ229 -> 0 | BC14: =+'자금수지(FS)_작성시트'!BK229 -> 0 | BD14: =+'자금수지(FS)_작성시트'!BL229 -> 0 | BE14: =+'자금수지(FS)_작성시트'!BM229 -> 0 | BF14: =+'자금수지(FS)_작성시트'!BN229 -> 0 | ... BJ14: =+'자금수지(FS)_작성시트'!BR229 -> 0 | BK14: =+'자금수지(FS)_작성시트'!BT229 -> 0 | BL14: =+'자금수지(FS)_작성시트'!BU229 -> 0 | BM14: =+'자금수지(FS)_작성시트'!BV229 -> 0 | BN14: =+'자금수지(FS)_작성시트'!BW229 -> 0 | BO14: =+'자금수지(FS)_작성시트'!BX229 -> 0 | BP14: =+'자금수지(FS)_작성시트'!BY229 -> 0 | BQ14: =+'자금수지(FS)_작성시트'!BZ229 -> 0 | BR14: =+'자금수지(FS)_작성시트'!CA229 -> 0 | ... BV14: =+'자금수지(FS)_작성시트'!CE229 -> 0 | BW14: =+'자금수지(FS)_작성시트'!CG229 -> 0 | BX14: =+'자금수지(FS)_작성시트'!CH229 -> 0 | BY14: =+'자금수지(FS)_작성시트'!CI229 -> 0 | BZ14: =+'자금수지(FS)_작성시트'!CJ229 -> 0 | CA14: =+'자금수지(FS)_작성시트'!CK229 -> 0 | CB14: =+'자금수지(FS)_작성시트'!CL229 -> 0 | CC14: =+'자금수지(FS)_작성시트'!CM229 -> 0 | CD14: =+'자금수지(FS)_작성시트'!CN229 -> 0 | ... CH14: =+'자금수지(FS)_작성시트'!CR229 -> 0
B15: 기타지출 | C15: =+'자금수지(FS)_작성시트'!G232+'자금수지(FS)_작성시트'!G235+'자금수지(FS)_작성시트'!G238+'자금수지(FS)_작성시트'!G241 -> -120.04592 | D15: =+'자금수지(FS)_작성시트'!H232+'자금수지(FS)_작성시트'!H235+'자금수지(FS)_작성시트'!H238+'자금수지(FS)_작성시트'!H241 -> 303.87641 | E15: =+'자금수지(FS)_작성시트'!I232+'자금수지(FS)_작성시트'!I235+'자금수지(FS)_작성시트'!I238+'자금수지(FS)_작성시트'!I241 -> -297.89657 | F15: =+'자금수지(FS)_작성시트'!J232+'자금수지(FS)_작성시트'!J235+'자금수지(FS)_작성시트'!J238+'자금수지(FS)_작성시트'!J241 -> -9.9071555 | G15: =+'자금수지(FS)_작성시트'!K232+'자금수지(FS)_작성시트'!K235+'자금수지(FS)_작성시트'!K238+'자금수지(FS)_작성시트'!K241 -> 30.4 | H15: =+'자금수지(FS)_작성시트'!L232+'자금수지(FS)_작성시트'!L235+'자금수지(FS)_작성시트'!L238+'자금수지(FS)_작성시트'!L241 -> 88.969389 | I15: =+'자금수지(FS)_작성시트'!M232+'자금수지(FS)_작성시트'!M235+'자금수지(FS)_작성시트'!M238+'자금수지(FS)_작성시트'!M241 -> 99.133653 | J15: =+'자금수지(FS)_작성시트'!N232+'자금수지(FS)_작성시트'!N235+'자금수지(FS)_작성시트'!N238+'자금수지(FS)_작성시트'!N241 -> 380.02656 | ... N15: =+'자금수지(FS)_작성시트'!R232+'자금수지(FS)_작성시트'!R235+'자금수지(FS)_작성시트'!R238+'자금수지(FS)_작성시트'!R241 -> 0 | O15: =+'자금수지(FS)_작성시트'!T232+'자금수지(FS)_작성시트'!T235+'자금수지(FS)_작성시트'!T238+'자금수지(FS)_작성시트'!T241+'자금수지(FS)_작성시트'!T244 -> 645.82342 | P15: =+'자금수지(FS)_작성시트'!U232+'자금수지(FS)_작성시트'!U235+'자금수지(FS)_작성시트'!U238+'자금수지(FS)_작성시트'!U241+'자금수지(FS)_작성시트'!U244 -> 438.92278 | Q15: =+'자금수지(FS)_작성시트'!V232+'자금수지(FS)_작성시트'!V235+'자금수지(FS)_작성시트'!V238+'자금수지(FS)_작성시트'!V241+'자금수지(FS)_작성시트'!V244 -> 458.80609 | R15: =+'자금수지(FS)_작성시트'!W232+'자금수지(FS)_작성시트'!W235+'자금수지(FS)_작성시트'!W238+'자금수지(FS)_작성시트'!W241+'자금수지(FS)_작성시트'!W244 -> 1033.5568 | S15: =+'자금수지(FS)_작성시트'!X232+'자금수지(FS)_작성시트'!X235+'자금수지(FS)_작성시트'!X238+'자금수지(FS)_작성시트'!X241+'자금수지(FS)_작성시트'!X244 -> 156.4169 | T15: =+'자금수지(FS)_작성시트'!Y232+'자금수지(FS)_작성시트'!Y235+'자금수지(FS)_작성시트'!Y238+'자금수지(FS)_작성시트'!Y241+'자금수지(FS)_작성시트'!Y244 -> 3617.1601 | U15: =+'자금수지(FS)_작성시트'!Z232+'자금수지(FS)_작성시트'!Z235+'자금수지(FS)_작성시트'!Z238+'자금수지(FS)_작성시트'!Z241+'자금수지(FS)_작성시트'!Z244 -> 0.54991034 | V15: =+'자금수지(FS)_작성시트'!AA232+'자금수지(FS)_작성시트'!AA235+'자금수지(FS)_작성시트'!AA238+'자금수지(FS)_작성시트'!AA241+'자금수지(FS)_작성시트'!AA244 -> 1.62873 | ... Z15: =+'자금수지(FS)_작성시트'!AE232+'자금수지(FS)_작성시트'!AE235+'자금수지(FS)_작성시트'!AE238+'자금수지(FS)_작성시트'!AE241+'자금수지(FS)_작성시트'!AE244 -> 570.88686 | AA15: =+'자금수지(FS)_작성시트'!AG232+'자금수지(FS)_작성시트'!AG235+'자금수지(FS)_작성시트'!AG238+'자금수지(FS)_작성시트'!AG241+'자금수지(FS)_작성시트'!AG244 -> 0 | AB15: =+'자금수지(FS)_작성시트'!AH232+'자금수지(FS)_작성시트'!AH235+'자금수지(FS)_작성시트'!AH238+'자금수지(FS)_작성시트'!AH241+'자금수지(FS)_작성시트'!AH244 -> 3136.5148 | AC15: =+'자금수지(FS)_작성시트'!AI232+'자금수지(FS)_작성시트'!AI235+'자금수지(FS)_작성시트'!AI238+'자금수지(FS)_작성시트'!AI241+'자금수지(FS)_작성시트'!AI244 -> 594.13028 | AD15: =+'자금수지(FS)_작성시트'!AJ232+'자금수지(FS)_작성시트'!AJ235+'자금수지(FS)_작성시트'!AJ238+'자금수지(FS)_작성시트'!AJ241+'자금수지(FS)_작성시트'!AJ244 -> 2368.7444 | AE15: =+'자금수지(FS)_작성시트'!AK232+'자금수지(FS)_작성시트'!AK235+'자금수지(FS)_작성시트'!AK238+'자금수지(FS)_작성시트'!AK241+'자금수지(FS)_작성시트'!AK244 -> 4033.1724 | AF15: =+'자금수지(FS)_작성시트'!AL232+'자금수지(FS)_작성시트'!AL235+'자금수지(FS)_작성시트'!AL238+'자금수지(FS)_작성시트'!AL241+'자금수지(FS)_작성시트'!AL244 -> 10412.821 | AG15: =+'자금수지(FS)_작성시트'!AM232+'자금수지(FS)_작성시트'!AM235+'자금수지(FS)_작성시트'!AM238+'자금수지(FS)_작성시트'!AM241+'자금수지(FS)_작성시트'!AM244 -> 6532.187 | AH15: =+'자금수지(FS)_작성시트'!AN232+'자금수지(FS)_작성시트'!AN235+'자금수지(FS)_작성시트'!AN238+'자금수지(FS)_작성시트'!AN241+'자금수지(FS)_작성시트'!AN244 -> 1015.4112 | ... AL15: =+'자금수지(FS)_작성시트'!AR232+'자금수지(FS)_작성시트'!AR235+'자금수지(FS)_작성시트'!AR238+'자금수지(FS)_작성시트'!AR241+'자금수지(FS)_작성시트'!AR244 -> 57261.804 | AM15: =+'자금수지(FS)_작성시트'!AT232+'자금수지(FS)_작성시트'!AT235+'자금수지(FS)_작성시트'!AT238+'자금수지(FS)_작성시트'!AT241+'자금수지(FS)_작성시트'!AT244 -> 3237.6684 | AN15: =+'자금수지(FS)_작성시트'!AU232+'자금수지(FS)_작성시트'!AU235+'자금수지(FS)_작성시트'!AU238+'자금수지(FS)_작성시트'!AU241+'자금수지(FS)_작성시트'!AU244 -> 288.79439 | AO15: =+'자금수지(FS)_작성시트'!AV232+'자금수지(FS)_작성시트'!AV235+'자금수지(FS)_작성시트'!AV238+'자금수지(FS)_작성시트'!AV241+'자금수지(FS)_작성시트'!AV244 -> 1604.733 | AP15: =+'자금수지(FS)_작성시트'!AW232+'자금수지(FS)_작성시트'!AW235+'자금수지(FS)_작성시트'!AW238+'자금수지(FS)_작성시트'!AW241+'자금수지(FS)_작성시트'!AW244 -> 1403.6951 | AQ15: =+'자금수지(FS)_작성시트'!AX232+'자금수지(FS)_작성시트'!AX235+'자금수지(FS)_작성시트'!AX238+'자금수지(FS)_작성시트'!AX241+'자금수지(FS)_작성시트'!AX244-AQ12 -> 157.86309 | AR15: =+'자금수지(FS)_작성시트'!AY232+'자금수지(FS)_작성시트'!AY235+'자금수지(FS)_작성시트'!AY238+'자금수지(FS)_작성시트'!AY241+'자금수지(FS)_작성시트'!AY244-AR12 -> 0 | AS15: =+'자금수지(FS)_작성시트'!AZ232+'자금수지(FS)_작성시트'!AZ235+'자금수지(FS)_작성시트'!AZ238+'자금수지(FS)_작성시트'!AZ241+'자금수지(FS)_작성시트'!AZ244 -> 19736 | AT15: =+'자금수지(FS)_작성시트'!BA232+'자금수지(FS)_작성시트'!BA235+'자금수지(FS)_작성시트'!BA238+'자금수지(FS)_작성시트'!BA241+'자금수지(FS)_작성시트'!BA244-AT12 -> 152.03 | AU15: =+'자금수지(FS)_작성시트'!BB232+'자금수지(FS)_작성시트'!BB235+'자금수지(FS)_작성시트'!BB238+'자금수지(FS)_작성시트'!BB241+'자금수지(FS)_작성시트'!BB244 -> 8875 | AV15: =+'자금수지(FS)_작성시트'!BC232+'자금수지(FS)_작성시트'!BC235+'자금수지(FS)_작성시트'!BC238+'자금수지(FS)_작성시트'!BC241+'자금수지(FS)_작성시트'!BC244 -> 1010 | AW15: =+'자금수지(FS)_작성시트'!BD232+'자금수지(FS)_작성시트'!BD235+'자금수지(FS)_작성시트'!BD238+'자금수지(FS)_작성시트'!BD241+'자금수지(FS)_작성시트'!BD244 -> 152.03 | AX15: =+'자금수지(FS)_작성시트'!BE232+'자금수지(FS)_작성시트'!BE235+'자금수지(FS)_작성시트'!BE238+'자금수지(FS)_작성시트'!BE241+'자금수지(FS)_작성시트'!BE244 -> 0 | AY15: =+'자금수지(FS)_작성시트'!BG232+'자금수지(FS)_작성시트'!BG235+'자금수지(FS)_작성시트'!BG238+'자금수지(FS)_작성시트'!BG241+'자금수지(FS)_작성시트'!BG244 -> 635 | AZ15: =+'자금수지(FS)_작성시트'!BH232+'자금수지(FS)_작성시트'!BH235+'자금수지(FS)_작성시트'!BH238+'자금수지(FS)_작성시트'!BH241+'자금수지(FS)_작성시트'!BH244 -> 2864.03 | BA15: =+'자금수지(FS)_작성시트'!BI232+'자금수지(FS)_작성시트'!BI235+'자금수지(FS)_작성시트'!BI238+'자금수지(FS)_작성시트'!BI241+'자금수지(FS)_작성시트'!BI244 -> 771 | BB15: =+'자금수지(FS)_작성시트'!BJ232+'자금수지(FS)_작성시트'!BJ235+'자금수지(FS)_작성시트'!BJ238+'자금수지(FS)_작성시트'!BJ241+'자금수지(FS)_작성시트'!BJ244 -> 1823.4197 | BC15: =+'자금수지(FS)_작성시트'!BK232+'자금수지(FS)_작성시트'!BK235+'자금수지(FS)_작성시트'!BK238+'자금수지(FS)_작성시트'!BK241+'자금수지(FS)_작성시트'!BK244 -> 152.03 | BD15: =+'자금수지(FS)_작성시트'!BL232+'자금수지(FS)_작성시트'!BL235+'자금수지(FS)_작성시트'!BL238+'자금수지(FS)_작성시트'!BL241+'자금수지(FS)_작성시트'!BL244 -> 0 | BE15: =+'자금수지(FS)_작성시트'!BM232+'자금수지(FS)_작성시트'!BM235+'자금수지(FS)_작성시트'!BM238+'자금수지(FS)_작성시트'!BM241+'자금수지(FS)_작성시트'!BM244 -> 57725.255 | BF15: =+'자금수지(FS)_작성시트'!BN232+'자금수지(FS)_작성시트'!BN235+'자금수지(FS)_작성시트'!BN238+'자금수지(FS)_작성시트'!BN241+'자금수지(FS)_작성시트'!BN244 -> 152.03 | ... BJ15: =+'자금수지(FS)_작성시트'!BR232+'자금수지(FS)_작성시트'!BR235+'자금수지(FS)_작성시트'!BR238+'자금수지(FS)_작성시트'!BR241+'자금수지(FS)_작성시트'!BR244 -> 0 | BK15: =+'자금수지(FS)_작성시트'!BT232+'자금수지(FS)_작성시트'!BT235+'자금수지(FS)_작성시트'!BT238+'자금수지(FS)_작성시트'!BT241+'자금수지(FS)_작성시트'!BT244 -> 1022 | BL15: =+'자금수지(FS)_작성시트'!BU232+'자금수지(FS)_작성시트'!BU235+'자금수지(FS)_작성시트'!BU238+'자금수지(FS)_작성시트'!BU241+'자금수지(FS)_작성시트'!BU244 -> 152.03 | BM15: =+'자금수지(FS)_작성시트'!BV232+'자금수지(FS)_작성시트'!BV235+'자금수지(FS)_작성시트'!BV238+'자금수지(FS)_작성시트'!BV241+'자금수지(FS)_작성시트'!BV244 -> 2140 | BN15: =+'자금수지(FS)_작성시트'!BW232+'자금수지(FS)_작성시트'!BW235+'자금수지(FS)_작성시트'!BW238+'자금수지(FS)_작성시트'!BW241+'자금수지(FS)_작성시트'!BW244 -> 2848.9146 | BO15: =+'자금수지(FS)_작성시트'!BX232+'자금수지(FS)_작성시트'!BX235+'자금수지(FS)_작성시트'!BX238+'자금수지(FS)_작성시트'!BX241+'자금수지(FS)_작성시트'!BX244 -> 152.03 | BP15: =+'자금수지(FS)_작성시트'!BY232+'자금수지(FS)_작성시트'!BY235+'자금수지(FS)_작성시트'!BY238+'자금수지(FS)_작성시트'!BY241+'자금수지(FS)_작성시트'!BY244 -> 6780 | BQ15: =+'자금수지(FS)_작성시트'!BZ232+'자금수지(FS)_작성시트'!BZ235+'자금수지(FS)_작성시트'!BZ238+'자금수지(FS)_작성시트'!BZ241+'자금수지(FS)_작성시트'!BZ244 -> 3204.0221 | BR15: =+'자금수지(FS)_작성시트'!CA232+'자금수지(FS)_작성시트'!CA235+'자금수지(FS)_작성시트'!CA238+'자금수지(FS)_작성시트'!CA241+'자금수지(FS)_작성시트'!CA244 -> 152.03 | ... BV15: =+'자금수지(FS)_작성시트'!CE232+'자금수지(FS)_작성시트'!CE235+'자금수지(FS)_작성시트'!CE238+'자금수지(FS)_작성시트'!CE241+'자금수지(FS)_작성시트'!CE244 -> 0 | BW15: =+'자금수지(FS)_작성시트'!CG232+'자금수지(FS)_작성시트'!CG235+'자금수지(FS)_작성시트'!CG238+'자금수지(FS)_작성시트'!CG241+'자금수지(FS)_작성시트'!CG244 -> 83 | BX15: =+'자금수지(FS)_작성시트'!CH232+'자금수지(FS)_작성시트'!CH235+'자금수지(FS)_작성시트'!CH238+'자금수지(FS)_작성시트'!CH241+'자금수지(FS)_작성시트'!CH244 -> 6932.03 | BY15: =+'자금수지(FS)_작성시트'!CI232+'자금수지(FS)_작성시트'!CI235+'자금수지(FS)_작성시트'!CI238+'자금수지(FS)_작성시트'!CI241+'자금수지(FS)_작성시트'!CI244 -> 1735 | BZ15: =+'자금수지(FS)_작성시트'!CJ232+'자금수지(FS)_작성시트'!CJ235+'자금수지(FS)_작성시트'!CJ238+'자금수지(FS)_작성시트'!CJ241+'자금수지(FS)_작성시트'!CJ244 -> 332.14731 | CA15: =+'자금수지(FS)_작성시트'!CK232+'자금수지(FS)_작성시트'!CK235+'자금수지(FS)_작성시트'!CK238+'자금수지(FS)_작성시트'!CK241+'자금수지(FS)_작성시트'!CK244 -> 152.03 | CB15: =+'자금수지(FS)_작성시트'!CL232+'자금수지(FS)_작성시트'!CL235+'자금수지(FS)_작성시트'!CL238+'자금수지(FS)_작성시트'!CL241+'자금수지(FS)_작성시트'!CL244 -> 10170 | CC15: =+'자금수지(FS)_작성시트'!CM232+'자금수지(FS)_작성시트'!CM235+'자금수지(FS)_작성시트'!CM238+'자금수지(FS)_작성시트'!CM241+'자금수지(FS)_작성시트'!CM244 -> 485.5471 | CD15: =+'자금수지(FS)_작성시트'!CN232+'자금수지(FS)_작성시트'!CN235+'자금수지(FS)_작성시트'!CN238+'자금수지(FS)_작성시트'!CN241+'자금수지(FS)_작성시트'!CN244 -> 152.03 | ... CH15: =+'자금수지(FS)_작성시트'!CR232+'자금수지(FS)_작성시트'!CR235+'자금수지(FS)_작성시트'!CR238+'자금수지(FS)_작성시트'!CR241+'자금수지(FS)_작성시트'!CR244 -> 0
B16: 지출 총계 | C16: =SUM(C11:C15) -> 1764.8661 | D16: =SUM(D11:D15) -> 1889.227 | E16: =SUM(E11:E15) -> 1738.4785 | F16: =SUM(F11:F15) -> 1144.9062 | G16: =SUM(G11:G15) -> 2092.5812 | H16: =SUM(H11:H15) -> 1214.7683 | I16: =SUM(I11:I15) -> 1582.2965 | J16: =SUM(J11:J15) -> 1264.5129 | ... CH16: =SUM(CH11:CH15) -> 14320.371
A17: 수지 | B17: 과부족 | C17: =+C10-C16 -> 912.93362 | D17: =+D10-D16 -> 725.81327 | E17: =+E10-E16 -> -62.923032 | F17: =+F10-F16 -> -18.497689 | G17: =+G10-G16 -> -1126.3113 | H17: =+H10-H16 -> 1381.5692 | I17: =+I10-I16 -> 252.5569 | J17: =+J10-J16 -> -592.81642 | ... CH17: =+CH10-CH16 -> 1631.0385
B18: 과부족 누계 | C18: =21579+C17 -> 22491.934 | D18: =+C18+D17 -> 23217.747 | E18: =+D18+E17 -> 23154.824 | F18: =+E18+F17 -> 23136.326 | G18: =+F18+G17 -> 22010.015 | H18: =+G18+H17 -> 23391.584 | I18: =+H18+I17 -> 23644.141 | J18: =+I18+J17 -> 23051.325 | K18: =+J18+K17 -> 22704.368 | ... CH18: =+CG18+CH17 -> 37161.274
C19: =+'자금수지(FS)_작성시트'!G13 -> 22491.934 | D19: =+'자금수지(FS)_작성시트'!H13 -> 23217.747 | E19: =+'자금수지(FS)_작성시트'!I13 -> 23154.824 | F19: =+'자금수지(FS)_작성시트'!J13 -> 23136.326 | G19: =+'자금수지(FS)_작성시트'!K13 -> 22010.015 | H19: =+'자금수지(FS)_작성시트'!L13 -> 23391.584 | I19: =+'자금수지(FS)_작성시트'!M13 -> 23644.141 | J19: =+'자금수지(FS)_작성시트'!N13 -> 23051.325 | ... N19: =+'자금수지(FS)_작성시트'!R13 -> 48011.997 | O19: =+'자금수지(FS)_작성시트'!T13 -> 47718.722 | P19: =+'자금수지(FS)_작성시트'!U13 -> 47410.811 | Q19: =+'자금수지(FS)_작성시트'!V13 -> 46625.749 | R19: =+'자금수지(FS)_작성시트'!W13 -> 45368.243 | S19: =+'자금수지(FS)_작성시트'!X13 -> 45170.113 | T19: =+'자금수지(FS)_작성시트'!Y13 -> 41359.151 | U19: =+'자금수지(FS)_작성시트'!Z13 -> 122319.16 | V19: =+'자금수지(FS)_작성시트'!AA13 -> 124104.71 | ... Z19: =+'자금수지(FS)_작성시트'!AE13 -> 148173.73 | AA19: =+'자금수지(FS)_작성시트'!AG13 -> 150386.15 | AB19: =+'자금수지(FS)_작성시트'!AH13 -> 147124.72 | AC19: =+'자금수지(FS)_작성시트'!AI13 -> 146706.09 | AD19: =+'자금수지(FS)_작성시트'!AJ13 -> 144289.35 | AE19: =+'자금수지(FS)_작성시트'!AK13 -> 143244.75 | AF19: =+'자금수지(FS)_작성시트'!AL13 -> 133660.12 | AG19: =+'자금수지(FS)_작성시트'!AM13 -> 128477.4 | AH19: =+'자금수지(FS)_작성시트'!AN13 -> 126474.65 | ... AL19: =+'자금수지(FS)_작성시트'!AR13 -> 76334.82 | AM19: =+'자금수지(FS)_작성시트'!AT13 -> 77676.156 | AN19: =+'자금수지(FS)_작성시트'!AU13 -> 80349.125 | AO19: =+'자금수지(FS)_작성시트'!AV13 -> 79981.206 | AP19: =+'자금수지(FS)_작성시트'!AW13 -> 78169.622 | AQ19: =+'자금수지(FS)_작성시트'!AX13 -> 71219.62 | AR19: =+'자금수지(FS)_작성시트'!AY13 -> 66870.987 | AS19: =+'자금수지(FS)_작성시트'!AZ13 -> 37500.146 | AT19: =+'자금수지(FS)_작성시트'!BA13 -> 36233.895 | ... AX19: =+'자금수지(FS)_작성시트'!BE13 -> 23580.616 | AY19: =+'자금수지(FS)_작성시트'!BG13 -> 25593.899 | AZ19: =+'자금수지(FS)_작성시트'!BH13 -> 18090.285 | BA19: =+'자금수지(FS)_작성시트'!BI13 -> 13932.101 | BB19: =+'자금수지(FS)_작성시트'!BJ13 -> 19697.664 | BC19: =+'자금수지(FS)_작성시트'!BK13 -> 16820.885 | BD19: =+'자금수지(FS)_작성시트'!BL13 -> 15925.903 | BE19: =+'자금수지(FS)_작성시트'!BM13 -> 19628.469 | BF19: =+'자금수지(FS)_작성시트'!BN13 -> 20095.456 | ... BJ19: =+'자금수지(FS)_작성시트'!BR13 -> 20263.369 | BK19: =+'자금수지(FS)_작성시트'!BT13 -> 25979.127 | BL19: =+'자금수지(FS)_작성시트'!BU13 -> 29009.426 | BM19: =+'자금수지(FS)_작성시트'!BV13 -> 26607.266 | BN19: =+'자금수지(FS)_작성시트'!BW13 -> 24102.805 | BO19: =+'자금수지(FS)_작성시트'!BX13 -> 25078.856 | BP19: =+'자금수지(FS)_작성시트'!BY13 -> 18943.773 | BQ19: =+'자금수지(FS)_작성시트'!BZ13 -> 49374.506 | BR19: =+'자금수지(FS)_작성시트'!CA13 -> 38772.448 | ... BV19: =+'자금수지(FS)_작성시트'!CE13 -> 41913.098 | BW19: =+'자금수지(FS)_작성시트'!CG13 -> 43512.47 | BX19: =+'자금수지(FS)_작성시트'!CH13 -> 38361.237 | BY19: =+'자금수지(FS)_작성시트'!CI13 -> 38502.593 | BZ19: =+'자금수지(FS)_작성시트'!CJ13 -> 40160.706 | CA19: =+'자금수지(FS)_작성시트'!CK13 -> 42088.55 | CB19: =+'자금수지(FS)_작성시트'!CL13 -> 34073.881 | CC19: =+'자금수지(FS)_작성시트'!CM13 -> 36003.108 | CD19: =+'자금수지(FS)_작성시트'!CN13 -> 37781.994 | ... CH19: =+'자금수지(FS)_작성시트'!CR13 -> 37161.274
A20: 수입 | B20: 기성수금 일자 | D20: 23 | E20: 23 | F20: 20 | G20: 25 | H20: 22 | I20: 20 | J20: 24 | K20: 21 | L20: 26 | M20: 23 | N20: 21 | O20: 25 | P20: 22 | Q20: 28 | R20: 25 | S20: 23 | T20: 20 | U20: 25 | V20: 29 | W20: 26 | X20: 24 | Y20: 28 | Z20: 26 | AA20: 23 | AB20: 27 | AC20: 27 | AD20: 24 | AE20: 29 | AF20: 26 | AG20: 25 | AH20: 28 | AI20: 25 | AJ20: 23 | AK20: 27 | AL20: 26 | AM20: 23 | AN20: 26 | AO20: 26 | AP20: 28 | AQ20: 29 | AR20: 26 | AS20: 30 | AT20: 28 | AU20: 30 | AV20: 29 | AW20: 27 | AX20: 25 | AY20: 28
B21: 영업수익 | D21: =D5 -> 2585.0402 | E21: =E5 -> 1643.8651 | F21: =F5 -> 1095.5899 | G21: =G5 -> 938.78216 | H21: =H5 -> 2572.7345 | I21: =I5 -> 1109.6346 | J21: =J5 -> 640.46318 | K21: =K5 -> 824.97447 | ... AY21: =AY5 -> 18238.9
B22: 기타수입 | D22: =D9 -> 30 | E22: =E9 -> 31.690436 | F22: =F9 -> 30.818566 | G22: =G9 -> 27.487748 | H22: =H9 -> 23.602977 | I22: =I9 -> 725.21885 | J22: =J9 -> 31.233271 | K22: =K9 -> 15.518961 | ... AY22: =AY9 -> 78.602054
B23: 수입 계 | D23: =D21+D22 -> 2615.0402 | E23: =E21+E22 -> 1675.5555 | F23: =F21+F22 -> 1126.4085 | G23: =G21+G22 -> 966.26991 | H23: =H21+H22 -> 2596.3375 | I23: =I21+I22 -> 1834.8534 | J23: =J21+J22 -> 671.69645 | K23: =K21+K22 -> 840.49343 | ... AY23: =AY21+AY22 -> 18317.502
AM24: =AM10-AM23 -> 0 | AN24: 0 | AO24: 0 | AP24: 0 | AQ24: 0 | AR24: 0 | AS24: 0 | AT24: 0 | AU24: 0 | AV24: 0 | AW24: 0 | AX24: 0 | AY24: 0
A25: 지출 | B25: 1차 집행일 | D25: 10 | E25: 17 | F25: 14 | G25: 12 | H25: 16 | I25: 14 | J25: 11 | K25: 15 | L25: 13 | M25: 17 | N25: 15 | O25: 15 | P25: 15 | Q25: 15 | R25: 12 | S25: 17 | T25: 10 | U25: 12 | V25: 9 | W25: 13 | X25: 11 | Y25: 15 | Z25: 13 | AA25: 10 | AB25: 14 | AC25: 14 | AD25: 11 | AE25: 16 | AF25: 13 | AG25: 19 | AH25: 15 | AI25: 12 | AJ25: 17 | AK25: 14 | AL25: 12 | AM25: 16 | AN25: 13 | AO25: 13 | AP25: 15 | AQ25: 15 | AR25: 12 | AS25: 15 | AT25: 14 | AU25: 15 | AV25: 15 | AW25: 13 | AX25: 15 | AY25: 15
D26: =D11*0.2 -> 317.07011 | E26: =E11*0.2 -> 407.27502 | F26: =F11*0.2 -> 230.96267 | G26: =G11*0.2 -> 412.43624 | H26: =H11*0.2 -> 225.15977 | I26: =I11*0.2 -> 296.63257 | J26: =J11*0.2 -> 176.89726 | K26: =K11*0.2 -> 195.58734 | ... AY26: =AY11*0.2 -> 3133.8438
B27: 2차 집행일 | D27: 28 | E27: 31 | F27: 28 | G27: 31 | H27: 30 | I27: 31 | J27: 31 | K27: 29 | L27: 31 | M27: 30 | N27: 29 | O27: 29 | P27: 29 | Q27: 29 | R27: 30 | S27: 31 | T27: 28 | U27: 31 | V27: 30 | W27: 30 | X27: 30 | Y27: 29 | Z27: 27 | AA27: 24 | AB27: 28 | AC27: 31 | AD27: 30 | AE27: 30 | AF27: 27 | AG27: 31 | AH27: 29 | AI27: 30 | AJ27: 31 | AK27: 28 | AL27: 31 | AM27: 30 | AN27: 27 | AO27: 27 | AP27: 29 | AQ27: 29 | AR27: 30 | AS27: 31 | AT27: 28 | AU27: 30 | AV27: 30 | AW27: 30 | AX27: 31 | AY27: 29
D28: =D11*0.8 -> 1268.2804 | E28: =E11*0.8 -> 1629.1001 | F28: =F11*0.8 -> 923.85067 | G28: =G11*0.8 -> 1649.745 | H28: =H11*0.8 -> 900.6391 | I28: =I11*0.8 -> 1186.5303 | J28: =J11*0.8 -> 707.58905 | K28: =K11*0.8 -> 782.34935 | ... AY28: =AY11*0.8 -> 12535.375
B29: 기타지출 | D29: =D15 -> 303.87641 | E29: =E15 -> -297.89657 | F29: =F15 -> -9.9071555 | G29: =G15 -> 30.4 | H29: =H15 -> 88.969389 | I29: =I15 -> 99.133653 | J29: =J15 -> 380.02656 | K29: =K15 -> 209.51375 | ... AQ29: =AQ15 -> 157.86309 | AR29: =AR12 -> 0 | AS29: =AS15 -> 19736 | AT29: =AT15+AT12 -> 152.03 | AU29: =AU15 -> 8875 | AV29: =AV15 -> 1010 | AW29: =AW15 -> 152.03 | AX29: =AX15 -> 0 | AY29: =AY15 -> 635
B30: 지출 계 | D30: =D28+D26+D29 -> 1889.227 | E30: =E28+E26+E29 -> 1738.4785 | F30: =F28+F26+F29 -> 1144.9062 | G30: =G28+G26+G29 -> 2092.5812 | H30: =H28+H26+H29 -> 1214.7683 | I30: =I28+I26+I29 -> 1582.2965 | J30: =J28+J26+J29 -> 1264.5129 | K30: =K28+K26+K29 -> 1187.4504 | ... AY30: =AY28+AY26+AY29 -> 16304.219
AM31: =AM16-AM30 -> 4.9429443 | AN31: =AN16-AN30 -> 0 | AO31: =AO16-AO30 -> 0 | AP31: =AP16-AP30 -> 0.66770363 | AQ31: =AQ16-AQ30 -> 2.4161994 | AR31: =AR16-AR30 -> 17.935906 | AS31: =AS16-AS30 -> 0 | AT31: =AT16-AT30 -> 0 | ... AW31: =AW16-AW30 -> 0
B32: EPA 수입 | E32: 1369 | F32: 895 | G32: 858 | H32: 2037 | I32: 1719 | J32: 24980 | K32: 25015 | L32: 1100 | M32: 25665 | N32: 3044 | Q32: 993 | T32: 870.77341 | U32: 82183.553 | V32: 3022.8541 | W32: 2100.1871 | X32: 889.85455 | Y32: 5232.8136 | Z32: 32086.175 | AA32: 7637.3545 | AB32: 1121.966 | AC32: 1504.6779 | AD32: 2940.526 | AE32: 6945.41 | AF32: 4284.585 | AG32: 3932.74 | AH32: 5842.5378 | AI32: 2753.5817 | AJ32: 2402.335 | AK32: 4061.4161 | AL32: 17470.8 | AM32: 14495.383 | AN32: 8643.2453 | AO32: 4751.7529 | AP32: 5022.1657 | AQ32: 351.32115 | AR32: 2505.8723 | AS32: 362.30329 | AT32: 6961.123 | AU32: 5969.7948 | AV32: 7694.7842 | AW32: 13200.781 | AX32: 16429.106 | AY32: 18317.502 | AZ32: 15030.444 | BA32: 17925.86 | BB32: 34220.4 | BC32: 24531.567 | BD32: 26869.239 | BE32: 104908.18 | BF32: 26330.841 | BG32: 27038.191 | BH32: 24210.739 | BI32: 27899.207 | BJ32: 31207.898 | BK32: 31698.677 | BL32: 30231.741 | BM32: 26670.107 | BN32: 27143.816 | BO32: 26318.022 | BP32: 26771.811 | BQ32: 60109.237 | BR32: 28047.893 | BS32: 26598.573 | BT32: 27334.614 | BU32: 27853.994 | BV32: 28607.244 | BW32: 26783.237 | BX32: 27652.519 | BY32: 28683.648 | BZ32: 27535.172 | CA32: 28276.979 | CB32: 28856.48 | CC32: 27157.176 | CD32: 24584.799 | CE32: 24468.587 | CF32: 25943.414 | CG32: 15340.409 | CH32: 15951.409
B33: EPA 지출 | E33: 1533 | F33: 1243 | G33: 1130 | H33: 1096 | I33: 1725 | J33: 1356 | K33: 1365 | L33: 1306 | M33: 2204 | N33: 1962 | Q33: 5206 | T33: 4681.7359 | U33: 1223.5421 | V33: 1237.3043 | W33: 1110.4107 | X33: 4742.3073 | Y33: 3945.239 | Z33: 6220.4563 | AA33: 5424.9432 | AB33: 4383.3891 | AC33: 1923.3126 | AD33: 5357.2595 | AE33: 7990.0125 | AF33: 13869.213 | AG33: 9115.4618 | AH33: 7845.2867 | AI33: 2964.2778 | AJ33: 2124.1461 | AK33: 4509.7158 | AL33: 67229.826 | AM33: 13154.048 | AN33: 5970.2767 | AO33: 5119.6715 | AP33: 6833.7498 | AQ33: 7301.3232 | AR33: 6854.5052 | AS33: 29733.144 | AT33: 8227.3738 | AU33: 16116.325 | AV33: 8953.2787 | AW33: 13801.604 | AX33: 17076.537 | AY33: 16304.219 | AZ33: 22534.058 | BA33: 22084.045 | BB33: 28454.837 | BC33: 27408.345 | BD33: 27764.222 | BE33: 101205.62 | BF33: 25863.854 | BG33: 32813.233 | BH33: 27146.748 | BI33: 24861.955 | BJ33: 25366.187 | BK33: 25982.918 | BL33: 27201.442 | BM33: 29072.267 | BN33: 29648.277 | BO33: 25341.971 | BP33: 32906.894 | BQ33: 29678.505 | BR33: 38649.95 | BS33: 25202.36 | BT33: 29229.462 | BU33: 26370.525 | BV33: 26451.429 | BW33: 25183.864 | BX33: 32803.752 | BY33: 28542.292 | BZ33: 25877.059 | CA33: 26349.136 | CB33: 36871.15 | CC33: 25227.948 | CD33: 22805.913 | CE33: 22532.818 | CF33: 31144.095 | CG33: 14327.256 | CH33: 14320.371
B34: 검증 | D34: =D23-D32 -> 2615.0402 | E34: =E23-E32 -> 306.5555 | F34: =F23-F32 -> 231.4085 | G34: =G23-G32 -> 108.26991 | H34: =H23-H32 -> 559.33747 | I34: =I23-I32 -> 115.8534 | J34: =J23-J32 -> -24308.304 | K34: =K23-K32 -> -24174.507 | ... N34: =N23-N32 -> -16.648477 | P34: =P10-P32 -> 1250.9192 | Q34: =Q10-Q32 -> -362.24146 | R34: =R10-R32 -> 751.06609 | S34: =S10-S32 -> 979.58283 | T34: =T10-T32 -> 0 | U34: =U10-U32 -> 0 | V34: =V10-V32 -> 0 | W34: =W10-W32 -> 0 | ... CH34: =CH10-CH32 -> 0
D35: =D30-D33 -> 1889.227 | E35: =E30-E33 -> 205.47853 | F35: =F30-F33 -> -98.093814 | G35: =G30-G33 -> 962.58121 | H35: =H30-H33 -> 118.76826 | I35: =I30-I33 -> -142.70351 | J35: =J30-J33 -> -91.487128 | K35: =K30-K33 -> -177.54957 | ... N35: =N30-N33 -> -409.71114 | P35: =P16-P33 -> 1558.8296 | Q35: =Q16-Q33 -> -3790.1794 | R35: =R16-R33 -> 2008.5723 | S35: =S16-S33 -> 1177.7124 | T35: =T16-T33 -> 0 | U35: =U16-U33 -> 0 | V35: =V16-V33 -> 0 | W35: =W16-W33 -> 0 | ... CH35: =CH16-CH33 -> 0
B37: 시트 검증 | C37: =C18-C19 -> 0 | D37: =D18-D19 -> 0 | E37: =E18-E19 -> 0 | F37: =F18-F19 -> 0 | G37: =G18-G19 -> 0 | H37: =H18-H19 -> 0 | I37: =I18-I19 -> 0 | J37: =J18-J19 -> 0 | ... CH37: =CH18-CH19 -> 0

Sheet 자금수지(FS)_작성시트
A1: ▶ DECV법인 Cash Flow
A2: [단위:천USD] | DH2: 검증
A3: 구분 | C3: 약정항목명 | E3: Total | F3: 22년말 소계 | G3: 44927 | H3: 44958 | I3: 44986 | J3: 45017 | K3: 45047 | L3: 45078 | M3: 45108 | N3: 45139 | O3: 45170 | P3: 45200 | Q3: 45231 | R3: 45261 | S3: 23년계 | T3: 45292 | U3: 45323 | V3: 45352 | W3: 45383 | X3: 45413 | Y3: 45444 | Z3: 45474 | AA3: 45505 | AB3: 45536 | AC3: 45566 | AD3: 45597 | AE3: 45627 | AF3: 24년계 | AG3: 45658 | AH3: 45689 | AI3: 45717 | AJ3: 45748 | AK3: 45778 | AL3: 45809 | AM3: 45839 | AN3: 45870 | AO3: 45901 | AP3: 45931 | AQ3: 45962 | AR3: 45992 | AS3: 25년계 | AT3: 46023 | AU3: 46054 | AV3: 46082 | AW3: 46113 | AX3: 46143 | AY3: 46174 | AZ3: 46204 | BA3: 46235 | BB3: 46266 | BC3: 46296 | BD3: 46327 | BE3: 46357 | BF3: 26년계 | BG3: 46388 | BH3: 46419 | BI3: 46447 | BJ3: 46478 | BK3: 46508 | BL3: 46539 | BM3: 46569 | BN3: 46600 | BO3: 46631 | BP3: 46661 | BQ3: 46692 | BR3: 46722 | BS3: 27년계 | BT3: 46753 | BU3: 46784 | BV3: 46813 | BW3: 46844 | BX3: 46874 | BY3: 46905 | BZ3: 46935 | CA3: 46966 | CB3: 46997 | CC3: 47027 | CD3: 47058 | CE3: 47088 | CF3: 28년계 | CG3: 47119 | CH3: 47150 | CI3: 47178 | CJ3: 47209 | CK3: 47239 | CL3: 47270 | CM3: 47300 | CN3: 47331 | CO3: 47362 | CP3: 47392 | CQ3: 47423 | CR3: 47453 | CS3: 29년계 | CT3: 47484 | CU3: 47515 | CV3: 47543 | CW3: 47574 | CX3: 47604 | CY3: 47635 | CZ3: 47665 | DA3: 47696 | DB3: 47727 | DC3: 47757 | DD3: 47788 | DE3: 47818 | DF3: 30년계 | DG3: 30년이후 | DH3: 합계 | DI3: Total(C열) | DJ3: 잔액
A4: 영업 (도급/용역사업) | C4: 수입 | E4: =+E218 -> 1585765.7 | F4: =+F218 -> 4518.8 | G4: =+G218 -> 2410.7997 | H4: =+H218 -> 2585.0402 | I4: =+I218 -> 1643.8651 | J4: =+J218 -> 1095.5899 | K4: =+K218 -> 938.78216 | L4: =+L218 -> 2572.7345 | ... R4: =+R218 -> 2951.7028 | S4: =SUM(G4:R4) -> 43488.833 | T4: =+T218 -> 2477.254 | U4: =+U218 -> 1158.4478 | V4: =+V218 -> 607.71865 | W4: =+W218 -> 727.13063 | X4: =+X218 -> 647.41928 | Y4: =+Y218 -> 849.2885 | Z4: =+Z218 -> 1210.0058 | AA4: =+AA218 -> 1798.5852 | ... AE4: =+AE218 -> 32193.421 | AF4: =SUM(T4:AE4) -> 48106.146 | AG4: =+AG218 -> 5306.9558 | AH4: =+AH218 -> 1009.4704 | AI4: =+AI218 -> 1334.4752 | AJ4: =+AJ218 -> 2825.325 | AK4: =+AK218 -> 4332.9034 | AL4: =+AL218 -> 3324.7459 | AM4: =+AM218 -> 3227.9172 | AN4: =+AN218 -> 4322.3224 | ... AR4: =+AR218 -> 13048.983 | AS4: =SUM(AG4:AR4) -> 45881.708 | AT4: =+AT218 -> 13475.46 | AU4: =+AU218 -> 8369.8133 | AV4: =+AV218 -> 4229.9638 | AW4: =+AW218 -> 4720.3816 | AX4: =+AX218 -> 65.990113 | AY4: =+AY218 -> 1989.083 | AZ4: =+AZ218 -> 139.4 | BA4: =+BA218 -> 6836.1225 | ... BE4: =+BE218 -> 16348.346 | BF4: =SUM(AT4:BE4) -> 82749.419 | BG4: =+BG218 -> 18238.9 | BH4: =+BH218 -> 14945.131 | BI4: =+BI218 -> 17865.559 | BJ4: =+BJ218 -> 34173.96 | BK4: =+BK218 -> 24465.908 | BL4: =+BL218 -> 26813.17 | BM4: =+BM218 -> 104855.1 | BN4: =+BN218 -> 26265.412 | ... BR4: =+BR218 -> 31159.826 | BS4: =SUM(BG4:BR4) -> 377778.43 | BT4: =+BT218 -> 31631.133 | BU4: =+BU218 -> 30145.143 | BV4: =+BV218 -> 26573.409 | BW4: =+BW218 -> 27055.125 | BX4: =+BX218 -> 26237.679 | BY4: =+BY218 -> 26688.215 | BZ4: =+BZ218 -> 27897.091 | CA4: =+CA218 -> 27883.311 | ... CE4: =+CE218 -> 28474.719 | CF4: =SUM(BT4:CE4) -> 333982.29 | CG4: =+CG218 -> 26643.526 | CH4: =+CH218 -> 27507.478 | CI4: =+CI218 -> 28555.777 | CJ4: =+CJ218 -> 27406.83 | CK4: =+CK218 -> 28143.11 | CL4: =+CL218 -> 28716.185 | CM4: =+CM218 -> 27043.597 | CN4: =+CN218 -> 24464.789 | ... CR4: =+CR218 -> 15832.975 | CS4: =SUM(CG4:CR4) -> 299693.29 | CT4: =+CT218 -> 12869.378 | CU4: =+CU218 -> 13263.673 | CV4: =+CV218 -> 13554.382 | CW4: =+CW218 -> 13732.829 | CX4: =+CX218 -> 13863.124 | CY4: =+CY218 -> 13936.781 | CZ4: =+CZ218 -> 55828.963 | DA4: =+DA218 -> 9689.531 | ... DE4: =+DE218 -> 60543.681 | DF4: =SUM(CT4:DE4) -> 234406.05 | DG4: =+DG218 -> 119679.58 | DH4: =+F4+S4+AF4+AS4+BF4+BS4+DG4 -> 722202.91 | DI4: =+E4 -> 1585765.7 | DJ4: =+DI4-DH4 -> 863562.83
C5: 지출 | E5: =+E219 -> 1419511.3 | F5: =+F219 -> 764.563 | G5: =+G219 -> 1884.912 | H5: =+H219 -> 1585.3505 | I5: =+I219 -> 2036.3751 | J5: =+J219 -> 1154.8133 | K5: =+K219 -> 2062.1812 | L5: =+L219 -> 1125.7989 | ... R5: =+R219 -> 1552.2889 | S5: =SUM(G5:R5) -> 17355.856 | T5: =+T219 -> 2322.1345 | U5: =+U219 -> 1117.9377 | V5: =+V219 -> 955.4101 | W5: =+W219 -> 975.01553 | X5: =+X219 -> 1021.2955 | Y5: =+Y219 -> 1055.7002 | Z5: =+Z219 -> 1216.6466 | AA5: =+AA219 -> 1250.1821 | ... AE5: =+AE219 -> 6072.4212 | AF5: =SUM(T5:AE5) -> 22136.582 | AG5: =+AG219 -> 5420.8115 | AH5: =+AH219 -> 1242.4144 | AI5: =+AI219 -> 1290.7705 | AJ5: =+AJ219 -> 2987.2081 | AK5: =+AK219 -> 3954.8912 | AL5: =+AL219 -> 3456.3917 | AM5: =+AM219 -> 2578.389 | AN5: =+AN219 -> 2865.3009 | ... AR5: =+AR219 -> 9966.0627 | AS5: =SUM(AG5:AR5) -> 42903.182 | AT5: =+AT219 -> 9911.4363 | AU5: =+AU219 -> 5681.4823 | AV5: =+AV219 -> 3514.9385 | AW5: =+AW219 -> 5429.3869 | AX5: =+AX219 -> 7141.0439 | AY5: =+AY219 -> 6836.5693 | AZ5: =+AZ219 -> 9997.1444 | BA5: =+BA219 -> 8075.3438 | ... BE5: =+BE219 -> 17076.537 | BF5: =SUM(AT5:BE5) -> 102498.06 | BG5: =+BG219 -> 15669.219 | BH5: =+BH219 -> 19670.028 | BI5: =+BI219 -> 21313.045 | BJ5: =+BJ219 -> 26631.418 | BK5: =+BK219 -> 27256.315 | BL5: =+BL219 -> 27764.222 | BM5: =+BM219 -> 43480.36 | BN5: =+BN219 -> 25711.824 | ... BR5: =+BR219 -> 25366.187 | BS5: =SUM(BG5:BR5) -> 306996.61 | BT5: =+BT219 -> 24960.918 | BU5: =+BU219 -> 27049.412 | BV5: =+BV219 -> 26932.267 | BW5: =+BW219 -> 26799.363 | BX5: =+BX219 -> 25189.941 | BY5: =+BY219 -> 26126.894 | BZ5: =+BZ219 -> 26474.482 | CA5: =+CA219 -> 38497.92 | ... CE5: =+CE219 -> 26451.429 | CF5: =SUM(BT5:CE5) -> 325699.98 | CG5: =+CG219 -> 25100.864 | CH5: =+CH219 -> 25871.722 | CI5: =+CI219 -> 26807.292 | CJ5: =+CJ219 -> 25544.912 | CK5: =+CK219 -> 26197.106 | CL5: =+CL219 -> 26701.15 | CM5: =+CM219 -> 24742.401 | CN5: =+CN219 -> 22653.883 | ... CR5: =+CR219 -> 14320.371 | CS5: =SUM(CG5:CR5) -> 278589.46 | CT5: =+CT219 -> 12115.72 | CU5: =+CU219 -> 12462.163 | CV5: =+CV219 -> 12715.634 | CW5: =+CW219 -> 12868.507 | CX5: =+CX219 -> 12978.669 | CY5: =+CY219 -> 13038.684 | CZ5: =+CZ219 -> 49897.289 | DA5: =+DA219 -> 9286.4147 | ... DE5: =+DE219 -> 54002.635 | DF5: =SUM(CT5:DE5) -> 215449.14 | DG5: =+DG219 -> 107882.39 | DH5: =+F5+S5+AF5+AS5+BF5+BS5+DG5 -> 600537.24 | DI5: =+E5 -> 1419511.3 | DJ5: =+DI5-DH5 -> 818974.02 | DK5: =+DH5/DH4 -> 0.83153533
C6: 과부족 | E6: =+E4-E5 -> 166254.49 | G6: =+G4-G5 -> 525.8877 | H6: =+H4-H5 -> 999.68968 | I6: =+I4-I5 -> -392.51004 | J6: =+J4-J5 -> -59.223411 | K6: =+K4-K5 -> -1123.399 | L6: =+L4-L5 -> 1446.9356 | M6: =+M4-M5 -> -373.52829 | N6: =+N4-N5 -> -244.02313 | ... R6: =+R4-R5 -> 1399.414 | S6: =SUM(G6:R6) -> 26132.977 | T6: =+T4-T5 -> 155.11949 | U6: =+U4-U5 -> 40.510149 | V6: =+V4-V5 -> -347.69145 | W6: =+W4-W5 -> -247.8849 | X6: =+X4-X5 -> -373.87624 | Y6: =+Y4-Y5 -> -206.41167 | Z6: =+Z4-Z5 -> -6.640862 | AA6: =+AA4-AA5 -> 548.40306 | ... AE6: =+AE4-AE5 -> 26121 | AF6: =SUM(T6:AE6) -> 25969.565 | AG6: =+AG4-AG5 -> -113.85578 | AH6: =+AH4-AH5 -> -232.94401 | AI6: =+AI4-AI5 -> 43.704654 | AJ6: =+AJ4-AJ5 -> -161.88308 | AK6: =+AK4-AK5 -> 378.01215 | AL6: =+AL4-AL5 -> -131.64582 | AM6: =+AM4-AM5 -> 649.52821 | AN6: =+AN4-AN5 -> 1457.0215 | ... AR6: =+AR4-AR5 -> 3082.92 | AS6: =SUM(AG6:AR6) -> 2978.5261 | AT6: =+AT4-AT5 -> 3564.0235 | AU6: =+AU4-AU5 -> 2688.3311 | AV6: =+AV4-AV5 -> 715.02523 | AW6: =+AW4-AW5 -> -709.00534 | AX6: =+AX4-AX5 -> -7075.0538 | AY6: =+AY4-AY5 -> -4847.4862 | AZ6: =+AZ4-AZ5 -> -9857.7444 | BA6: =+BA4-BA5 -> -1239.2214 | ... BE6: =+BE4-BE5 -> -728.19094 | BF6: =SUM(AT6:BE6) -> -19748.641 | BG6: =+BG4-BG5 -> 2569.681 | BH6: =+BH4-BH5 -> -4724.8969 | BI6: =+BI4-BI5 -> -3447.4857 | BJ6: =+BJ4-BJ5 -> 7542.5423 | BK6: =+BK4-BK5 -> -2790.407 | BL6: =+BL4-BL5 -> -951.05199 | BM6: =+BM4-BM5 -> 61374.735 | BN6: =+BN4-BN5 -> 553.58845 | ... BR6: =+BR4-BR5 -> 5793.6396 | BS6: =SUM(BG6:BR6) -> 70781.824 | BT6: =+BT4-BT5 -> 6670.2142 | BU6: =+BU4-BU5 -> 3095.7314 | BV6: =+BV4-BV5 -> -358.85781 | BW6: =+BW4-BW5 -> 255.76267 | BX6: =+BX4-BX5 -> 1047.7382 | BY6: =+BY4-BY5 -> 561.32088 | BZ6: =+BZ4-BZ5 -> 1422.6089 | CA6: =+CA4-CA5 -> -10614.609 | ... CE6: =+CE4-CE5 -> 2023.2902 | CF6: =SUM(BT6:CE6) -> 8282.3125 | CG6: =+CG4-CG5 -> 1542.6617 | CH6: =+CH4-CH5 -> 1635.7556 | CI6: =+CI4-CI5 -> 1748.4853 | CJ6: =+CJ4-CJ5 -> 1861.9187 | CK6: =+CK4-CK5 -> 1946.0046 | CL6: =+CL4-CL5 -> 2015.0355 | CM6: =+CM4-CM5 -> 2301.1953 | CN6: =+CN4-CN5 -> 1810.9051 | ... CR6: =+CR4-CR5 -> 1512.6044 | CS6: =SUM(CG6:CR6) -> 21103.825 | CT6: =+CT4-CT5 -> 753.65819 | CU6: =+CU4-CU5 -> 801.51049 | CV6: =+CV4-CV5 -> 838.74744 | CW6: =+CW4-CW5 -> 864.32234 | CX6: =+CX4-CX5 -> 884.4553 | CY6: =+CY4-CY5 -> 898.09614 | CZ6: =+CZ4-CZ5 -> 5931.6743 | DA6: =+DA4-DA5 -> 403.11638 | ... DE6: =+DE4-DE5 -> 6541.0457 | DF6: =SUM(CT6:DE6) -> 18956.912 | DG6: =+DG4-DG5 -> 11797.19 | DH6: =+DH4-DH5 -> 121665.68 | DI6: =+E6 -> 166254.49 | DJ6: =+DI6-DH6 -> 44588.813
